Workbook

Sheet RESUME
A1: DASHBOARD
A3: Total beneficiaires
A4: =COUNTIF(DEPENDANTS!$D$3:$D$725,"<>")
F5: Par Statut | I5: Par Sexe | L5: Localisation x Statut | P5: Par Tranche age
F6: Statut | G6: Effectif | I6: Sexe | J6: Effectif | L6: Localisation | M6: Employe(e) | N6: Enfant | P6: Tranche | Q6: Effectif | S6: Site | T6: Effectif | U6: KPI | V6: Valeur
F7: Enfant | G7: =COUNTIF(DEPENDANTS!$D$3:$D$725,"Enfant") | I7: M | J7: =COUNTIF(DEPENDANTS!$E$3:$E$725,"M") | L7: Kinshasa | M7: =COUNTIFS(DEPENDANTS!$G$3:$G$725,"Kinshasa",DEPENDANTS!$D$3:$D$725,"*Employ*") | N7: =COUNTIFS(DEPENDANTS!$G$3:$G$725,"Kinshasa",DEPENDANTS!$D$3:$D$725,"Enfant") | P7: 0-2 ans | Q7: =COUNTIFS(DEPENDANTS!$I$3:$I$725,">=0",DEPENDANTS!$I$3:$I$725,"<=2") | S7: Kinshasa | T7: =V11 | U7: Total beneficiaires | V7: =COUNTIF(DEPENDANTS!$D$3:$D$725,"<>")
A8: Employes | B8: =U9 | D8: =U10 | F8: Employe(e) | G8: =COUNTIF(DEPENDANTS!$D$3:$D$725,"*Employ*") | I8: F | J8: =COUNTIF(DEPENDANTS!$E$3:$E$725,"F") | L8: Zamba | M8: =COUNTIFS(DEPENDANTS!$G$3:$G$725,"Zamba",DEPENDANTS!$D$3:$D$725,"*Employ*") | N8: =COUNTIFS(DEPENDANTS!$G$3:$G$725,"Zamba",DEPENDANTS!$D$3:$D$725,"Enfant") | P8: 3-12 ans | Q8: =COUNTIFS(DEPENDANTS!$I$3:$I$725,">=3",DEPENDANTS!$I$3:$I$725,"<=12") | S8: Zamba | T8: =V12 | U8: Employes
A9: =COUNTIF(DEPENDANTS!$D$3:$D$725,"*Employ*") | B9: =COUNTIF(DEPENDANTS!$D$3:$D$725,"*Conjoint*") | D9: =COUNTIF(DEPENDANTS!$D$3:$D$725,"Enfant") | F9: Conjoint(e) | G9: =COUNTIF(DEPENDANTS!$D$3:$D$725,"*Conjoint*") | L9: Lubudi | M9: =COUNTIFS(DEPENDANTS!$G$3:$G$725,"Lubudi",DEPENDANTS!$D$3:$D$725,"*Employ*") | N9: =COUNTIFS(DEPENDANTS!$G$3:$G$725,"Lubudi",DEPENDANTS!$D$3:$D$725,"Enfant") | P9: 13-15 ans | Q9: =COUNTIFS(DEPENDANTS!$I$3:$I$725,">=13",DEPENDANTS!$I$3:$I$725,"<=15") | S9: lubudi | T9: =V16 | U9: Conjoints
A10: Par site | P10: 16-19 ans | Q10: =COUNTIFS(DEPENDANTS!$I$3:$I$725,">=16",DEPENDANTS!$I$3:$I$725,"<=19") | U10: Enfants
A11: Total | B11: Kinshasa | C11: Lubudi | D11: Zamba | P11: 20-25 ans | Q11: =COUNTIFS(DEPENDANTS!$I$3:$I$725,">=20",DEPENDANTS!$I$3:$I$725,"<=25") | U11: Kinshasa | V11: =COUNTIF(DEPENDANTS!$G$3:$G$725,"Kinshasa")
A12: =SUM(B12:D12) | B12: =COUNTIF(DEPENDANTS!$G$3:$G$725,"Kinshasa") | C12: =COUNTIF(DEPENDANTS!$G$3:$G$725,"Lubudi") | D12: =COUNTIF(DEPENDANTS!$G$3:$G$725,"Zamba") | P12: 26 ans et + | Q12: =COUNTIF(DEPENDANTS!$I$3:$I$725,">=26") | U12: Zamba | V12: =COUNTIF(DEPENDANTS!$G$3:$G$725,"Zamba")
U13: Beneficiaires avec matricule | V13: =COUNTIF(DEPENDANTS!$B$3:$B$725,"<>")
U14: Employes avec matricule
A15: Employés avec matricule | U15: Moyenne enfants par employe
A16: =COUNTIFS(DEPENDANTS!$D$3:$D$725,"*Employ*",DEPENDANTS!$B$3:$B$725,"<>") | U16: lubudi | V16: =COUNTIF(DEPENDANTS!$G$3:$G$725,"lubudi")
A17: Moyenne enfants par employé
A18: =AVERAGEIF(DEPENDANTS!$D$3:$D$725,"*Employ*",DEPENDANTS!$K$3:$K$725)
A19: Employés avec famille
A20: =COUNTIFS(DEPENDANTS!$D$3:$D$725,"*Employ*",DEPENDANTS!$L$3:$L$725,">=2")
A21: Employés seuls
A22: =COUNTIFS(DEPENDANTS!$D$3:$D$725,"*Employ*",DEPENDANTS!$L$3:$L$725,"1")
A24: =A19 | B24: =A21
A25: =A20 | B25: =A22
A26: Localisation × statut
A27: Site | B27: Emp. | C27: Conj. | D27: Enf. | E27: Total
A28: Zamba | B28: =COUNTIFS(DEPENDANTS!$G$3:$G$725,"Zamba",DEPENDANTS!$D$3:$D$725,"*Employ*") | C28: =COUNTIFS(DEPENDANTS!$G$3:$G$725,"Zamba",DEPENDANTS!$D$3:$D$725,"*Conjoint*") | D28: =COUNTIFS(DEPENDANTS!$G$3:$G$725,"Zamba",DEPENDANTS!$D$3:$D$725,"Enfant") | E28: =SUM(B28:D28)
A29: Kinshasa | B29: =COUNTIFS(DEPENDANTS!$G$3:$G$725,"Kinshasa",DEPENDANTS!$D$3:$D$725,"*Employ*") | C29: =COUNTIFS(DEPENDANTS!$G$3:$G$725,"Kinshasa",DEPENDANTS!$D$3:$D$725,"*Conjoint*") | D29: =COUNTIFS(DEPENDANTS!$G$3:$G$725,"Kinshasa",DEPENDANTS!$D$3:$D$725,"Enfant") | E29: =SUM(B29:D29)
A30: Lubudi | B30: =COUNTIFS(DEPENDANTS!$G$3:$G$725,"Lubudi",DEPENDANTS!$D$3:$D$725,"*Employ*") | C30: =COUNTIFS(DEPENDANTS!$G$3:$G$725,"Lubudi",DEPENDANTS!$D$3:$D$725,"*Conjoint*") | D30: =COUNTIFS(DEPENDANTS!$G$3:$G$725,"Lubudi",DEPENDANTS!$D$3:$D$725,"Enfant") | E30: =SUM(B30:D30)
A31: TOTAL | B31: =SUM(B28:B30) | C31: =SUM(C28:C30) | D31: =SUM(D28:D30) | E31: =SUM(E28:E30)
A33: Mineurs et majeurs par site
A34: Site | B34: Min | C34: Maj | D34: Total
A35: Zamba | B35: =COUNTIFS(DEPENDANTS!$G$3:$G$725,"Zamba",DEPENDANTS!$I$3:$I$725,"<=17") | C35: =COUNTIF(DEPENDANTS!$G$3:$G$725,"Zamba")-B35 | D35: =SUM(B35:C35)
A36: Kinshasa | B36: =COUNTIFS(DEPENDANTS!$G$3:$G$725,"Kinshasa",DEPENDANTS!$I$3:$I$725,"<=17") | C36: =COUNTIF(DEPENDANTS!$G$3:$G$725,"Kinshasa")-B36 | D36: =SUM(B36:C36)
A37: Lubudi | B37: =COUNTIFS(DEPENDANTS!$G$3:$G$725,"Lubudi",DEPENDANTS!$I$3:$I$725,"<=17") | C37: =COUNTIF(DEPENDANTS!$G$3:$G$725,"Lubudi")-B37 | D37: =SUM(B37:C37)
A38: TOTAL | B38: =SUM(B35:B37) | C38: =SUM(C35:C37) | D38: =SUM(D35:D37)

Sheet DEPENDANTS
A1: PPC BARNET DRC-PRISE EN CHARGE MEDICALE | L1: Total | M1: 705
A2: N° | B2: Matricule | C2: N° Pactilis | D2: Statut | E2: Sexe | F2: Nom et Prénoms | G2: Localisation | H2: Date de naissance | I2: Age | J2: Composition de la famille | K2: Enfants | L2: Total | M2: Commentaires | N2: Lien document | O2: Numero Villa | P2: Type de maison
A3: 1 | B3: 70000265 | C3: 108112 | D3: Employé | E3: F | F3: EWULI SUKA Carine | G3: Kinshasa | H3: 30022 | I3: =DATEDIF(H3,TODAY(),"Y") | J3: 1 | K3: 2 | L3: 4
A4: 2 | B4: 70000265 | C4: 162600 | D4: Conjoint | E4: M | F4: MPEZO MATONDO JEAN CYRIL | G4: Kinshasa | H4: 26225 | I4: =DATEDIF(H4,TODAY(),"Y")
A5: 3 | B5: 70000265 | C5: 162601 | D5: Enfant | E5: M | F5: MPEZO EWULI DONEL | G5: Kinshasa | H5: 40593 | I5: =DATEDIF(H5,TODAY(),"Y")
A6: 4 | B6: 70000265 | C6: 162602 | D6: Enfant | E6: F | F6: MPEZO BUTELEZI YOELLE ELISA | G6: Kinshasa | H6: 41303 | I6: =DATEDIF(H6,TODAY(),"Y")
A7: 5 | B7: 70000240 | C7: 155437 | D7: Employé | E7: M | F7: MAYUMBU NZINDU NELSON | G7: Zamba | H7: 34545 | I7: =DATEDIF(H7,TODAY(),"Y") | J7: 0 | K7: 0 | L7: 1
A8: 6 | B8: 70000295 | C8: 163787 | D8: Employé | E8: F | F8: KINKINIA DIAVEZUKA PELAGIE | G8: Zamba | H8: 27986 | I8: =DATEDIF(H8,TODAY(),"Y") | J8: 1 | K8: 4 | L8: 6
A9: 7 | B9: 70000295 | C9: 163789 | D9: Enfant | E9: F | F9: NSOMPETI BELUNDJA LOYCE | G9: Zamba | H9: 37796 | I9: =DATEDIF(H9,TODAY(),"Y")
A10: 8 | B10: 70000295 | C10: 163790 | D10: Enfant | E10: F | F10: SOMPETI KUTU Médina | G10: Zamba | H10: 38460 | I10: =DATEDIF(H10,TODAY(),"Y")
A11: 9 | B11: 70000295 | C11: 163791 | D11: Enfant | E11: M | F11: NSOMPETI SULUTANI-IBHA JOSEPH | G11: Zamba | H11: 39245 | I11: =DATEDIF(H11,TODAY(),"Y")
A12: 10 | B12: 70000295 | C12: 163792 | D12: Enfant | E12: F | F12: NSOMPETI KINKINIA Dove | G12: Zamba | H12: 40155 | I12: =DATEDIF(H12,TODAY(),"Y")
A13: 11 | B13: 70000295 | C13: 164637 | D13: Conjoint | E13: M | F13: NSOMPETI NGOLENKOLO Willy | G13: Zamba | H13: 24053 | I13: =DATEDIF(H13,TODAY(),"Y")
A14: 12 | B14: 70000112 | C14: 163936 | D14: Employé | E14: M | F14: ADHULE NYADRIA JOEL | G14: Zamba | H14: 30328 | I14: =DATEDIF(H14,TODAY(),"Y") | J14: 1 | K14: 5 | L14: 7
A15: 13 | B15: 70000112 | C15: 163937 | D15: Conjoint | E15: F | F15: KIZEKELE MBANGO JUDITH | G15: Zamba | H15: 32408 | I15: =DATEDIF(H15,TODAY(),"Y")
A16: 14 | B16: 70000112 | C16: 163938 | D16: Enfant | E16: F | F16: ADHULE DEZMIE shukurani | G16: Zamba | H16: 42157 | I16: =DATEDIF(H16,TODAY(),"Y")
A17: 15 | B17: 70000112 | C17: 163939 | D17: Enfant | E17: M | F17: SALEM ADHULE GENEVIEVE | G17: Zamba | H17: 42604 | I17: =DATEDIF(H17,TODAY(),"Y")
A18: 16 | B18: 70000112 | C18: 163940 | D18: Enfant | E18: M | F18: LEMA ADHULE david | G18: Zamba | H18: 44042 | I18: =DATEDIF(H18,TODAY(),"Y")
A19: 17 | B19: 70000112 | C19: 166049 | D19: Enfant | E19: M | F19: ADHULE JIREH FENI | G19: Zamba | H19: 44596 | I19: =DATEDIF(H19,TODAY(),"Y")
A20: 710 | B20: 70000112 | C20: 178129 | D20: Enfant | E20: M | F20: ADHULE KIZEKELE Nour | G20: Zamba | H20: 46190 | I20: =DATEDIF(H20,TODAY(),"Y") | N20: https://ppcafr.sharepoint.com/:b:/r/sites/knshr/HR%20ADMINISTRATION/ETAT%20DES%20INCORPORATIONS/2026/Etat_INCORPORATION_1_POLICE_1_0807.pdf?csf=1&amp;amp;amp;amp;amp;amp;amp;amp;amp;amp;amp;amp;amp;amp;amp;amp;amp;amp;amp;amp;amp;amp;amp;web=1&amp;amp;amp;amp;amp;amp;amp;amp;amp;amp;amp;amp;amp;amp;amp;amp;amp;amp;amp;amp;amp;amp;amp;e=Y0DLts
A21: 18 | B21: 70000023 | C21: 163951 | D21: Employé | E21: M | F21: BANGA BANGA APEA ONESIME | G21: Kinshasa | H21: 25208 | I21: =DATEDIF(H21,TODAY(),"Y") | J21: 1 | K21: 2 | L21: 4
A22: 19 | B22: 70000023 | C22: 163952 | D22: Conjoint | E22: F | F22: MAVULA CLEMENTINE | G22: Kinshasa | H22: 26155 | I22: =DATEDIF(H22,TODAY(),"Y")
A23: 20 | B23: 70000023 | C23: 163953 | D23: Enfant | E23: F | F23: BANGA NTUMBA META MILKANE | G23: Kinshasa | H23: 40539 | I23: =DATEDIF(H23,TODAY(),"Y")
A24: 21 | B24: 70000023 | C24: 163954 | D24: Enfant | E24: M | F24: BANGA BANGA PRINCE | G24: Kinshasa | H24: 42141 | I24: =DATEDIF(H24,TODAY(),"Y")
A25: 22 | B25: 70000019 | C25: 163955 | D25: Employé | E25: F | F25: BANGULI KIESSE SANDRINE | G25: Kinshasa | H25: 28799 | I25: =DATEDIF(H25,TODAY(),"Y") | J25: 1 | K25: 0 | L25: 2
A26: 23 | B26: 70000019 | C26: 163956 | D26: Conjoint | E26: M | F26: AMINA DADDY | G26: Kinshasa | H26: 26402 | I26: =DATEDIF(H26,TODAY(),"Y")
A27: 24 | B27: 70000078 | C27: 163957 | D27: Employé | E27: F | F27: BATEKISA MIABANGANA NICHA | G27: Kinshasa | H27: 35405 | I27: =DATEDIF(H27,TODAY(),"Y") | J27: 0 | K27: 0 | L27: 1
A28: 25 | B28: 70000069 | C28: 163958 | D28: Employé | E28: M | F28: BAVIBIDILA MUNTANA GERVAIS | G28: Zamba | H28: 27917 | I28: =DATEDIF(H28,TODAY(),"Y") | J28: 1 | K28: 2 | L28: 4
A29: 26 | B29: 70000069 | C29: 163959 | D29: Enfant | E29: F | F29: DIAKIESE BATOMA LOICE | G29: Zamba | H29: 43293 | I29: =DATEDIF(H29,TODAY(),"Y")
A30: 27 | B30: 70000069 | C30: 167049 | D30: Conjoint | E30: F | F30: BATOMA BASISILA BIBICHE | G30: Zamba | H30: 31924 | I30: =DATEDIF(H30,TODAY(),"Y")
A31: 28 | B31: 70000069 | C31: 167741 | D31: Enfant | E31: F | F31: LUKELO BATOMA SPLENDEUR | G31: Zamba | H31: 44883 | I31: =DATEDIF(H31,TODAY(),"Y")
A32: 29 | B32: 70000052 | C32: 163960 | D32: Employé | E32: M | F32: BAYISA SIMON DIDIER | G32: Zamba | H32: 29768 | I32: =DATEDIF(H32,TODAY(),"Y") | J32: 1 | K32: 5 | L32: 7
A33: 30 | B33: 70000052 | C33: 163961 | D33: Conjoint | E33: F | F33: DIAZUNDA DIAZOLA | G33: Zamba | H33: 32609 | I33: =DATEDIF(H33,TODAY(),"Y")
A34: 31 | B34: 70000052 | C34: 163962 | D34: Enfant | E34: M | F34: MALUNGU BAYISA MERCENE | G34: Zamba | H34: 39183 | I34: =DATEDIF(H34,TODAY(),"Y")
A35: 32 | B35: 70000052 | C35: 163963 | D35: Enfant | E35: M | F35: BAYISA FUABADIDI RANDY | G35: Zamba | H35: 42160 | I35: =DATEDIF(H35,TODAY(),"Y")
A36: 33 | B36: 70000052 | C36: 163964 | D36: Enfant | E36: M | F36: DISU BAYISA BRANDY | G36: Zamba | H36: 42771 | I36: =DATEDIF(H36,TODAY(),"Y")
A37: 34 | B37: 70000052 | C37: 163965 | D37: Enfant | E37: F | F37: BAYISA MAKIESE BLESSING | G37: Zamba | H37: 43855 | I37: =DATEDIF(H37,TODAY(),"Y")
A38: 35 | B38: 70000052 | C38: 173119 | D38: Enfant | E38: M | F38: MIAMBANZILA BAYISA BRAYAN | G38: Zamba | H38: 45743 | I38: =DATEDIF(H38,TODAY(),"Y")
A39: 36 | B39: 70000179 | C39: 163967 | D39: Employé | E39: F | F39: BIGANIRO NDAMUSO NELLY | G39: Kinshasa | H39: 31542 | I39: =DATEDIF(H39,TODAY(),"Y") | J39: 0 | K39: 0 | L39: 1
A40: 37 | B40: 70000045 | C40: 163968 | D40: Employé | E40: F | F40: BILONDA KAZADI DIANE | G40: Kinshasa | H40: 32197 | I40: =DATEDIF(H40,TODAY(),"Y") | J40: 1 | K40: 0 | L40: 2
...
