Workbook

Sheet DASHBOARD CSR
A1: DASHBOARD CSR | C1: FY2026
A5: EFFECTIFS | G5: BUDGET
A6: TOTAL PROJET | B6: TERMINE | C6: ENCOURS | D6: =UPPER("Non debuté") -> NON DEBUTÉ | G6: Categorie | H6: Prevus | I6: Depensé | J6: Ecart
A7: =COUNTIFS(PROJECTS!$E$5:$E$73,"CSR",PROJECTS!$G$5:$G$73,$C$1) -> 15 | B7: =COUNTIFS(PROJECTS!$E$5:$E$73,"CSR",PROJECTS!$M$5:$M$73,"Terminé",PROJECTS!$G$5:$G$73,$C$1) -> 11 | C7: =COUNTIFS(PROJECTS!$E$5:$E$73,"CSR",PROJECTS!$M$5:$M$73,"En cours",PROJECTS!$G$5:$G$73,$C$1) -> 2 | D7: =COUNTIFS(PROJECTS!$E$5:$E$73,"CSR",PROJECTS!$M$5:$M$73,"non debuté",PROJECTS!$G$5:$G$73,$C$1) -> 2 | G7: Terminé | H7: =SUMIFS(PROJECTS!$I$5:$I$73,PROJECTS!$E$5:$E$73,"CSR",PROJECTS!$M$5:$M$73,G7,PROJECTS!$G$5:$G$73,$C$1) -> 454653.67 | I7: =SUMIFS(PROJECTS!$J$5:$J$73,PROJECTS!$E$5:$E$73,"CSR",PROJECTS!$M$5:$M$73,G7,PROJECTS!$G$5:$G$73,$C$1) -> 454653.67 | J7: =H7-I7 -> 0
G8: En cours | H8: =SUMIFS(PROJECTS!$I$5:$I$73,PROJECTS!$E$5:$E$73,"CSR",PROJECTS!$M$5:$M$73,G8,PROJECTS!$G$5:$G$73,$C$1) -> 20535 | I8: =SUMIFS(PROJECTS!$J$5:$J$73,PROJECTS!$E$5:$E$73,"CSR",PROJECTS!$M$5:$M$73,G8,PROJECTS!$G$5:$G$73,$C$1) -> 20535 | J8: =H8-I8 -> 0
G9: Non debuté | H9: =SUMIFS(PROJECTS!$I$5:$I$73,PROJECTS!$E$5:$E$73,"CSR",PROJECTS!$M$5:$M$73,G9,PROJECTS!$G$5:$G$73,$C$1) -> 0 | I9: =SUMIFS(PROJECTS!$J$5:$J$73,PROJECTS!$E$5:$E$73,"CSR",PROJECTS!$M$5:$M$73,G9,PROJECTS!$G$5:$G$73,$C$1) -> 0 | J9: =H9-I9 -> 0
G10: Total | H10: =SUM(H7:H9) -> 475188.67 | I10: =SUM(I7:I9) -> 475188.67 | J10: =SUM(J7:J9) -> 0
A13: Par Secteurs | G13: BUDGET
A14: TOTAL PROJET | B14: =G15 -> Santé | C14: =G16 -> Education | D14: =G17 -> Sociale | E14: =G18 -> Infrastructures | G14: Categorie | H14: Prevus | I14: Depensé | J14: Ecart
A15: =COUNTIFS(PROJECTS!$E$5:$E$73,"CSR",PROJECTS!$G$5:$G$73,$C$1) -> 15 | B15: =COUNTIFS(PROJECTS!$D$5:$D$73,'DASHBOARD CSR'!G15,PROJECTS!$E$5:$E$73,"CSR",PROJECTS!$G$5:$G$73,$C$1) -> 3 | C15: =COUNTIFS(PROJECTS!$D$5:$D$73,'DASHBOARD CSR'!G16,PROJECTS!$E$5:$E$73,"CSR",PROJECTS!$G$5:$G$73,$C$1) -> 4 | D15: =COUNTIFS(PROJECTS!$D$5:$D$73,'DASHBOARD CSR'!G17,PROJECTS!$E$5:$E$73,"CSR",PROJECTS!$G$5:$G$73,$C$1) -> 5 | E15: =COUNTIFS(PROJECTS!$D$5:$D$73,'DASHBOARD CSR'!G18,PROJECTS!$E$5:$E$73,"CSR",PROJECTS!$G$5:$G$73,$C$1) -> 3 | G15: {=_xlfn.UNIQUE(_xlfn._xlws.FILTER(PROJECTS!D5:D73,PROJECTS!E5:E73="CSR"))} -> Santé | H15: =SUMIFS(PROJECTS!$I$5:$I$73,PROJECTS!$E$5:$E$73,"CSR",PROJECTS!$D$5:$D$73,G15,PROJECTS!$G$5:$G$73,$C$1) -> 12923.64 | I15: =SUMIFS(PROJECTS!$J$5:$J$73,PROJECTS!$E$5:$E$73,"CSR",PROJECTS!$D$5:$D$73,G15,PROJECTS!$G$5:$G$73,$C$1) -> 12923.64 | J15: =H15-I15 -> 0
G16: Education | H16: =SUMIFS(PROJECTS!$I$5:$I$73,PROJECTS!$E$5:$E$73,"CSR",PROJECTS!$D$5:$D$73,G16,PROJECTS!$G$5:$G$73,$C$1) -> 344744.83 | I16: =SUMIFS(PROJECTS!$J$5:$J$73,PROJECTS!$E$5:$E$73,"CSR",PROJECTS!$D$5:$D$73,G16,PROJECTS!$G$5:$G$73,$C$1) -> 344744.83 | J16: =H16-I16 -> 0
G17: Sociale | H17: =SUMIFS(PROJECTS!$I$5:$I$73,PROJECTS!$E$5:$E$73,"CSR",PROJECTS!$D$5:$D$73,G17,PROJECTS!$G$5:$G$73,$C$1) -> 31500 | I17: =SUMIFS(PROJECTS!$J$5:$J$73,PROJECTS!$E$5:$E$73,"CSR",PROJECTS!$D$5:$D$73,G17,PROJECTS!$G$5:$G$73,$C$1) -> 31500 | J17: =H17-I17 -> 0
G18: Infrastructures | H18: =SUMIFS(PROJECTS!$I$5:$I$73,PROJECTS!$E$5:$E$73,"CSR",PROJECTS!$D$5:$D$73,G18,PROJECTS!$G$5:$G$73,$C$1) -> 86020.2 | I18: =SUMIFS(PROJECTS!$J$5:$J$73,PROJECTS!$E$5:$E$73,"CSR",PROJECTS!$D$5:$D$73,G18,PROJECTS!$G$5:$G$73,$C$1) -> 86020.2 | J18: =H18-I18 -> 0
G19: TOTAL | H19: =SUM(H15:H18) -> 475188.67 | I19: =SUM(I15:I18) -> 475188.67 | J19: =SUM(J15:J18) -> 0

Sheet DASHBOARD CC
A1: DASHBOARD CAHIER DES CHARGES | E1: FY2024
A4: EFFECTIF | G4: BUDGET
A5: TOTAL PROJET | B5: TERMINE | C5: ENCOURS | D5: =UPPER("Non debuté") -> NON DEBUTÉ | G5: Categorie | H5: Prevus | I5: Depensé | J5: Ecart
A6: =COUNTIF(PROJECTS!$E$5:$E$73,"Cahier de charges") -> 31 | B6: =COUNTIFS(PROJECTS!$E$5:$E$73,"Cahier de charges",PROJECTS!$M$5:$M$73,"Terminé") -> 13 | C6: =COUNTIFS(PROJECTS!$E$5:$E$73,"Cahier de charges",PROJECTS!$M$5:$M$73,"En cours") -> 9 | D6: =COUNTIFS(PROJECTS!$E$5:$E$73,"Cahier de charges",PROJECTS!$M$5:$M$73,"non debuté") -> 9 | G6: Terminé | H6: =SUMIFS(PROJECTS!$I$5:$I$73,PROJECTS!$E$5:$E$73,"Cahier de charges",PROJECTS!$M$5:$M$73,G6,PROJECTS!$G$5:$G$73,$E$1) -> 116930 | I6: =SUMIFS(PROJECTS!$J$5:$J$73,PROJECTS!$E$5:$E$73,"Cahier de charges",PROJECTS!$M$5:$M$73,G6,PROJECTS!$G$5:$G$73,$E$1) -> 99178.38 | J6: =H6-I6 -> 17751.62
G7: En cours | H7: =SUMIFS(PROJECTS!$I$5:$I$73,PROJECTS!$E$5:$E$73,"Cahier de charges",PROJECTS!$M$5:$M$73,G7,PROJECTS!$G$5:$G$73,$E$1) -> 1447189.5 | I7: =SUMIFS(PROJECTS!$J$5:$J$73,PROJECTS!$E$5:$E$73,"Cahier de charges",PROJECTS!$M$5:$M$73,G7,PROJECTS!$G$5:$G$73,$E$1) -> 1346469.3 | J7: =H7-I7 -> 100720.16
G8: Non debuté | H8: =SUMIFS(PROJECTS!$I$5:$I$73,PROJECTS!$E$5:$E$73,"Cahier de charges",PROJECTS!$M$5:$M$73,G8,PROJECTS!$G$5:$G$73,$E$1) -> 171189.5 | I8: =SUMIFS(PROJECTS!$J$5:$J$73,PROJECTS!$E$5:$E$73,"Cahier de charges",PROJECTS!$M$5:$M$73,G8,PROJECTS!$G$5:$G$73,$E$1) -> 14807.3 | J8: =H8-I8 -> 156382.2
G9: Total | H9: =SUMIFS(PROJECTS!$I$5:$I$73,PROJECTS!$E$5:$E$73,"Cahier de charges") -> 1735309 | I9: =SUMIFS(PROJECTS!$J$5:$J$73,PROJECTS!$E$5:$E$73,"Cahier de charges") -> 1460455 | J9: =H9-I9 -> 274853.98
A12: EFFECTIF PAR SECTEURS | G12: BUDGET PAR SECTEURS D'ACTIVITE
A13: TOTAL PROJET | B13: =G14 -> Agriculture et élevage | C13: =G15 -> Energie | D13: =G16 -> Education | E13: =G17 -> Infrastructures | G13: Secteur | H13: Prevus | I13: Depensé | J13: Ecart
A14: =COUNTIF(PROJECTS!$E$5:$E$73,"Cahier de charges") -> 31 | B14: =COUNTIFS(PROJECTS!$D$5:$D$73,'DASHBOARD CC'!G14,PROJECTS!$E$5:$E$73,"Cahier de charges") -> 8 | C14: =COUNTIFS(PROJECTS!$D$5:$D$73,'DASHBOARD CC'!G15,PROJECTS!$E$5:$E$73,"Cahier de charges") -> 5 | D14: =COUNTIFS(PROJECTS!$D$5:$D$73,'DASHBOARD CC'!G16,PROJECTS!$E$5:$E$73,"Cahier de charges") -> 4 | E14: =COUNTIFS(PROJECTS!$D$5:$D$73,'DASHBOARD CC'!G17,PROJECTS!$E$5:$E$73,"Cahier de charges") -> 9 | G14: {=_xlfn.UNIQUE(_xlfn._xlws.FILTER(PROJECTS!D5:D73,PROJECTS!E5:E73="Cahier de charges"))} -> Agriculture et élevage | H14: =SUMIFS(PROJECTS!$I$5:$I$73,PROJECTS!$E$5:$E$73,"Cahier de charges",PROJECTS!$D$5:$D$73,G14,PROJECTS!$G$5:$G$73,$E$1) -> 131949 | I14: =SUMIFS(PROJECTS!$J$5:$J$73,PROJECTS!$E$5:$E$73,"Cahier de charges",PROJECTS!$D$5:$D$73,G14,PROJECTS!$G$5:$G$73,$E$1) -> 47991.9 | J14: =H14-I14 -> 83957.1
G15: Energie | H15: =SUMIFS(PROJECTS!$I$5:$I$73,PROJECTS!$E$5:$E$73,"Cahier de charges",PROJECTS!$D$5:$D$73,G15,PROJECTS!$G$5:$G$73,$E$1) -> 1377000 | I15: =SUMIFS(PROJECTS!$J$5:$J$73,PROJECTS!$E$5:$E$73,"Cahier de charges",PROJECTS!$D$5:$D$73,G15,PROJECTS!$G$5:$G$73,$E$1) -> 1354525 | J15: =H15-I15 -> 22475
G16: Education | H16: =SUMIFS(PROJECTS!$I$5:$I$73,PROJECTS!$E$5:$E$73,"Cahier de charges",PROJECTS!$D$5:$D$73,G16,PROJECTS!$G$5:$G$73,$E$1) -> 57360 | I16: =SUMIFS(PROJECTS!$J$5:$J$73,PROJECTS!$E$5:$E$73,"Cahier de charges",PROJECTS!$D$5:$D$73,G16,PROJECTS!$G$5:$G$73,$E$1) -> 15931.8 | J16: =H16-I16 -> 41428.2
G17: Infrastructures | H17: =SUMIFS(PROJECTS!$I$5:$I$73,PROJECTS!$E$5:$E$73,"Cahier de charges",PROJECTS!$D$5:$D$73,G17,PROJECTS!$G$5:$G$73,$E$1) -> 97000 | I17: =SUMIFS(PROJECTS!$J$5:$J$73,PROJECTS!$E$5:$E$73,"Cahier de charges",PROJECTS!$D$5:$D$73,G17,PROJECTS!$G$5:$G$73,$E$1) -> 17000 | J17: =H17-I17 -> 80000
G18: Loisirs | H18: =SUMIFS(PROJECTS!$I$5:$I$73,PROJECTS!$E$5:$E$73,"Cahier de charges",PROJECTS!$D$5:$D$73,G18,PROJECTS!$G$5:$G$73,$E$1) -> 32000 | I18: =SUMIFS(PROJECTS!$J$5:$J$73,PROJECTS!$E$5:$E$73,"Cahier de charges",PROJECTS!$D$5:$D$73,G18,PROJECTS!$G$5:$G$73,$E$1) -> 25006.32 | J18: =H18-I18 -> 6993.68
G19: Santé | H19: =SUMIFS(PROJECTS!$I$5:$I$73,PROJECTS!$E$5:$E$73,"Cahier de charges",PROJECTS!$D$5:$D$73,G19,PROJECTS!$G$5:$G$73,$E$1) -> 40000 | I19: =SUMIFS(PROJECTS!$J$5:$J$73,PROJECTS!$E$5:$E$73,"Cahier de charges",PROJECTS!$D$5:$D$73,G19,PROJECTS!$G$5:$G$73,$E$1) -> 0 | J19: =H19-I19 -> 40000
H20: =SUM(H14:H19) -> 1735309 | I20: =SUM(I14:I19) -> 1460455 | J20: =SUM(J14:J19) -> 274853.98
A23: REPARTITION PAR LIEU D'ACTIVITE
A24: Lieu | B24: Nombre de projet | C24: Prevus | D24: Depensé | E24: Ecart
A25: {=_xlfn.UNIQUE(_xlfn._xlws.FILTER(PROJECTS!C5:C73,PROJECTS!E5:E73="Cahier de charges"))} -> Malanga Gare | B25: =COUNTIFS(PROJECTS!$E$5:$E$73,"Cahier de charges",PROJECTS!$C$5:$C$73,A25,PROJECTS!$G$5:$G$73,$E$1) -> 7 | C25: =SUMIFS(PROJECTS!$I$5:$I$73,PROJECTS!$E$5:$E$73,"Cahier de charges",PROJECTS!$C$5:$C$73,A25,PROJECTS!$G$5:$G$73,$E$1) -> 89327.25 | D25: =SUMIFS(PROJECTS!$J$5:$J$73,PROJECTS!$E$5:$E$73,"Cahier de charges",PROJECTS!$C$5:$C$73,A25,PROJECTS!$G$5:$G$73,$E$1) -> 58703.08 | E25: =C25-D25 -> 30624.17
A26: Nkumba | B26: =COUNTIFS(PROJECTS!$E$5:$E$73,"Cahier de charges",PROJECTS!$C$5:$C$73,A26,PROJECTS!$G$5:$G$73,$E$1) -> 7 | C26: =SUMIFS(PROJECTS!$I$5:$I$73,PROJECTS!$E$5:$E$73,"Cahier de charges",PROJECTS!$C$5:$C$73,A26,PROJECTS!$G$5:$G$73,$E$1) -> 89327.25 | D26: =SUMIFS(PROJECTS!$J$5:$J$73,PROJECTS!$E$5:$E$73,"Cahier de charges",PROJECTS!$C$5:$C$73,A26,PROJECTS!$G$5:$G$73,$E$1) -> 52178.08 | E26: =C26-D26 -> 37149.17
A27: Malanga Cité | B27: =COUNTIFS(PROJECTS!$E$5:$E$73,"Cahier de charges",PROJECTS!$C$5:$C$73,A27,PROJECTS!$G$5:$G$73,$E$1) -> 9 | C27: =SUMIFS(PROJECTS!$I$5:$I$73,PROJECTS!$E$5:$E$73,"Cahier de charges",PROJECTS!$C$5:$C$73,A27,PROJECTS!$G$5:$G$73,$E$1) -> 821327.25 | D27: =SUMIFS(PROJECTS!$J$5:$J$73,PROJECTS!$E$5:$E$73,"Cahier de charges",PROJECTS!$C$5:$C$73,A27,PROJECTS!$G$5:$G$73,$E$1) -> 725090.58 | E27: =C27-D27 -> 96236.67
A28: Zamba 1er | B28: =COUNTIFS(PROJECTS!$E$5:$E$73,"Cahier de charges",PROJECTS!$C$5:$C$73,A28,PROJECTS!$G$5:$G$73,$E$1) -> 6 | C28: =SUMIFS(PROJECTS!$I$5:$I$73,PROJECTS!$E$5:$E$73,"Cahier de charges",PROJECTS!$C$5:$C$73,A28,PROJECTS!$G$5:$G$73,$E$1) -> 670327.25 | D28: =SUMIFS(PROJECTS!$J$5:$J$73,PROJECTS!$E$5:$E$73,"Cahier de charges",PROJECTS!$C$5:$C$73,A28,PROJECTS!$G$5:$G$73,$E$1) -> 624483.28 | E28: =C28-D28 -> 45843.97
A29: Multi-villages | B29: =COUNTIFS(PROJECTS!$E$5:$E$73,"Cahier de charges",PROJECTS!$C$5:$C$73,A29,PROJECTS!$G$5:$G$73,$E$1) -> 2 | C29: =SUMIFS(PROJECTS!$I$5:$I$73,PROJECTS!$E$5:$E$73,"Cahier de charges",PROJECTS!$C$5:$C$73,A29,PROJECTS!$G$5:$G$73,$E$1) -> 65000 | D29: =SUMIFS(PROJECTS!$J$5:$J$73,PROJECTS!$E$5:$E$73,"Cahier de charges",PROJECTS!$C$5:$C$73,A29,PROJECTS!$G$5:$G$73,$E$1) -> 0 | E29: =C29-D29 -> 65000
B30: =SUM(B25:B29) -> 31 | C30: =SUM(C25:C29) -> 1735309 | D30: =SUM(D25:D29) -> 1460455 | E30: =SUM(E25:E29) -> 274853.98

Sheet PROJECTS
A1: CSR PROJECTS DATABASE
I3: =SUM(I5:I124) -> 2210497.7 | J3: =SUM(J5:J124) -> 1935643.7 | K3: =SUM(K5:K124) -> 274853.98 | L3: Avancement (%) | M3: =COUNTIF(M5:M24,"Terminé")&"/"&COUNTA(M5:M124) -> 15/46
A4: N° | B4: Projets | C4: Lieu | D4: Secteur | E4: Type de projet | F4: Sous-activité | G4: AF Début | H4: Responsable | I4: Budget prévu($) | J4: Budget dépensé($) | K4: Écart | M4: Statut
A5: 1 | B5: Assistance médicale | D5: Santé | E5: CSR | G5: FY2026 | I5: =J5 -> 1523.64 | J5: =SUMIFS('Budget expense Details'!$E$4:$E$86,'Budget expense Details'!$C$4:$C$86,PROJECTS!B5) -> 1523.64 | K5: =IF(I5-J5=0,0,I5-J5) -> 0 | L5: 1 | M5: =IF(L5<0.1,"Non debuté",IF(L5<1,"En cours","Terminé")) -> Terminé
A6: =A5+1 -> 2 | B6: Soutien financier Centre de coupe et couture | D6: Education | E6: CSR | G6: FY2026 | I6: =J6 -> 27677.49 | J6: =SUMIFS('Budget expense Details'!$E$4:$E$86,'Budget expense Details'!$C$4:$C$86,PROJECTS!B6) -> 27677.49 | K6: =IF(I6-J6=0,0,I6-J6) -> 0 | L6: 1 | M6: =IF(L6<0.1,"Non debuté",IF(L6<1,"En cours","Terminé")) -> Terminé
A7: =A6+1 -> 3 | B7: Réunion avec le clan Nanga (boissons non alcoolisées) | D7: Sociale | E7: CSR | G7: FY2026 | I7: =J7 -> 3400 | J7: =SUMIFS('Budget expense Details'!$E$4:$E$86,'Budget expense Details'!$C$4:$C$86,PROJECTS!B7) -> 3400 | K7: =IF(I7-J7=0,0,I7-J7) -> 0 | L7: 1 | M7: =IF(L7<0.1,"Non debuté",IF(L7<1,"En cours","Terminé")) -> Terminé
A8: =A7+1 -> 4 | B8: Dons de fin d’année aux autorités locales | D8: Sociale | E8: CSR | G8: FY2026 | I8: =J8 -> 2500 | J8: =SUMIFS('Budget expense Details'!$E$4:$E$86,'Budget expense Details'!$C$4:$C$86,PROJECTS!B8) -> 2500 | K8: =IF(I8-J8=0,0,I8-J8) -> 0 | L8: 1 | M8: =IF(L8<0.1,"Non debuté",IF(L8<1,"En cours","Terminé")) -> Terminé
A9: =A8+1 -> 5 | B9: Trust Fund - Clan Nanga | D9: Sociale | E9: CSR | G9: FY2026 | I9: =J9 -> 25000 | J9: =SUMIFS('Budget expense Details'!$E$4:$E$86,'Budget expense Details'!$C$4:$C$86,PROJECTS!B9) -> 25000 | K9: =IF(I9-J9=0,0,I9-J9) -> 0 | L9: 1 | M9: =IF(L9<0.1,"Non debuté",IF(L9<1,"En cours","Terminé")) -> Terminé
A10: =A9+1 -> 6 | B10: Contribution à l’association des personnes handicapées de Songololo | D10: Sociale | E10: CSR | G10: FY2026 | I10: =J10 -> 600 | J10: =SUMIFS('Budget expense Details'!$E$4:$E$86,'Budget expense Details'!$C$4:$C$86,PROJECTS!B10) -> 600 | K10: =IF(I10-J10=0,0,I10-J10) -> 0 | L10: 1 | M10: =IF(L10<0.1,"Non debuté",IF(L10<1,"En cours","Terminé")) -> Terminé
A11: =A10+1 -> 7 | B11: Puits de forage | D11: Infrastructures | E11: CSR | G11: FY2026 | I11: =J11 -> 37719 | J11: =SUMIFS('Budget expense Details'!$E$4:$E$86,'Budget expense Details'!$C$4:$C$86,PROJECTS!B11) -> 37719 | K11: =IF(I11-J11=0,0,I11-J11) -> 0 | L11: 1 | M11: =IF(L11<0.1,"Non debuté",IF(L11<1,"En cours","Terminé")) -> Terminé
A12: =A11+1 -> 8 | B12: École PPC | D12: Education | E12: CSR | G12: FY2026 | I12: =J12 -> 317067.34 | J12: =SUMIFS('Budget expense Details'!$E$4:$E$86,'Budget expense Details'!$C$4:$C$86,PROJECTS!B12) -> 317067.34 | K12: =IF(I12-J12=0,0,I12-J12) -> 0 | L12: 1 | M12: =IF(L12<0.1,"Non debuté",IF(L12<1,"En cours","Terminé")) -> Terminé
A13: =A12+1 -> 9 | B13: Poste de police | D13: Infrastructures | E13: CSR | G13: FY2026 | I13: =J13 -> 27766.2 | J13: =SUMIFS('Budget expense Details'!$E$4:$E$86,'Budget expense Details'!$C$4:$C$86,PROJECTS!B13) -> 27766.2 | K13: =IF(I13-J13=0,0,I13-J13) -> 0 | L13: 1 | M13: =IF(L13<0.1,"Non debuté",IF(L13<1,"En cours","Terminé")) -> Terminé
A14: =A13+1 -> 10 | B14: Batteries pour le centre hospitalier de Malanga | D14: Santé | E14: CSR | G14: FY2026 | I14: =J14 -> 0 | J14: =SUMIFS('Budget expense Details'!$E$4:$E$86,'Budget expense Details'!$C$4:$C$86,PROJECTS!B14) -> 0 | K14: =IF(I14-J14=0,0,I14-J14) -> 0 | L14: 0 | M14: =IF(L14<0.1,"Non debuté",IF(L14<1,"En cours","Terminé")) -> Non debuté
A15: =A14+1 -> 11 | B15: Lutte anti-vectorielle | D15: Santé | E15: CSR | G15: FY2026 | I15: =J15 -> 11400 | J15: =SUMIFS('Budget expense Details'!$E$4:$E$86,'Budget expense Details'!$C$4:$C$86,PROJECTS!B15) -> 11400 | K15: =IF(I15-J15=0,0,I15-J15) -> 0 | L15: 1 | M15: =IF(L15<0.1,"Non debuté",IF(L15<1,"En cours","Terminé")) -> Terminé
A16: =A15+1 -> 12 | B16: Mwinda | D16: Education | E16: CSR | G16: FY2026 | I16: =J16 -> 0 | J16: =SUMIFS('Budget expense Details'!$E$4:$E$86,'Budget expense Details'!$C$4:$C$86,PROJECTS!B16) -> 0 | K16: =IF(I16-J16=0,0,I16-J16) -> 0 | L16: 0.1 | M16: =IF(L16<0.1,"Non debuté",IF(L16<1,"En cours","Terminé")) -> En cours
A17: =A16+1 -> 13 | B17: Forage Ecole PPC | D17: Infrastructures | E17: CSR | G17: FY2026 | I17: =J17 -> 20535 | J17: =SUMIFS('Budget expense Details'!$E$4:$E$86,'Budget expense Details'!$C$4:$C$86,PROJECTS!B17) -> 20535 | K17: =IF(I17-J17=0,0,I17-J17) -> 0 | L17: 0.6 | M17: =IF(L17<0.1,"Non debuté",IF(L17<1,"En cours","Terminé")) -> En cours
... A19: =A18+1 -> 15 | B19: Orphelinat des sœurs (kinshasa) | D19: Sociale | E19: CSR | G19: FY2026 | I19: =J19 -> 0 | J19: =SUMIFS('Budget expense Details'!$E$4:$E$86,'Budget expense Details'!$C$4:$C$86,PROJECTS!B19) -> 0 | K19: =IF(I19-J19=0,0,I19-J19) -> 0 | L19: 1 | M19: =IF(L19<0.1,"Non debuté",IF(L19<1,"En cours","Terminé")) -> Terminé
A20: =A14+1 -> 11 | B20: Permaculture | Malanga Gare | C20: Malanga Gare | D20: Agriculture et élevage | E20: Cahier de charges | F20: Formation et mise en place systèmes | G20: FY2024 | I20: 32094.75 | J20: =SUMIFS('Budget expense Details'!$E$4:$E$86,'Budget expense Details'!$C$4:$C$86,PROJECTS!B20) -> 14807.3 | K20: =IF(I20-J20=0,0,I20-J20) -> 17287.45 | L20: 0 | M20: =IF(L20<0.1,"Non debuté",IF(L20<1,"En cours","Terminé")) -> Non debuté
A21: =A15+1 -> 12 | B21: Apiculture | Malanga Gare | C21: Malanga Gare | D21: Agriculture et élevage | E21: Cahier de charges | F21: Formation et installation ruches | G21: FY2024 | I21: 892.5 | J21: =SUMIFS('Budget expense Details'!$E$4:$E$86,'Budget expense Details'!$C$4:$C$86,PROJECTS!B21) -> 892.5 | K21: =IF(I21-J21=0,0,I21-J21) -> 0 | L21: 1 | M21: =IF(L21<0.1,"Non debuté",IF(L21<1,"En cours","Terminé")) -> Terminé
A22: =A16+1 -> 13 | B22: Adduction d’eau | Malanga Gare | C22: Malanga Gare | D22: Energie | E22: Cahier de charges | F22: Captage et traitement eau | G22: FY2024 | I22: 24000 | J22: =SUMIFS('Budget expense Details'!$E$4:$E$86,'Budget expense Details'!$C$4:$C$86,PROJECTS!B22) -> 25525 | K22: =IF(I22-J22=0,0,I22-J22) -> -1525 | L22: 1 | M22: =IF(L22<0.1,"Non debuté",IF(L22<1,"En cours","Terminé")) -> Terminé
A23: =A17+1 -> 14 | B23: Bourse universitaire | Malanga Gare | C23: Malanga Gare | D23: Education | E23: Cahier de charges | F23: Prise en charge études | G23: FY2024 | I23: 14340 | J23: =SUMIFS('Budget expense Details'!$E$4:$E$86,'Budget expense Details'!$C$4:$C$86,PROJECTS!B23) -> 2526.7 | K23: =IF(I23-J23=0,0,I23-J23) -> 11813.3 | L23: 1 | M23: =IF(L23<0.1,"Non debuté",IF(L23<1,"En cours","Terminé")) -> Terminé
A24: =A18+1 -> 15 | B24: Aménagement route | Malanga Gare | C24: Malanga Gare | D24: Infrastructures | E24: Cahier de charges | F24: Nivellement et drainage | G24: FY2024 | J24: =SUMIFS('Budget expense Details'!$E$4:$E$86,'Budget expense Details'!$C$4:$C$86,PROJECTS!B24) -> 11000 | K24: =IF(I24-J24=0,0,I24-J24) -> -11000 | L24: 1 | M24: =IF(L24<0.1,"Non debuté",IF(L24<1,"En cours","Terminé")) -> Terminé
A25: =A19+1 -> 16 | B25: Renforcement maisons | Malanga Gare | C25: Malanga Gare | D25: Infrastructures | E25: Cahier de charges | F25: Réhabilitation structures | G25: FY2024 | I25: 10000 | J25: =SUMIFS('Budget expense Details'!$E$4:$E$86,'Budget expense Details'!$C$4:$C$86,PROJECTS!B25) -> 0 | K25: =IF(I25-J25=0,0,I25-J25) -> 10000 | L25: 0 | M25: =IF(L25<0.1,"Non debuté",IF(L25<1,"En cours","Terminé")) -> Non debuté
A26: =A20+1 -> 12 | B26: Football | Malanga Gare | C26: Malanga Gare | D26: Loisirs | E26: Cahier de charges | F26: Aménagement et équipement terrain | G26: FY2024 | I26: 8000 | J26: =SUMIFS('Budget expense Details'!$E$4:$E$86,'Budget expense Details'!$C$4:$C$86,PROJECTS!B26) -> 3951.58 | K26: =IF(I26-J26=0,0,I26-J26) -> 4048.42 | L26: 0.5 | M26: =IF(L26<0.1,"Non debuté",IF(L26<1,"En cours","Terminé")) -> En cours
A27: =A21+1 -> 13 | B27: Permaculture | Nkumba | C27: Nkumba | D27: Agriculture et élevage | E27: Cahier de charges | F27: Formation et mise en place systèmes | G27: FY2024 | I27: 32094.75 | J27: =SUMIFS('Budget expense Details'!$E$4:$E$86,'Budget expense Details'!$C$4:$C$86,PROJECTS!B27) -> 14807.3 | K27: =IF(I27-J27=0,0,I27-J27) -> 17287.45 | L27: 0.2 | M27: =IF(L27<0.1,"Non debuté",IF(L27<1,"En cours","Terminé")) -> En cours
A28: =A22+1 -> 14 | B28: Apiculture | Nkumba | C28: Nkumba | D28: Agriculture et élevage | E28: Cahier de charges | F28: Formation et installation ruches | G28: FY2024 | I28: 892.5 | J28: =SUMIFS('Budget expense Details'!$E$4:$E$86,'Budget expense Details'!$C$4:$C$86,PROJECTS!B28) -> 892.5 | K28: =IF(I28-J28=0,0,I28-J28) -> 0 | L28: 1 | M28: =IF(L28<0.1,"Non debuté",IF(L28<1,"En cours","Terminé")) -> Terminé
A29: =A23+1 -> 15 | B29: Adduction d’eau | Nkumba | C29: Nkumba | D29: Energie | E29: Cahier de charges | F29: Forage et distribution eau | G29: FY2024 | I29: 24000 | J29: =SUMIFS('Budget expense Details'!$E$4:$E$86,'Budget expense Details'!$C$4:$C$86,PROJECTS!B29) -> 24000 | K29: =IF(I29-J29=0,0,I29-J29) -> 0 | L29: 1 | M29: =IF(L29<0.1,"Non debuté",IF(L29<1,"En cours","Terminé")) -> Terminé
A30: =A24+1 -> 16 | B30: Bourse universitaire | Nkumba | C30: Nkumba | D30: Education | E30: Cahier de charges | F30: Prise en charge études | G30: FY2024 | I30: 14340 | J30: =SUMIFS('Budget expense Details'!$E$4:$E$86,'Budget expense Details'!$C$4:$C$86,PROJECTS!B30) -> 2526.7 | K30: =IF(I30-J30=0,0,I30-J30) -> 11813.3 | L30: 1 | M30: =IF(L30<0.1,"Non debuté",IF(L30<1,"En cours","Terminé")) -> Terminé
A31: =A25+1 -> 17 | B31: Renforcement maisons | Nkumba | C31: Nkumba | D31: Infrastructures | E31: Cahier de charges | F31: Réhabilitation structures | G31: FY2024 | I31: 10000 | J31: =SUMIFS('Budget expense Details'!$E$4:$E$86,'Budget expense Details'!$C$4:$C$86,PROJECTS!B31) -> 0 | K31: =IF(I31-J31=0,0,I31-J31) -> 10000 | L31: 0 | M31: =IF(L31<0.1,"Non debuté",IF(L31<1,"En cours","Terminé")) -> Non debuté
A32: =A26+1 -> 13 | B32: Aménagement route | Nkumba | C32: Nkumba | D32: Infrastructures | E32: Cahier de charges | F32: Nivellement et drainage | G32: FY2024 | J32: =SUMIFS('Budget expense Details'!$E$4:$E$86,'Budget expense Details'!$C$4:$C$86,PROJECTS!B32) -> 6000 | K32: =IF(I32-J32=0,0,I32-J32) -> -6000 | L32: 1 | M32: =IF(L32<0.1,"Non debuté",IF(L32<1,"En cours","Terminé")) -> Terminé
A33: =A27+1 -> 14 | B33: Football | Nkumba | C33: Nkumba | D33: Loisirs | E33: Cahier de charges | F33: Aménagement et équipement terrain | G33: FY2024 | I33: 8000 | J33: =SUMIFS('Budget expense Details'!$E$4:$E$86,'Budget expense Details'!$C$4:$C$86,PROJECTS!B33) -> 3951.58 | K33: =IF(I33-J33=0,0,I33-J33) -> 4048.42 | L33: 0.5 | M33: =IF(L33<0.1,"Non debuté",IF(L33<1,"En cours","Terminé")) -> En cours
A34: =A28+1 -> 15 | B34: Permaculture | Malanga Cité | C34: Malanga Cité | D34: Agriculture et élevage | E34: Cahier de charges | F34: Formation et production | G34: FY2024 | I34: 32094.75 | J34: =SUMIFS('Budget expense Details'!$E$4:$E$86,'Budget expense Details'!$C$4:$C$86,PROJECTS!B34) -> 14807.3 | K34: =IF(I34-J34=0,0,I34-J34) -> 17287.45 | L34: 0.6 | M34: =IF(L34<0.1,"Non debuté",IF(L34<1,"En cours","Terminé")) -> En cours
A35: =A29+1 -> 16 | B35: Apiculture | Malanga Cité | C35: Malanga Cité | D35: Agriculture et élevage | E35: Cahier de charges | F35: Formation et installation ruches | G35: FY2024 | I35: 892.5 | J35: =SUMIFS('Budget expense Details'!$E$4:$E$86,'Budget expense Details'!$C$4:$C$86,PROJECTS!B35) -> 892.5 | K35: =IF(I35-J35=0,0,I35-J35) -> 0 | L35: 1 | M35: =IF(L35<0.1,"Non debuté",IF(L35<1,"En cours","Terminé")) -> Terminé
A36: =A30+1 -> 17 | B36: Electricité | Malanga Cité | C36: Malanga Cité | D36: Energie | E36: Cahier de charges | F36: Raccordement SNEL | G36: FY2024 | I36: 700000 | J36: =SUMIFS('Budget expense Details'!$E$4:$E$86,'Budget expense Details'!$C$4:$C$86,PROJECTS!B36) -> 700000 | K36: =IF(I36-J36=0,0,I36-J36) -> 0 | L36: 0.5 | M36: =IF(L36<0.1,"Non debuté",IF(L36<1,"En cours","Terminé")) -> En cours
A37: =A31+1 -> 18 | B37: Adduction d’eau | Malanga Cité | C37: Malanga Cité | D37: Energie | E37: Cahier de charges | F37: Etudes et forage | G37: FY2024 | I37: 24000 | J37: =SUMIFS('Budget expense Details'!$E$4:$E$86,'Budget expense Details'!$C$4:$C$86,PROJECTS!B37) -> 0 | K37: =IF(I37-J37=0,0,I37-J37) -> 24000 | L37: 0.1 | M37: =IF(L37<0.1,"Non debuté",IF(L37<1,"En cours","Terminé")) -> En cours
A38: =A32+1 -> 14 | B38: Bourse universitaire | Malanga Cité | C38: Malanga Cité | D38: Education | E38: Cahier de charges | F38: Prise en charge études | G38: FY2024 | I38: 14340 | J38: =SUMIFS('Budget expense Details'!$E$4:$E$86,'Budget expense Details'!$C$4:$C$86,PROJECTS!B38) -> 5439.2 | K38: =IF(I38-J38=0,0,I38-J38) -> 8900.8 | L38: 1 | M38: =IF(L38<0.1,"Non debuté",IF(L38<1,"En cours","Terminé")) -> Terminé
A39: =A33+1 -> 15 | B39: Ponts et route | Malanga Cité | C39: Malanga Cité | D39: Infrastructures | E39: Cahier de charges | F39: Construction ponts et route | G39: FY2024 | I39: 30000 | J39: =SUMIFS('Budget expense Details'!$E$4:$E$86,'Budget expense Details'!$C$4:$C$86,PROJECTS!B39) -> 0 | K39: =IF(I39-J39=0,0,I39-J39) -> 30000 | L39: 0.1 | M39: =IF(L39<0.1,"Non debuté",IF(L39<1,"En cours","Terminé")) -> En cours
A40: =A34+1 -> 16 | B40: Renforcement maisons | Malanga Cité | C40: Malanga Cité | D40: Infrastructures | E40: Cahier de charges | F40: Réhabilitation structures | G40: FY2024 | I40: 10000 | J40: =SUMIFS('Budget expense Details'!$E$4:$E$86,'Budget expense Details'!$C$4:$C$86,PROJECTS!B40) -> 0 | K40: =IF(I40-J40=0,0,I40-J40) -> 10000 | L40: 0 | M40: =IF(L40<0.1,"Non debuté",IF(L40<1,"En cours","Terminé")) -> Non debuté
A41: =A35+1 -> 17 | B41: Etude passerelle | Malanga Cité | C41: Malanga Cité | D41: Infrastructures | E41: Cahier de charges | F41: Etude faisabilité | G41: FY2024 | I41: 2000 | J41: =SUMIFS('Budget expense Details'!$E$4:$E$86,'Budget expense Details'!$C$4:$C$86,PROJECTS!B41) -> 0 | K41: =IF(I41-J41=0,0,I41-J41) -> 2000 | L41: 0 | M41: =IF(L41<0.1,"Non debuté",IF(L41<1,"En cours","Terminé")) -> Non debuté
A42: =A36+1 -> 18 | B42: Football | Malanga Cité | C42: Malanga Cité | D42: Loisirs | E42: Cahier de charges | F42: Aménagement terrain | G42: FY2024 | I42: 8000 | J42: =SUMIFS('Budget expense Details'!$E$4:$E$86,'Budget expense Details'!$C$4:$C$86,PROJECTS!B42) -> 3951.58 | K42: =IF(I42-J42=0,0,I42-J42) -> 4048.42 | L42: 0.5 | M42: =IF(L42<0.1,"Non debuté",IF(L42<1,"En cours","Terminé")) -> En cours
...

Sheet Budget expense Details
A1: Budget expense Details
A3: N° | B3: Date | C3: Projets | D3: Motif | E3: Budget dépensé($)
A4: 1 | B4: 25/06/2026 | C4: Assistance médicale | D4: Initial | E4: 1523.64
A5: 2 | B5: 25/06/2026 | C5: Soutien financier Centre de coupe et couture | D5: Initial | E5: 27677.49
A6: 3 | B6: 25/06/2026 | C6: Réunion avec le clan Nanga (boissons non alcoolisées) | D6: Initial | E6: 3400
A7: 4 | B7: 25/06/2026 | C7: Dons de fin d’année aux autorités locales | D7: Initial | E7: 2500
A8: 5 | B8: 25/06/2026 | C8: Trust Fund - Clan Nanga | D8: Initial | E8: 25000
A9: 6 | B9: 25/06/2026 | C9: Contribution à l’association des personnes handicapées de Songololo | D9: Initial | E9: 600
A10: 7 | B10: 25/06/2026 | C10: Puits de forage | D10: Initial | E10: 37719
A11: 8 | B11: 25/06/2026 | C11: École PPC | D11: Initial | E11: 317067.34
A12: 9 | B12: 25/06/2026 | C12: Poste de police | D12: Initial | E12: 27766.2
A13: 10 | B13: 25/06/2026 | C13: Lutte anti-vectorielle | D13: Initial | E13: 11400
A14: 11 | B14: 25/06/2026 | C14: Forage Ecole PPC | D14: Initial | E14: 20535
A15: 12 | B15: 25/06/2026 | C15: Permaculture | Malanga Gare | D15: Initial | E15: 14807.3
... A35: 32 | B35: 25/06/2026 | C35: Football | Zamba 1er | D35: Initial | E35: 13151.58
A36: 33
A37: 34
A38: 35
A39: 36
A40: 37
A41: 38
A42: 39
A43: 40
A44: 41
A45: 42
A46: 43
A47: 44
... A86: 83

Sheet Params
A1: Liste de projet
A2: {=_xlfn.UNIQUE(PROJECTS!B5:B124)} -> Assistance médicale
A3: Soutien financier Centre de coupe et couture
A4: Réunion avec le clan Nanga (boissons non alcoolisées)
A5: Dons de fin d’année aux autorités locales
A6: Trust Fund - Clan Nanga
A7: Contribution à l’association des personnes handicapées de Songololo
A8: Puits de forage
A9: École PPC
A10: Poste de police
A11: Batteries pour le centre hospitalier de Malanga
A12: Lutte anti-vectorielle
A13: Mwinda
A14: Forage Ecole PPC
... A47: Centre médical | Multi-villages
A48: 0
