Workbook

Sheet Sheet1
A4: PAIE PPC AOUT 2026
BA5: 1.3 | BB5: 1.6 | BC5: 2 | BD5: 0.1 | BE5: 0.25
G6: CLASSE | I6: BASE | K6: JOURS PRESTES | N6: JOURS FERIES | Q6: JOURS CONGES | T6: JOURS MALADIES | W6: INDEMNITES | AA6: MONT HEURES SUPP | AB6: Brut Impos | AC6: Sal Impos | AD6: DEDUCTIONS EMPLOYEE | AH6: Net à Payer | AI6: DEDUCTION PATRONALE | AN6: Gross Salary | AO6: M.B | AP6: Provision PPE | AQ6: Prov. S. Méd. | AR6: TVA | AS6: Total Gén
A7: MATR | B7: NOMS | C7: FONCTIONS | D7: NUMERO CNSS | E7: NUMERO DE COMPTE | F7: BANQUE | K7: Jrs | L7: Tx/Jr | M7: Base | N7: Jrs | O7: Tx/Jr | P7: Base | Q7: Jrs | R7: Tx/Jr | S7: Base | T7: Jrs | U7: Tx/Jr | V7: Base | W7: Logm | X7: Trs / Jrs | Y7: Trs Dimanche& Feries | Z7: Tot Trs | AD7: Cnss/O | AE7: Ipr | AF7: Total | AG7: AVANCES | AI7: Cnss/P | AJ7: Inpp | AK7: Onem | AL7: Total | AU7: Sundays | AV7: Overtime 130% (Hrs) | AW7: Overtime 160% (Hrs) | AX7: Overtime 200% (Hrs) | AY7: Overtime 10% (Hrs) | AZ7: Overtime 25% (Hrs) | BA7: Overtime 130% US$ | BB7: Overtime 160% US$ | BC7: Overtime 200% US$ | BD7: Overtime 10% US$ | BE7: Overtime 25% US$ | BF7: Total overtime
G8: Classification | I8: sal base bareme | K8: Pointage | L8: base/pointage | M8: base mensuel | O8: base/pointage | P8: Jrsxtx | R8: base/pointage | S8: Jrsxtx | U8: 0.667*tx | V8: Jrsxtx | W8: 30%base pres, fer, cong,mal | X8: Nbr jr x course | Y8: Awxtras | Z8: x+y | AA8: BH | AB8: Bases+HS | AC8: AB-AD | AD8: BIx5% | AE8: Tranches | AF8: AD+AE | AH8: BI,Log, inden-avance-deduct | AI8: 13%BI | AJ8: 2%BI | AK8: 0.5%BI | AL8: AI+AJ+AK | AN8: AD+AE+AG+AH+AL | AO8: %AN | AP8: forfait | AQ8: Forfait | AR8: 16%AN | AS8: AN+AO+AP+AQ+AR | BA8: (Txj/8)*av*ba

Sheet Sheet1 (2)
A4: PAIE PPC AOUT 2026
BA5: 1.3 | BB5: 1.6 | BC5: 2 | BD5: 0.1 | BE5: 0.25
G6: CLASSE | I6: BASE | K6: JOURS PRESTES | N6: JOURS FERIES | Q6: JOURS CONGES | T6: JOURS MALADIES | W6: INDEMNITES | AA6: MONT HEURES SUPP | AB6: Brut Impos | AC6: Sal Impos | AD6: DEDUCTIONS EMPLOYEE | AH6: Net à Payer | AI6: DEDUCTION PATRONALE | AN6: Gross Salary | AO6: M.B | AP6: Provision PPE | AQ6: Prov. S. Méd. | AR6: TVA | AS6: Total Gén
A7: MATR | B7: NOMS | C7: FONCTIONS | D7: NUMERO CNSS | E7: NUMERO DE COMPTE | F7: BANQUE | K7: Jrs | L7: Tx/Jr | M7: Base | N7: Jrs | O7: Tx/Jr | P7: Base | Q7: Jrs | R7: Tx/Jr | S7: Base | T7: Jrs | U7: Tx/Jr | V7: Base | W7: Logm | X7: Trs / Jrs | Y7: Trs Dimanche& Feries | Z7: Tot Trs | AD7: Cnss/O | AE7: Ipr | AF7: Total | AG7: AVANCES | AI7: Cnss/P | AJ7: Inpp | AK7: Onem | AL7: Total | AU7: Sundays | AV7: Overtime 130% (Hrs) | AW7: Overtime 160% (Hrs) | AX7: Overtime 200% (Hrs) | AY7: Overtime 10% (Hrs) | AZ7: Overtime 25% (Hrs) | BA7: Overtime 130% US$ | BB7: Overtime 160% US$ | BC7: Overtime 200% US$ | BD7: Overtime 10% US$ | BE7: Overtime 25% US$ | BF7: Total overtime
G8: Classification | I8: sal base bareme | K8: 13 | L8: 10 | M8: =L8*K8 -> 130 | N8: 1 | O8: 10 | P8: =N8*O8 -> 10 | Q8: 2 | R8: 10 | S8: =Q8*R8 -> 20 | T8: 3 | U8: =0.667*L8 -> 6.67 | V8: =T8*U8 -> 20.01 | W8: =0.3*(M8+P8+S8+V8) -> 54.003 | X8: =K8*5400 -> 70200 | Y8: 20000 | Z8: =X8+Y8 -> 90200 | AA8: 50000 | AB8: =M8+P8+S8+V8+AA8 -> 50180.01 | AC8: AB-AD | AD8: =AB8*5% -> 2509.0005 | AE8: Tranches | AF8: AD+AE | AH8: BI,Log, inden-avance-deduct | AI8: 13%BI | AJ8: 2%BI | AK8: 0.5%BI | AL8: AI+AJ+AK | AN8: AD+AE+AG+AH+AL | AO8: %AN | AP8: forfait | AQ8: Forfait | AR8: 16%AN | AS8: AN+AO+AP+AQ+AR | BA8: (Txj/8)*av*ba

Sheet PPC Usine-Zamba
I3: JOURS PRESTES | L3: JOURS FERIES | O3: JOURS CONGES | R3: JOURS MALADIES | U3: INDEMNITES | AD3: DEDUCTIONS EMPLOYEE | AI3: DEDUCTION PATRONALE | AZ3: 1.3 | BA3: 1.6 | BB3: 2 | BC3: 0.1 | BD3: 0.25
A5: MATR | B5: NOMS | C5: FONCTIONS | D5: NUMERO CNSS | E5: NUMERO DE COMPTE | F5: BANQUE | G5: Dépendant | H5: BASE | I5: Jrs | J5: Tx/Jr | K5: Base2 | L5: Jrs3 | M5: Tx/Jr4 | N5: Base5 | O5: Jrs6 | P5: Tx/Jr7 | Q5: Base8 | R5: Jrs9 | S5: Tx/Jr10 | T5: Base11 | U5: Logm | V5: cout/Trs | W5: Trs / Jrs | X5: Jrs/feries&Dimanche | Y5: Trs Dimanche& Feries | Z5: Tot Trs | AA5: MONT HEURES SUPP | AB5: Brut Impos | AC5: Sal Impos | AD5: Cnss/O | AE5: Ipr | AF5: Total | AG5: AVANCES | AH5: Net à Payer | AI5: Cnss/P | AJ5: Inpp | AK5: Onem | AL5: Total12 | AM5: Gross Salary | AN5: M.B | AO5: Provision PPE | AP5: Prov. S. Méd. | AQ5: TVA | AR5: Total Gén | AT5: Sundays | AU5: Overtime 130% (Hrs) | AV5: Overtime 160% (Hrs) | AW5: Overtime 200% (Hrs) | AX5: Overtime 10% (Hrs) | AY5: Overtime 25% (Hrs) | AZ5: Overtime 130% US$ | BA5: Overtime 160% US$ | BB5: Overtime 200% US$ | BC5: Overtime 10% US$ | BD5: Overtime 25% US$ | BE5: Total overtime
A6: CHRS_PPC0118 | B6: TULOMBA NSIMBA BIENVENU | C6: BAGS STORE CONTROLLER | E6: 544200035353086 | F6: EBCDC | G6: 5 | I6: 13 | J6: 13.201175 | K6: =J6*I6 -> 171.61527 | L6: 0 | M6: =Tableau2[[#This Row],[Tx/Jr]] -> 13.201175 | N6: =L6*M6 -> 0 | O6: 0 | P6: =Tableau2[[#This Row],[Tx/Jr]] -> 13.201175 | Q6: =O6*P6 -> 0 | R6: 0 | S6: =0.667*J6 -> 8.8051835 | T6: =R6*S6 -> 0 | U6: =0.3*(K6+N6+Q6+T6) -> 51.484581 | V6: 1.17 | W6: =I6*V6 -> 15.21 | X6: 0 | Y6: =X6*V6 -> 0 | Z6: =W6+Y6 -> 15.21 | AA6: =BE6 -> 111.71494 | AB6: =K6+N6+Q6+T6+AA6 -> 283.33021 | AC6: =Tableau2[[#This Row],[Brut Impos]]-Tableau2[[#This Row],[Cnss/O]] -> 269.1637 | AD6: =AB6*5% -> 14.166511 | AE6: =+'Moteur IPR'!P6 -> 28.730143 | AF6: =+AD6+AE6 -> 42.896654 | AG6: 0 | AH6: =+AB6+U6+Z6-AG6-AF6 -> 307.12814 | AI6: =+AB6*0.13 -> 36.832928 | AJ6: =2%*AB6 -> 5.6666042 | AK6: =0.5%*AB6 -> 1.4166511 | AL6: =+AI6+AJ6+AK6 -> 43.916183 | AM6: =+AD6+AE6+AG6+AH6+AL6 -> 393.94098 | AN6: 0 | AO6: 25 | AP6: 70 | AQ6: =0.16*AM6 -> 63.030556 | AR6: =AM6+AN6+AO6+AP6+AQ6 -> 551.97153 | AU6: 3 | AV6: 0 | AW6: 0 | AX6: 8 | AY6: 44 | AZ6: =($J6/8)*$AU6*(1+0.3) -> 6.4355727 | BA6: =($J6/8)*$AV6*(1+0.6) -> 0 | BB6: =($J6/8)*2*$AW6 -> 0 | BC6: =($J6/8)*$AX6*(1+0.1) -> 14.521292 | BD6: =($J6/8)*$AY6*(1+0.25) -> 90.758076 | BE6: =AZ6+BA6+BB6+BC6+BD6 -> 111.71494
A7: CHRS_PPC0096 | B7: NKULUKI MBOBA BODRI | C7: BAGS STORE CONTROLLER | E7: 260000143861032 | F7: EBCDC | G7: 3 | I7: 13 | J7: 13.201175 | K7: 171.61527 | L7: 0 | M7: 13.201175 | N7: 0 | O7: 0 | P7: 13.201175 | Q7: 0 | R7: 0 | S7: 8.8051835 | T7: 0 | U7: 51.484581 | V7: 1.17 | W7: 15.21 | X7: 0 | Y7: 0 | Z7: 15.21 | AA7: 94.470907 | AB7: 266.08618 | AC7: 252.78187 | AD7: 13.304309 | AE7: 27.6972 | AF7: 41.001509 | AG7: 0 | AH7: 291.77925 | AI7: 34.591203 | AJ7: 5.3217236 | AK7: 1.3304309 | AL7: 41.243358 | AM7: 374.02412 | AN7: 0 | AO7: 25 | AP7: 70 | AQ7: 59.843859 | AR7: 528.86798 | AU7: 0 | AV7: 0 | AW7: 0 | AX7: 10 | AY7: 37 | AZ7: 0 | BA7: 0 | BB7: 0 | BC7: 18.151615 | BD7: 76.319291 | BE7: 94.470907
A8: CHRS_PPC0115 | B8: SUNGA MAVITA ARNAL | C8: BAGS STORE CONTROLLER | E8: 544200035354250 | F8: EBCDC | G8: 3 | I8: 13 | J8: 12.541338 | K8: 163.03739 | L8: 0 | M8: 12.541338 | N8: 0 | O8: 0 | P8: 12.541338 | Q8: 0 | R8: 0 | S8: 8.3650724 | T8: 0 | U8: 48.911218 | V8: 1.17 | W8: 15.21 | X8: 0 | Y8: 0 | Z8: 15.21 | AA8: 84.340498 | AB8: 247.37789 | AC8: 235.009 | AD8: 12.368895 | AE8: 25.191225 | AF8: 37.56012 | AG8: 0 | AH8: 273.93899 | AI8: 32.159126 | AJ8: 4.9475578 | AK8: 1.2368895 | AL8: 38.343573 | AM8: 349.84268 | AN8: 0 | AO8: 25 | AP8: 70 | AQ8: 55.974829 | AR8: 500.81751 | AU8: 0 | AV8: 0 | AW8: 0 | AX8: 8 | AY8: 36 | AZ8: 0 | BA8: 0 | BB8: 0 | BC8: 13.795472 | BD8: 70.545026 | BE8: 84.340498
A9: CHRS_PPC0042 | B9: LUSAKU TUMBA HERBI | C9: BAGS STORE CONTROLLER | E9: 544200035354347 | F9: EBCDC | G9: 3 | I9: 13 | J9: 12.541338 | K9: 163.03739 | L9: 0 | M9: 12.541338 | N9: 0 | O9: 0 | P9: 12.541338 | Q9: 0 | R9: 0 | S9: 8.3650724 | T9: 0 | U9: 48.911218 | V9: 1.17 | W9: 15.21 | X9: 0 | Y9: 0 | Z9: 15.21 | AA9: 122.66996 | AB9: 285.70736 | AC9: 271.42199 | AD9: 14.285368 | AE9: 30.325457 | AF9: 44.610824 | AG9: 0 | AH9: 305.21775 | AI9: 37.141956 | AJ9: 5.7141471 | AK9: 1.4285368 | AL9: 44.28464 | AM9: 394.11321 | AN9: 0 | AO9: 25 | AP9: 70 | AQ9: 63.058114 | AR9: 552.17133 | AU9: 6 | AV9: 2 | AW9: 0 | AX9: 10 | AY9: 45 | AZ9: 12.227804 | BA9: 5.0165352 | BB9: 0 | BC9: 17.24434 | BD9: 88.181282 | BE9: 122.66996
B10: NSITAKODILA DIBASANA | C10: BOILER MAKER | I10: 11 | J10: 12.541338 | K10: 137.95472 | L10: 0 | M10: 12.541338 | N10: 0 | O10: 0 | P10: 12.541338 | Q10: 0 | R10: 0 | S10: 8.3650724 | T10: 0 | U10: 41.386415 | V10: 1.17 | W10: 12.87 | X10: 6 | Y10: 7.02 | Z10: 19.89 | AA10: 147.04719 | AB10: 285.0019 | AC10: 270.75181 | AD10: 14.250095 | AE10: 30.325457 | AF10: 44.575552 | AG10: 0 | AH10: 301.70277 | AI10: 37.050248 | AJ10: 5.7000381 | AK10: 1.4250095 | AL10: 44.175295 | AM10: 390.45362 | AN10: 0 | AO10: 25 | AP10: 70 | AQ10: 62.472578 | AR10: 547.92619 | AT10: 6 | AU10: 6 | AV10: 0 | AW10: 43 | AX10: 0 | AY10: 0 | AZ10: 12.227804 | BA10: 0 | BB10: 134.81938 | BC10: 0 | BD10: 0 | BE10: 147.04719
A11: CHRS_PPC0050 | B11: MAKOSI LUNZAYILADIO JOHN | C11: BOILER MAKER | E11: 544200132484230 | F11: EBCDC | G11: 3 | I11: 11 | J11: 12.541338 | K11: 137.95472 | L11: 0 | M11: 12.541338 | N11: 0 | O11: 0 | P11: 12.541338 | Q11: 0 | R11: 0 | S11: 8.3650724 | T11: 0 | U11: 41.386415 | V11: 1.17 | W11: 12.87 | X11: 3 | Y11: 3.51 | Z11: 16.38 | AA11: 139.89862 | AB11: 277.85334 | AC11: 263.96068 | AD11: 13.892667 | AE11: 29.273412 | AF11: 43.166079 | AG11: 0 | AH11: 292.45368 | AI11: 36.120934 | AJ11: 5.5570668 | AK11: 1.3892667 | AL11: 43.067268 | AM11: 378.68703 | AN11: 0 | AO11: 25 | AP11: 70 | AQ11: 60.589924 | AR11: 534.27695 | AU11: 15.5 | AV11: 7 | AW11: 28.67 | AX11: 0.5 | AY11: 0 | AZ11: 31.588495 | BA11: 17.557873 | BB11: 89.89004 | BC11: 0.86221698 | BD11: 0 | BE11: 139.89862
A12: CHRS_PPC0105 | B12: NTEDIKA NTEDIKA Edgard | C12: BUILDER | E12: 544200184545197 | F12: EBCDC | G12: 5 | I12: 11 | J12: 9.0685128 | K12: 99.753641 | L12: 0 | M12: 9.0685128 | N12: 0 | O12: 0 | P12: 9.0685128 | Q12: 0 | R12: 0 | S12: 6.048698 | T12: 0 | U12: 29.926092 | V12: 1.17 | W12: 12.87 | X12: 0 | Y12: 0 | Z12: 12.87 | AA12: 23.521455 | AB12: 123.2751 | AC12: 117.11134 | AD12: 6.1637548 | AE12: 8.2030745 | AF12: 14.366829 | AG12: 0 | AH12: 151.70436 | AI12: 16.025762 | AJ12: 2.4655019 | AK12: 0.61637548 | AL12: 19.10764 | AM12: 185.17883 | AN12: 0 | AO12: 25 | AP12: 70 | AQ12: 29.628612 | AR12: 309.80744 | AU12: 13.5 | AV12: 2 | AW12: 0 | AX12: 0 | AY12: 0 | AZ12: 19.89405 | BA12: 3.6274051 | BB12: 0 | BC12: 0 | BD12: 0 | BE12: 23.521455
A13: CHRS_PPC0067 | B13: MBELOLO KIESE Philemon | C13: CARPENTER | E13: 544200184583221 | F13: EBCDC | G13: 4 | I13: 11 | J13: 12.541338 | K13: 137.95472 | L13: 0 | M13: 12.541338 | N13: 0 | O13: 0 | P13: 12.541338 | Q13: 0 | R13: 0 | S13: 8.3650724 | T13: 0 | U13: 41.386415 | V13: 1.17 | W13: 12.87 | X13: 0 | Y13: 0 | Z13: 12.87 | AA13: 32.529095 | AB13: 170.48381 | AC13: 161.95962 | AD13: 8.5241906 | AE13: 14.574428 | AF13: 23.098618 | AG13: 0 | AH13: 201.64161 | AI13: 22.162896 | AJ13: 3.4096763 | AK13: 0.85241906 | AL13: 26.424991 | AM13: 251.16522 | AN13: 0 | AO13: 25 | AP13: 70 | AQ13: 40.186435 | AR13: 386.35165 | AU13: 13.5 | AV13: 2 | AW13: 0 | AX13: 0 | AY13: 0 | AZ13: 27.51256 | BA13: 5.0165352 | BB13: 0 | BC13: 0 | BD13: 0 | BE13: 32.529095
A14: CHRS_PPC0054 | B14: WETE MANDIANGU PAUL | C14: CLEANER | E14: 544200031884948 | F14: EBCDC | G14: 1 | I14: 11 | J14: 7.9502631 | K14: 87.452894 | L14: 0 | M14: 7.9502631 | N14: 0 | O14: 0 | P14: 7.9502631 | Q14: 0 | R14: 0 | S14: 5.3028255 | T14: 0 | U14: 26.235868 | V14: 1.17 | W14: 12.87 | X14: 3 | Y14: 3.51 | Z14: 16.38 | AA14: 65.887805 | AB14: 153.3407 | AC14: 145.67366 | AD14: 7.667035 | AE14: 13.130898 | AF14: 20.797933 | AG14: 0 | AH14: 175.15863 | AI14: 19.934291 | AJ14: 3.066814 | AK14: 0.7667035 | AL14: 23.767808 | AM14: 219.72438 | AN14: 0 | AO14: 25 | AP14: 70 | AQ14: 35.1559 | AR14: 349.88028 | AU14: 11 | AV14: 0 | AW14: 26 | AX14: 0 | AY14: 0 | AZ14: 14.211095 | BA14: 0 | BB14: 51.67671 | BC14: 0 | BD14: 0 | BE14: 65.887805
A15: CHRS_PPC0016 | B15: BOLA MANZA HELDER | C15: CLEANER | E15: 544200031835866 | F15: EBCDC | G15: 1 | I15: 11 | J15: 7.9502631 | K15: 87.452894 | L15: 0 | M15: 7.9502631 | N15: 0 | O15: 0 | P15: 7.9502631 | Q15: 0 | R15: 0 | S15: 5.3028255 | T15: 0 | U15: 26.235868 | V15: 1.17 | W15: 12.87 | X15: 4 | Y15: 4.68 | Z15: 17.55 | AA15: 83.775897 | AB15: 171.22879 | AC15: 162.66735 | AD15: 8.5614396 | AE15: 15.62897 | AF15: 24.19041 | AG15: 0 | AH15: 190.82425 | AI15: 22.259743 | AJ15: 3.4245758 | AK15: 0.85614396 | AL15: 26.540463 | AM15: 241.55512 | AN15: 0 | AO15: 25 | AP15: 70 | AQ15: 38.64882 | AR15: 375.20394 | AU15: 11 | AV15: 0 | AW15: 35 | AX15: 0 | AY15: 0 | AZ15: 14.211095 | BA15: 0 | BB15: 69.564802 | BC15: 0 | BD15: 0 | BE15: 83.775897
A16: CHRS_PPC0005 | B16: BANZA MUSUAMBA Cyntiche | C16: CLEANER | G16: 0 | I16: 11 | J16: 7.9502631 | K16: 87.452894 | L16: 0 | M16: 7.9502631 | N16: 0 | O16: 0 | P16: 7.9502631 | Q16: 0 | R16: 0 | S16: 5.3028255 | T16: 0 | U16: 26.235868 | V16: 1.17 | W16: 12.87 | X16: 6 | Y16: 7.02 | Z16: 19.89 | AA16: 132.17312 | AB16: 219.62602 | AC16: 208.64472 | AD16: 10.981301 | AE16: 22.844534 | AF16: 33.825835 | AG16: 0 | AH16: 231.92605 | AI16: 28.551382 | AJ16: 4.3925204 | AK16: 1.0981301 | AL16: 34.042033 | AM16: 299.79392 | AN16: 0 | AO16: 25 | AP16: 70 | AQ16: 47.967027 | AR16: 442.76095 | AU16: 14 | AV16: 8 | AW16: 51 | AX16: 0 | AY16: 0 | AZ16: 18.086849 | BA16: 12.720421 | BB16: 101.36585 | BC16: 0 | BD16: 0 | BE16: 132.17312
A17: CHRS_PPC0004 | B17: BALOKI NYAMBU GLORIA | C17: CRUSHER OPERATOR | E17: 544200031507812 | F17: EBCDC | G17: 4 | I17: 12 | J17: 13.201175 | K17: 158.4141 | L17: 0 | M17: 13.201175 | N17: 0 | O17: 0 | P17: 13.201175 | Q17: 0 | R17: 0 | S17: 8.8051835 | T17: 0 | U17: 47.524229 | V17: 1.17 | W17: 14.04 | X17: 0 | Y17: 0 | Z17: 14.04 | AA17: 101.64905 | AB17: 260.06314 | AC17: 247.05998 | AD17: 13.003157 | AE17: 26.318278 | AF17: 39.321435 | AG17: 0 | AH17: 282.30594 | AI17: 33.808208 | AJ17: 5.2012628 | AK17: 1.3003157 | AL17: 40.309787 | AM17: 361.93716 | AN17: 0 | AO17: 25 | AP17: 70 | AQ17: 57.909945 | AR17: 514.8471 | AU17: 6 | AV17: 0 | AW17: 0 | AX17: 8 | AY17: 36 | AZ17: 12.871145 | BA17: 0 | BB17: 0 | BC17: 14.521292 | BD17: 74.256608 | BE17: 101.64905
A18: CHRS_PPC0093 | B18: NKAYILU MPANGU PATRICK | C18: CRUSHER OPERATOR | E18: 544200178241749 | F18: EBCDC | G18: 0 | I18: 13 | J18: 12.541338 | K18: 163.03739 | L18: 0 | M18: 12.541338 | N18: 0 | O18: 0 | P18: 12.541338 | Q18: 0 | R18: 0 | S18: 8.3650724 | T18: 0 | U18: 48.911218 | V18: 1.17 | W18: 15.21 | X18: 0 | Y18: 0 | Z18: 15.21 | AA18: 89.74895 | AB18: 252.78634 | AC18: 240.14703 | AD18: 12.639317 | AE18: 27.56988 | AF18: 40.209197 | AG18: 0 | AH18: 276.69836 | AI18: 32.862225 | AJ18: 5.0557269 | AK18: 1.2639317 | AL18: 39.181883 | AM18: 356.08944 | AN18: 0 | AO18: 25 | AP18: 70 | AQ18: 56.974311 | AR18: 508.06376 | AU18: 0 | AV18: 0 | AW18: 0 | AX18: 10 | AY18: 37 | AZ18: 0 | BA18: 0 | BB18: 0 | BC18: 17.24434 | BD18: 72.50461 | BE18: 89.74895
A19: CHRS_PPC0090 | B19: NGABU MAKANZU Gabriel | C19: CRUSHER OPERATOR | E19: 544100187466260 | F19: EBCDC | G19: 0 | I19: 13 | J19: 4.5538401 | K19: 59.199921 | L19: 0 | M19: 4.5538401 | N19: 0 | O19: 0 | P19: 4.5538401 | Q19: 0 | R19: 0 | S19: 3.0374114 | T19: 0 | U19: 17.759976 | V19: 1.17 | W19: 15.21 | X19: 0 | Y19: 0 | Z19: 15.21 | AA19: 30.624575 | AB19: 89.824496 | AC19: 85.333271 | AD19: 4.4912248 | AE19: 4.3478168 | AF19: 8.8390416 | AG19: 0 | AH19: 113.95543 | AI19: 11.677185 | AJ19: 1.7964899 | AK19: 0.44912248 | AL19: 13.922797 | AM19: 136.71727 | AN19: 0 | AO19: 25 | AP19: 70 | AQ19: 21.874763 | AR19: 253.59203 | AU19: 0 | AV19: 0 | AW19: 0 | AX19: 8 | AY19: 36 | AZ19: 0 | BA19: 0 | BB19: 0 | BC19: 5.0092241 | BD19: 25.615351 | BE19: 30.624575
A20: CHRS_PPC0017 | B20: BONGENDE BOFALE ALAIN | C20: DRILLER OPERATOR | G20: 0 | I20: 13 | J20: 21.223401 | K20: 275.90421 | L20: 0 | M20: 21.223401 | N20: 0 | O20: 0 | P20: 21.223401 | Q20: 0 | R20: 0 | S20: 14.156008 | T20: 0 | U20: 82.771263 | V20: 1.17 | W20: 15.21 | X20: 0 | Y20: 0 | Z20: 15.21 | AA20: 53.85438 | AB20: 329.75859 | AC20: 313.27066 | AD20: 16.487929 | AE20: 38.538425 | AF20: 55.026355 | AG20: 0 | AH20: 372.7135 | AI20: 42.868617 | AJ20: 6.5951718 | AK20: 1.6487929 | AL20: 51.112581 | AM20: 478.85243 | AN20: 0 | AO20: 25 | AP20: 70 | AQ20: 76.61639 | AR20: 650.46882 | AU20: 5 | AV20: 0 | AW20: 0 | AX20: 8 | AY20: 4 | AZ20: 17.244013 | BA20: 0 | BB20: 0 | BC20: 23.345741 | BD20: 13.264626 | BE20: 53.85438
A21: CHRS_PPC0008 | B21: BAVEDILA LENDA RIGOBERT | C21: DRILLER OPERATOR | G21: 0 | I21: 14 | J21: 21.223401 | K21: 297.12761 | L21: 0 | M21: 21.223401 | N21: 0 | O21: 0 | P21: 21.223401 | Q21: 0 | R21: 0 | S21: 14.156008 | T21: 0 | U21: 89.138283 | V21: 1.17 | W21: 16.38 | X21: 0 | Y21: 0 | Z21: 16.38 | AA21: 100.9438 | AB21: 398.07141 | AC21: 378.16784 | AD21: 19.903571 | AE21: 48.273002 | AF21: 68.176573 | AG21: 0 | AH21: 435.41312 | AI21: 51.749283 | AJ21: 7.9614282 | AK21: 1.9903571 | AL21: 61.701069 | AM21: 565.29076 | AN21: 0 | AO21: 25 | AP21: 70 | AQ21: 90.446522 | AR21: 750.73729 | AU21: 16 | AV21: 0 | AW21: 0 | AX21: 10 | AY21: 5 | AZ21: 55.180842 | BA21: 0 | BB21: 0 | BC21: 29.182176 | BD21: 16.580782 | BE21: 100.9438
A22: CHRS_PPC0101 | B22: NSEMBOLO NSEMBOLO BLAISE | C22: DRIVER | E22: 260000145560375 | F22: EBCDC | G22: 2 | I22: 11 | J22: 14.763946 | K22: 162.40341 | L22: 0 | M22: 14.763946 | N22: 0 | O22: 0 | P22: 14.763946 | Q22: 0 | R22: 0 | S22: 9.847552 | T22: 0 | U22: 48.721022 | V22: 1.17 | W22: 12.87 | X22: 0 | Y22: 0 | Z22: 12.87 | AA22: 332.46561 | AB22: 494.86902 | AC22: 470.12557 | AD22: 24.743451 | AE22: 59.583994 | AF22: 84.327445 | AG22: 0 | AH22: 472.13259 | AI22: 64.332972 | AJ22: 9.8973803 | AK22: 2.4743451 | AL22: 76.704698 | AM22: 633.16474 | AN22: 0 | AO22: 25 | AP22: 70 | AQ22: 101.30636 | AR22: 829.47109 | AU22: 16 | AV22: 20 | AW22: 28 | AX22: 16 | AY22: 43 | AZ22: 38.38626 | BA22: 59.055784 | BB22: 103.34762 | BC22: 32.480681 | BD22: 99.195262 | BE22: 332.46561
A23: CHRS_PPC0116 | B23: TENDA DIWASILUA BINGI | C23: DRIVER | E23: 260000143824754 | F23: EBCDC | G23: 5 | I23: 12 | J23: 12.541338 | K23: 150.49606 | L23: 0 | M23: 12.541338 | N23: 0 | O23: 0 | P23: 12.541338 | Q23: 0 | R23: 0 | S23: 8.3650724 | T23: 0 | U23: 45.148817 | V23: 1.17 | W23: 14.04 | X23: 5 | Y23: 5.85 | Z23: 19.89 | AA23: 188.19845 | AB23: 338.69451 | AC23: 321.75978 | AD23: 16.934725 | AE23: 35.830614 | AF23: 52.76534 | AG23: 0 | AH23: 350.96798 | AI23: 44.030286 | AJ23: 6.7738902 | AK23: 1.6934725 | AL23: 52.497649 | AM23: 456.23097 | AN23: 0 | AO23: 25 | AP23: 70 | AQ23: 72.996956 | AR23: 624.22793 | AU23: 11 | AV23: 0 | AW23: 46 | AX23: 0 | AY23: 11 | AZ23: 22.417642 | BA23: 0 | BB23: 144.22539 | BC23: 0 | BD23: 21.555425 | BE23: 188.19845
B24: MABIALA BANIONGA CHANCARD | C24: DRIVER | G24: 0 | I24: 11 | J24: 12.541338 | K24: 137.95472 | L24: 0 | M24: 12.541338 | N24: 0 | O24: 0 | P24: 12.541338 | Q24: 0 | R24: 0 | S24: 8.3650724 | T24: 0 | U24: 41.386415 | V24: 1.17 | W24: 12.87 | X24: 0 | Y24: 0 | Z24: 12.87 | AA24: 110.28069 | AB24: 248.2354 | AC24: 235.82363 | AD24: 12.41177 | AE24: 35.830614 | AF24: 48.242384 | AG24: 0 | AH24: 254.24944 | AI24: 32.270603 | AJ24: 4.9647081 | AK24: 1.241177 | AL24: 38.476488 | AM24: 340.96831 | AN24: 0 | AO24: 25 | AP24: 70 | AQ24: 54.554929 | AR24: 490.52324 | AU24: 9.5 | AV24: 25.67 | AW24: 0 | AX24: 8 | AY24: 6.5 | AZ24: 19.36069 | BA24: 64.387229 | BB24: 0 | BC24: 13.795472 | BD24: 12.737296 | BE24: 110.28069
A25: CHRS_PPC0049 | B25: MAKENGELE KISAMBU HENOCK | C25: DRIVER | E25: 544200099112253 | F25: EBCDC | G25: 0 | I25: 12 | J25: 12.541338 | K25: 150.49606 | L25: 0 | M25: 12.541338 | N25: 0 | O25: 0 | P25: 12.541338 | Q25: 0 | R25: 0 | S25: 8.3650724 | T25: 0 | U25: 45.148817 | V25: 1.17 | W25: 14.04 | X25: 5 | Y25: 5.85 | Z25: 19.89 | AA25: 273.55793 | AB25: 424.05399 | AC25: 402.85129 | AD25: 21.202699 | AE25: 51.97552 | AF25: 73.178219 | AG25: 0 | AH25: 415.91459 | AI25: 55.127019 | AJ25: 8.4810798 | AK25: 2.1202699 | AL25: 65.728368 | AM25: 554.82117 | AN25: 0 | AO25: 25 | AP25: 70 | AQ25: 88.771388 | AR25: 738.59256 | AU25: 19 | AV25: 23 | AW25: 56.5 | AX25: 0 | AY25: 0 | AZ25: 38.721381 | BA25: 57.690155 | BB25: 177.1464 | BC25: 0 | BD25: 0 | BE25: 273.55793
A26: CHRS_PPC0078 | B26: MUTSHI MUNA JEAN PIERRE | C26: DRIVER | E26: 522100130128429 | F26: EBCDC | G26: 5 | J26: 12.541338 | K26: 0 | L26: 0 | M26: 12.541338 | N26: 0 | O26: 0 | P26: 12.541338 | Q26: 0 | R26: 0 | S26: 8.3650724 | T26: 0 | U26: 0 | V26: 1.17 | W26: 0 | X26: 0 | Y26: 0 | Z26: 0 | AA26: 0 | AB26: 0 | AC26: 0 | AD26: 0 | AE26: 0.9 | AF26: 0.9 | AG26: 0 | AH26: -0.9 | AI26: 0 | AJ26: 0 | AK26: 0 | AL26: 0 | AM26: 0 | AN26: 0 | AO26: 25 | AP26: 70 | AQ26: 0 | AR26: 95 | AU26: 0 | AV26: 0 | AW26: 0 | AX26: 0 | AY26: 0 | AZ26: 0 | BA26: 0 | BB26: 0 | BC26: 0 | BD26: 0 | BE26: 0
A27: CHRS_PPC0023 | B27: DIKI NGANGU | C27: DRIVER | E27: 544100230516897 | F27: EBCDC | G27: 0 | I27: 14 | J27: 12.541338 | K27: 175.57873 | L27: 0 | M27: 12.541338 | N27: 0 | O27: 0 | P27: 12.541338 | Q27: 0 | R27: 0 | S27: 8.3650724 | T27: 0 | U27: 52.673619 | V27: 1.17 | W27: 16.38 | X27: 0 | Y27: 0 | Z27: 16.38 | AA27: 239.06925 | AB27: 414.64799 | AC27: 393.91559 | AD27: 20.732399 | AE27: 50.635164 | AF27: 71.367563 | AG27: 0 | AH27: 412.33404 | AI27: 53.904238 | AJ27: 8.2929597 | AK27: 2.0732399 | AL27: 64.270438 | AM27: 547.97204 | AN27: 0 | AO27: 25 | AP27: 70 | AQ27: 87.675527 | AR27: 730.64757 | AU27: 24 | AV27: 27.5 | AW27: 0 | AX27: 18 | AY27: 46 | AZ27: 48.911218 | BA27: 68.977359 | BB27: 0 | BC27: 31.039811 | BD27: 90.140866 | BE27: 239.06925
A28: CHRS_PPC0114 | B28: SENDA BAKOMISA | C28: DRIVER | E28: 544100264766336 | F28: EBCDC | G28: 0 | I28: 13 | J28: 12.541338 | K28: 163.03739 | L28: 0 | M28: 12.541338 | N28: 0 | O28: 0 | P28: 12.541338 | Q28: 0 | R28: 0 | S28: 8.3650724 | T28: 0 | U28: 48.911218 | V28: 1.17 | W28: 15.21 | X28: 0 | Y28: 0 | Z28: 15.21 | AA28: 154.49361 | AB28: 317.531 | AC28: 301.65445 | AD28: 15.87655 | AE28: 36.795994 | AF28: 52.672544 | AG28: 0 | AH28: 328.97967 | AI28: 41.27903 | AJ28: 6.35062 | AK28: 1.587655 | AL28: 49.217305 | AM28: 430.86952 | AN28: 0 | AO28: 25 | AP28: 70 | AQ28: 68.939124 | AR28: 594.80865 | AU28: 19 | AV28: 9 | AW28: 0 | AX28: 12 | AY28: 37 | AZ28: 38.721381 | BA28: 22.574408 | BB28: 0 | BC28: 20.693208 | BD28: 72.50461 | BE28: 154.49361
A29: CHRS_PPC0021 | B29: DIAWAKANA NKUMANI SEBASTIEN | C29: DRIVER | G29: 0 | I29: 14 | J29: 12.541338 | K29: 175.57873 | L29: 0 | M29: 12.541338 | N29: 0 | O29: 0 | P29: 12.541338 | Q29: 0 | R29: 0 | S29: 8.3650724 | T29: 0 | U29: 52.673619 | V29: 1.17 | W29: 16.38 | X29: 0 | Y29: 0 | Z29: 16.38 | AA29: 200.81817 | AB29: 376.39691 | AC29: 357.57706 | AD29: 18.819845 | AE29: 45.184385 | AF29: 64.00423 | AG29: 0 | AH29: 381.44629 | AI29: 48.931598 | AJ29: 7.5279381 | AK29: 1.8819845 | AL29: 58.34152 | AM29: 503.79204 | AN29: 0 | AO29: 25 | AP29: 70 | AQ29: 80.606727 | AR29: 679.39877 | AU29: 12 | AV29: 22 | AW29: 0 | AX29: 18 | AY29: 46 | AZ29: 24.455609 | BA29: 55.181887 | BB29: 0 | BC29: 31.039811 | BD29: 90.140866 | BE29: 200.81817
A30: CHRS_PPC0085 | B30: NDANDU YAZOLA RODRIGUE | C30: ELECTRICIAN | E30: 544200130200365 | F30: EBCDC | G30: 0 | I30: 13 | J30: 24.592041 | K30: 319.69654 | L30: 0 | M30: 24.592041 | N30: 0 | O30: 0 | P30: 24.592041 | Q30: 0 | R30: 0 | S30: 16.402891 | T30: 0 | U30: 95.908961 | V30: 1.17 | W30: 15.21 | X30: 0 | Y30: 0 | Z30: 15.21 | AA30: 175.98679 | AB30: 495.68333 | AC30: 470.89916 | AD30: 24.784167 | AE30: 62.182701 | AF30: 86.966867 | AG30: 0 | AH30: 519.83542 | AI30: 64.438833 | AJ30: 9.9136666 | AK30: 2.4784167 | AL30: 76.830916 | AM30: 683.63321 | AN30: 0 | AO30: 25 | AP30: 70 | AQ30: 109.38131 | AR30: 888.01452 | AU30: 0 | AV30: 0 | AW30: 0 | AX30: 10 | AY30: 37 | AZ30: 0 | BA30: 0 | BB30: 0 | BC30: 33.814057 | BD30: 142.17274 | BE30: 175.98679
A31: CHRS_PPC0007 | B31: BATUKUEMI MATONDO Dieu | C31: ELECTRICIAN | E31: 544200170434316 | F31: EBCDC | G31: 4 | I31: 13 | J31: 12.541338 | K31: 163.03739 | L31: 0 | M31: 12.541338 | N31: 0 | O31: 0 | P31: 12.541338 | Q31: 0 | R31: 0 | S31: 8.3650724 | T31: 0 | U31: 48.911218 | V31: 1.17 | W31: 15.21 | X31: 0 | Y31: 0 | Z31: 15.21 | AA31: 84.340498 | AB31: 247.37789 | AC31: 235.009 | AD31: 12.368895 | AE31: 24.655242 | AF31: 37.024136 | AG31: 0 | AH31: 274.47497 | AI31: 32.159126 | AJ31: 4.9475578 | AK31: 1.2368895 | AL31: 38.343573 | AM31: 349.84268 | AN31: 0 | AO31: 25 | AP31: 70 | AQ31: 55.974829 | AR31: 500.81751 | AU31: 0 | AV31: 0 | AW31: 0 | AX31: 8 | AY31: 36 | AZ31: 0 | BA31: 0 | BB31: 0 | BC31: 13.795472 | BD31: 70.545026 | BE31: 84.340498
A32: CHRS_PPC0073 | B32: MISAMU NGOLO ROUSSEL | C32: ELECTRICIAN | E32: 544200098683707 | F32: EBCDC | G32: 0 | I32: 11 | J32: 12.541338 | K32: 137.95472 | L32: 0 | M32: 12.541338 | N32: 0 | O32: 0 | P32: 12.541338 | Q32: 0 | R32: 0 | S32: 8.3650724 | T32: 0 | U32: 41.386415 | V32: 1.17 | W32: 12.87 | X32: 2 | Y32: 2.34 | Z32: 15.21 | AA32: 134.50585 | AB32: 272.46057 | AC32: 258.83754 | AD32: 13.623028 | AE32: 30.373457 | AF32: 43.996485 | AG32: 0 | AH32: 285.0605 | AI32: 35.419874 | AJ32: 5.4492113 | AK32: 1.3623028 | AL32: 42.231388 | AM32: 371.28837 | AN32: 0 | AO32: 25 | AP32: 70 | AQ32: 59.406139 | AR32: 525.69451 | AU32: 0 | AV32: 0 | AW32: 16 | AX32: 8 | AY32: 36 | AZ32: 0 | BA32: 0 | BB32: 50.165352 | BC32: 13.795472 | BD32: 70.545026 | BE32: 134.50585
A33: CHRS_PPC0055 | B33: MANSATILA LUTETE JUNIOR | C33: ELECTRICIAN | E33: 544200219560354 | F33: EBCDC | G33: 1 | I33: 13 | J33: 12.541338 | K33: 163.03739 | L33: 0 | M33: 12.541338 | N33: 0 | O33: 0 | P33: 12.541338 | Q33: 0 | R33: 0 | S33: 8.3650724 | T33: 0 | U33: 48.911218 | V33: 1.17 | W33: 15.21 | X33: 0 | Y33: 0 | Z33: 15.21 | AA33: 100.01717 | AB33: 263.05456 | AC33: 249.90184 | AD33: 13.152728 | AE33: 28.452439 | AF33: 41.605168 | AG33: 0 | AH33: 285.57061 | AI33: 34.197093 | AJ33: 5.2610913 | AK33: 1.3152728 | AL33: 40.773457 | AM33: 367.94924 | AN33: 0 | AO33: 25 | AP33: 70 | AQ33: 58.871878 | AR33: 521.82112 | AU33: 0 | AV33: 0 | AW33: 0 | AX33: 8 | AY33: 44 | AZ33: 0 | BA33: 0 | BB33: 0 | BC33: 13.795472 | BD33: 86.221698 | BE33: 100.01717
A34: CHRS_PPC0120 | B34: WATUZOLA WENAYETO Osée | C34: ELECTRICIAN | E34: 544100227055064 | F34: EBCDC | G34: 1 | I34: 12 | J34: 12.541338 | K34: 150.49606 | L34: 0 | M34: 12.541338 | N34: 0 | O34: 0 | P34: 12.541338 | Q34: 0 | R34: 0 | S34: 8.3650724 | T34: 0 | U34: 45.148817 | V34: 1.17 | W34: 14.04 | X34: 0 | Y34: 0 | Z34: 14.04 | AA34: 84.340498 | AB34: 234.83655 | AC34: 223.09473 | AD34: 11.741828 | AE34: 24.511794 | AF34: 36.253622 | AG34: 0 | AH34: 257.77175 | AI34: 30.528752 | AJ34: 4.6967311 | AK34: 1.1741828 | AL34: 36.399666 | AM34: 330.42504 | AN34: 0 | AO34: 25 | AP34: 70 | AQ34: 52.868006 | AR34: 478.29304 | AU34: 0 | AV34: 0 | AW34: 0 | AX34: 8 | AY34: 36 | AZ34: 0 | BA34: 0 | BB34: 0 | BC34: 13.795472 | BD34: 70.545026 | BE34: 84.340498
A35: CHRS_PPC0069 | B35: MBILA MBAKULU DAVID | C35: ELECTRICIAN | E35: 544200219476061 | F35: EBCDC | G35: 1 | I35: 11 | J35: 12.541338 | K35: 137.95472 | L35: 0 | M35: 12.541338 | N35: 0 | O35: 0 | P35: 12.541338 | Q35: 0 | R35: 0 | S35: 8.3650724 | T35: 0 | U35: 41.386415 | V35: 1.17 | W35: 12.87 | X35: 1 | Y35: 1.17 | Z35: 14.04 | AA35: 109.42317 | AB35: 247.37789 | AC35: 235.009 | AD35: 12.368895 | AE35: 26.263192 | AF35: 38.632087 | AG35: 0 | AH35: 264.17222 | AI35: 32.159126 | AJ35: 4.9475578 | AK35: 1.2368895 | AL35: 38.343573 | AM35: 341.14788 | AN35: 0 | AO35: 25 | AP35: 70 | AQ35: 54.583661 | AR35: 490.73154 | AU35: 0 | AV35: 0 | AW35: 8 | AX35: 8 | AY35: 36 | AZ35: 0 | BA35: 0 | BB35: 25.082676 | BC35: 13.795472 | BD35: 70.545026 | BE35: 109.42317
A36: CHRS_PPC0086 | B36: NDUBU LUNTELADIO JOEL | C36: ELECTRICIAN | E36: 544100218325549 | F36: EBCDC | G36: 1 | I36: 11 | J36: 12.541338 | K36: 137.95472 | L36: 0 | M36: 12.541338 | N36: 0 | O36: 0 | P36: 12.541338 | Q36: 0 | R36: 0 | S36: 8.3650724 | T36: 0 | U36: 41.386415 | V36: 1.17 | W36: 12.87 | X36: 2 | Y36: 2.34 | Z36: 15.21 | AA36: 88.965116 | AB36: 226.91983 | AC36: 215.57384 | AD36: 11.345992 | AE36: 23.406224 | AF36: 34.752216 | AG36: 0 | AH36: 248.76403 | AI36: 29.499578 | AJ36: 4.5383967 | AK36: 1.1345992 | AL36: 35.172574 | AM36: 318.68882 | AN36: 0 | AO36: 25 | AP36: 70 | AQ36: 50.990212 | AR36: 464.67903 | AU36: 13.5 | AV36: 4.5 | AW36: 16 | AX36: 0 | AY36: 0 | AZ36: 27.51256 | BA36: 11.287204 | BB36: 50.165352 | BC36: 0 | BD36: 0 | BE36: 88.965116
A37: CHRS_PPC0077 | B37: MUKANDA KASHABALA FRANCIS | C37: ELECTRICIAN | E37: 544200222145889 | F37: EBCDC | G37: 0 | I37: 11 | J37: 12.541338 | K37: 137.95472 | L37: 0 | M37: 12.541338 | N37: 0 | O37: 0 | P37: 12.541338 | Q37: 0 | R37: 0 | S37: 8.3650724 | T37: 0 | U37: 41.386415 | V37: 1.17 | W37: 12.87 | X37: 2 | Y37: 2.34 | Z37: 15.21 | AA37: 118.82918 | AB37: 256.78389 | AC37: 243.9447 | AD37: 12.839195 | AE37: 28.139531 | AF37: 40.978726 | AG37: 0 | AH37: 272.40158 | AI37: 33.381906 | AJ37: 5.1356779 | AK37: 1.2839195 | AL37: 39.801504 | AM37: 353.18181 | AN37: 0 | AO37: 25 | AP37: 70 | AQ37: 56.50909 | AR37: 504.6909 | AU37: 0 | AV37: 0 | AW37: 16 | AX37: 8 | AY37: 28 | AZ37: 0 | BA37: 0 | BB37: 50.165352 | BC37: 13.795472 | BD37: 54.868354 | BE37: 118.82918
A38: CHRS_PPC0103 | B38: NSUMBU NLANDU FAVARO | C38: ELECTRICIAN | E38: 05126-01175328001-38 | F38: RAWBANK | G38: 3 | I38: 13 | J38: 12.541338 | K38: 163.03739 | L38: 0 | M38: 12.541338 | N38: 0 | O38: 0 | P38: 12.541338 | Q38: 0 | R38: 0 | S38: 8.3650724 | T38: 0 | U38: 48.911218 | V38: 1.17 | W38: 15.21 | X38: 0 | Y38: 0 | Z38: 15.21 | AA38: 84.340498 | AB38: 247.37789 | AC38: 235.009 | AD38: 12.368895 | AE38: 25.191225 | AF38: 37.56012 | AG38: 0 | AH38: 273.93899 | AI38: 32.159126 | AJ38: 4.9475578 | AK38: 1.2368895 | AL38: 38.343573 | AM38: 349.84268 | AN38: 0 | AO38: 25 | AP38: 70 | AQ38: 55.974829 | AR38: 500.81751 | AU38: 0 | AV38: 0 | AW38: 0 | AX38: 8 | AY38: 36 | AZ38: 0 | BA38: 0 | BB38: 0 | BC38: 13.795472 | BD38: 70.545026 | BE38: 84.340498
A39: CHRS_PPC0045 | B39: LUZOLO LUAMFUMU Chadrack | C39: ELECTRICIAN | E39: 05126-00163104701-63 | F39: RAWBANK | G39: 0 | I39: 13 | J39: 12.541338 | K39: 163.03739 | L39: 0 | M39: 12.541338 | N39: 0 | O39: 0 | P39: 12.541338 | Q39: 0 | R39: 0 | S39: 8.3650724 | T39: 0 | U39: 48.911218 | V39: 1.17 | W39: 15.21 | X39: 0 | Y39: 0 | Z39: 15.21 | AA39: 95.862852 | AB39: 258.90025 | AC39: 245.95523 | AD39: 12.945012 | AE39: 28.441111 | AF39: 41.386123 | AG39: 0 | AH39: 281.63534 | AI39: 33.657032 | AJ39: 5.1780049 | AK39: 1.2945012 | AL39: 40.129538 | AM39: 363.151 | AN39: 0 | AO39: 25 | AP39: 70 | AQ39: 58.10416 | AR39: 516.25516 | AU39: 3 | AV39: 0 | AW39: 0 | AX39: 10 | AY39: 37 | AZ39: 6.1139022 | BA39: 0 | BB39: 0 | BC39: 17.24434 | BD39: 72.50461 | BE39: 95.862852
A40: CHRS_PPC0001 | B40: AGAMAKA MONENE DELORD | C40: ELECTRICIAN | E40: 544100263667229 | F40: EBCDC | G40: 0 | I40: 13 | J40: 12.541338 | K40: 163.03739 | L40: 0 | M40: 12.541338 | N40: 0 | O40: 0 | P40: 12.541338 | Q40: 0 | R40: 0 | S40: 8.3650724 | T40: 0 | U40: 48.911218 | V40: 1.17 | W40: 15.21 | X40: 0 | Y40: 0 | Z40: 15.21 | AA40: 84.340498 | AB40: 247.37789 | AC40: 235.009 | AD40: 12.368895 | AE40: 26.799176 | AF40: 39.16807 | AG40: 0 | AH40: 272.33104 | AI40: 32.159126 | AJ40: 4.9475578 | AK40: 1.2368895 | AL40: 38.343573 | AM40: 349.84268 | AN40: 0 | AO40: 25 | AP40: 70 | AQ40: 55.974829 | AR40: 500.81751 | AU40: 0 | AV40: 0 | AW40: 0 | AX40: 8 | AY40: 36 | AZ40: 0 | BA40: 0 | BB40: 0 | BC40: 13.795472 | BD40: 70.545026 | BE40: 84.340498
A41: CHRS_PPC0080 | B41: MUZIAMA KAHOTA MIRIAM | C41: ELECTRICIENNE | E41: 544100218318177 | F41: EBCDC | G41: 0 | I41: 11 | J41: 12.541338 | K41: 137.95472 | L41: 0 | M41: 12.541338 | N41: 0 | O41: 0 | P41: 12.541338 | Q41: 0 | R41: 0 | S41: 8.3650724 | T41: 0 | U41: 41.386415 | V41: 1.17 | W41: 12.87 | X41: 1 | Y41: 1.17 | Z41: 14.04 | AA41: 69.369276 | AB41: 207.32399 | AC41: 196.95779 | AD41: 10.3662 | AE41: 21.091495 | AF41: 31.457695 | AG41: 0 | AH41: 231.29271 | AI41: 26.952119 | AJ41: 4.1464799 | AK41: 1.03662 | AL41: 32.135219 | AM41: 294.88563 | AN41: 0 | AO41: 25 | AP41: 70 | AQ41: 47.1817 | AR41: 437.06733 | AU41: 12 | AV41: 7 | AW41: 7 | AX41: 2 | AY41: 1 | AZ41: 24.455609 | BA41: 17.557873 | BB41: 21.947341 | BC41: 3.4488679 | BD41: 1.9595841 | BE41: 69.369276
A42: CHRS_PPC0082 | B42: MWANAFIOTI AYAY Bénédicte | C42: ENVIRONMENTAL SUPPORT | E42: 05126-01148329001-01 | F42: RAWBANK | G42: 0 | I42: 11 | J42: 24.105846 | K42: 265.1643 | L42: 0 | M42: 24.105846 | N42: 0 | O42: 0 | P42: 24.105846 | Q42: 0 | R42: 0 | S42: 16.078599 | T42: 0 | U42: 79.549291 | V42: 1.17 | W42: 12.87 | X42: 0 | Y42: 0 | Z42: 12.87 | AA42: 29.378999 | AB42: 294.5433 | AC42: 279.81614 | AD42: 14.727165 | AE42: 33.520247 | AF42: 48.247412 | AG42: 0 | AH42: 338.71518 | AI42: 38.290629 | AJ42: 5.890866 | AK42: 1.4727165 | AL42: 45.654212 | AM42: 432.6168 | AN42: 0 | AO42: 25 | AP42: 70 | AQ42: 69.218689 | AR42: 596.83549 | AU42: 7.5 | AV42: 0 | AW42: 0 | AX42: 0 | AY42: 0 | AZ42: 29.378999 | BA42: 0 | BB42: 0 | BC42: 0 | BD42: 0 | BE42: 29.378999
A43: CHRS_PPC0059 | B43: MATONDO NZUZI ROGER | C43: FITTER | E43: 844200063076788 | F43: EBCDC | G43: 4 | I43: 11 | J43: 16.014163 | K43: 176.15579 | L43: 0 | M43: 16.014163 | N43: 0 | O43: 0 | P43: 16.014163 | Q43: 0 | R43: 0 | S43: 10.681447 | T43: 0 | U43: 52.846738 | V43: 1.17 | W43: 12.87 | X43: 0 | Y43: 0 | Z43: 12.87 | AA43: 68.560636 | AB43: 244.71643 | AC43: 232.48061 | AD43: 12.235821 | AE43: 24.306324 | AF43: 36.542145 | AG43: 0 | AH43: 273.89102 | AI43: 31.813136 | AJ43: 4.8943286 | AK43: 1.2235821 | AL43: 37.931047 | AM43: 348.36421 | AN43: 0 | AO43: 25 | AP43: 70 | AQ43: 55.738274 | AR43: 499.10249 | AU43: 3 | AV43: 0 | AW43: 0 | AX43: 6 | AY43: 19 | AZ43: 7.8069045 | BA43: 0 | BB43: 0 | BC43: 13.211685 | BD43: 47.542047 | BE43: 68.560636
...

Sheet Moteur IPR
I4: taux | J4: 2300
B5: taux | C5: valeur inf | D5: valeur sup | E5: cumul | G5: nbre pers | H5: USD | I5: CDF | J5: BI | K5: Taux | L5: Tranche | M5: Cumul IPR | N5: Rabais | O5: IPR NET | P5: IPR USD
B6: 0 | C6: 0 | D6: 162000 | E6: 4860 | G6: ='PPC Usine-Zamba'!G6 -> 5 | H6: ='PPC Usine-Zamba'!AC6 -> 269.1637 | I6: =Tableau1[[#This Row],[USD]]*$J$4 -> 619076.51 | J6: =I6-VLOOKUP($I6,$C$6:$D$9,1) -> 457076.51 | K6: =VLOOKUP($I6,$C$11:$D$14,2) -> 0.15 | L6: =J6*K6 -> 68561.477 | M6: =L6+VLOOKUP($I6,$C$15:$E$19,3) -> 73421.477 | N6: =M6*(G6*2%) -> 7342.1477 | O6: =M6-N6 -> 66079.329 | P6: =O6/$J$4 -> 28.730143
B7: 0.15 | C7: 162000 | D7: 1800000 | E7: 245700 | G7: ='PPC Usine-Zamba'!G7 -> 3 | H7: ='PPC Usine-Zamba'!AC7 -> 252.78187 | I7: =Tableau1[[#This Row],[USD]]*$J$4 -> 581398.3 | J7: =I7-VLOOKUP($I7,$C$6:$D$9,1) -> 419398.3 | K7: =VLOOKUP($I7,$C$11:$D$14,2) -> 0.15 | L7: =J7*K7 -> 62909.745 | M7: =L7+VLOOKUP($I7,$C$15:$E$19,3) -> 67769.745 | N7: =M7*(G7*2%) -> 4066.1847 | O7: =M7-N7 -> 63703.56 | P7: =O7/$J$4 -> 27.6972
B8: 0.3 | C8: 1800000 | D8: 3600000 | E8: 540000 | G8: ='PPC Usine-Zamba'!G8 -> 3 | H8: ='PPC Usine-Zamba'!AC8 -> 235.009 | I8: =Tableau1[[#This Row],[USD]]*$J$4 -> 540520.69 | J8: =I8-VLOOKUP($I8,$C$6:$D$9,1) -> 378520.69 | K8: =VLOOKUP($I8,$C$11:$D$14,2) -> 0.15 | L8: =J8*K8 -> 56778.104 | M8: =L8+VLOOKUP($I8,$C$15:$E$19,3) -> 61638.104 | N8: =M8*(G8*2%) -> 3698.2862 | O8: =M8-N8 -> 57939.818 | P8: =O8/$J$4 -> 25.191225
B9: 0.4 | C9: 3600000 | D9: 0 | E9: 0 | G9: ='PPC Usine-Zamba'!G9 -> 3 | H9: ='PPC Usine-Zamba'!AC9 -> 271.42199 | I9: =Tableau1[[#This Row],[USD]]*$J$4 -> 624270.57 | J9: =I9-VLOOKUP($I9,$C$6:$D$9,1) -> 462270.57 | K9: =VLOOKUP($I9,$C$11:$D$14,2) -> 0.15 | L9: =J9*K9 -> 69340.586 | M9: =L9+VLOOKUP($I9,$C$15:$E$19,3) -> 74200.586 | N9: =M9*(G9*2%) -> 4452.0351 | O9: =M9-N9 -> 69748.55 | P9: =O9/$J$4 -> 30.325457
G10: ='PPC Usine-Zamba'!G11 -> 3 | H10: ='PPC Usine-Zamba'!AC11 -> 263.96068 | I10: =Tableau1[[#This Row],[USD]]*$J$4 -> 607109.55 | J10: =I10-VLOOKUP($I10,$C$6:$D$9,1) -> 445109.55 | K10: =VLOOKUP($I10,$C$11:$D$14,2) -> 0.15 | L10: =J10*K10 -> 66766.433 | M10: =L10+VLOOKUP($I10,$C$15:$E$19,3) -> 71626.433 | N10: =M10*(G10*2%) -> 4297.586 | O10: =M10-N10 -> 67328.847 | P10: =O10/$J$4 -> 29.273412
C11: 0 | D11: 0 | G11: ='PPC Usine-Zamba'!G12 -> 5 | H11: ='PPC Usine-Zamba'!AC12 -> 117.11134 | I11: =Tableau1[[#This Row],[USD]]*$J$4 -> 269356.08 | J11: =I11-VLOOKUP($I11,$C$6:$D$9,1) -> 107356.08 | K11: =VLOOKUP($I11,$C$11:$D$14,2) -> 0.15 | L11: =J11*K11 -> 16103.413 | M11: =L11+VLOOKUP($I11,$C$15:$E$19,3) -> 20963.413 | N11: =M11*(G11*2%) -> 2096.3413 | O11: =M11-N11 -> 18867.071 | P11: =O11/$J$4 -> 8.2030745
C12: 162001 | D12: 0.15 | G12: ='PPC Usine-Zamba'!G13 -> 4 | H12: ='PPC Usine-Zamba'!AC13 -> 161.95962 | I12: =Tableau1[[#This Row],[USD]]*$J$4 -> 372507.13 | J12: =I12-VLOOKUP($I12,$C$6:$D$9,1) -> 210507.13 | K12: =VLOOKUP($I12,$C$11:$D$14,2) -> 0.15 | L12: =J12*K12 -> 31576.07 | M12: =L12+VLOOKUP($I12,$C$15:$E$19,3) -> 36436.07 | N12: =M12*(G12*2%) -> 2914.8856 | O12: =M12-N12 -> 33521.184 | P12: =O12/$J$4 -> 14.574428
C13: 1800001 | D13: 0.3 | G13: ='PPC Usine-Zamba'!G14 -> 1 | H13: ='PPC Usine-Zamba'!AC14 -> 145.67366 | I13: =Tableau1[[#This Row],[USD]]*$J$4 -> 335049.43 | J13: =I13-VLOOKUP($I13,$C$6:$D$9,1) -> 173049.43 | K13: =VLOOKUP($I13,$C$11:$D$14,2) -> 0.15 | L13: =J13*K13 -> 25957.414 | M13: =L13+VLOOKUP($I13,$C$15:$E$19,3) -> 30817.414 | N13: =M13*(G13*2%) -> 616.34829 | O13: =M13-N13 -> 30201.066 | P13: =O13/$J$4 -> 13.130898
C14: 3600001 | D14: 0.4 | G14: ='PPC Usine-Zamba'!G15 -> 1 | H14: ='PPC Usine-Zamba'!AC15 -> 162.66735 | I14: =Tableau1[[#This Row],[USD]]*$J$4 -> 374134.91 | J14: =I14-VLOOKUP($I14,$C$6:$D$9,1) -> 212134.91 | K14: =VLOOKUP($I14,$C$11:$D$14,2) -> 0.15 | L14: =J14*K14 -> 31820.236 | M14: =L14+VLOOKUP($I14,$C$15:$E$19,3) -> 36680.236 | N14: =M14*(G14*2%) -> 733.60473 | O14: =M14-N14 -> 35946.632 | P14: =O14/$J$4 -> 15.62897
G15: ='PPC Usine-Zamba'!G16 -> 0 | H15: ='PPC Usine-Zamba'!AC16 -> 208.64472 | I15: =Tableau1[[#This Row],[USD]]*$J$4 -> 479882.85 | J15: =I15-VLOOKUP($I15,$C$6:$D$9,1) -> 317882.85 | K15: =VLOOKUP($I15,$C$11:$D$14,2) -> 0.15 | L15: =J15*K15 -> 47682.427 | M15: =L15+VLOOKUP($I15,$C$15:$E$19,3) -> 52542.427 | N15: =M15*(G15*2%) -> 0 | O15: =M15-N15 -> 52542.427 | P15: =O15/$J$4 -> 22.844534
C16: 0 | D16: 4860 | E16: 2300 | G16: ='PPC Usine-Zamba'!G17 -> 4 | H16: ='PPC Usine-Zamba'!AC17 -> 247.05998 | I16: =Tableau1[[#This Row],[USD]]*$J$4 -> 568237.97 | J16: =I16-VLOOKUP($I16,$C$6:$D$9,1) -> 406237.97 | K16: =VLOOKUP($I16,$C$11:$D$14,2) -> 0.15 | L16: =J16*K16 -> 60935.695 | M16: =L16+VLOOKUP($I16,$C$15:$E$19,3) -> 65795.695 | N16: =M16*(G16*2%) -> 5263.6556 | O16: =M16-N16 -> 60532.039 | P16: =O16/$J$4 -> 26.318278
C17: 162001 | D17: 245700 | E17: 4860 | G17: ='PPC Usine-Zamba'!G18 -> 0 | H17: ='PPC Usine-Zamba'!AC18 -> 240.14703 | I17: =Tableau1[[#This Row],[USD]]*$J$4 -> 552338.16 | J17: =I17-VLOOKUP($I17,$C$6:$D$9,1) -> 390338.16 | K17: =VLOOKUP($I17,$C$11:$D$14,2) -> 0.15 | L17: =J17*K17 -> 58550.724 | M17: =L17+VLOOKUP($I17,$C$15:$E$19,3) -> 63410.724 | N17: =M17*(G17*2%) -> 0 | O17: =M17-N17 -> 63410.724 | P17: =O17/$J$4 -> 27.56988
C18: 1800001 | D18: 540000 | E18: 250560 | G18: ='PPC Usine-Zamba'!G19 -> 0 | H18: ='PPC Usine-Zamba'!AC19 -> 85.333271 | I18: =Tableau1[[#This Row],[USD]]*$J$4 -> 196266.52 | J18: =I18-VLOOKUP($I18,$C$6:$D$9,1) -> 34266.524 | K18: =VLOOKUP($I18,$C$11:$D$14,2) -> 0.15 | L18: =J18*K18 -> 5139.9786 | M18: =L18+VLOOKUP($I18,$C$15:$E$19,3) -> 9999.9786 | N18: =M18*(G18*2%) -> 0 | O18: =M18-N18 -> 9999.9786 | P18: =O18/$J$4 -> 4.3478168
C19: 3600001 | D19: 0 | E19: 790560 | G19: ='PPC Usine-Zamba'!G20 -> 0 | H19: ='PPC Usine-Zamba'!AC20 -> 313.27066 | I19: =Tableau1[[#This Row],[USD]]*$J$4 -> 720522.52 | J19: =I19-VLOOKUP($I19,$C$6:$D$9,1) -> 558522.52 | K19: =VLOOKUP($I19,$C$11:$D$14,2) -> 0.15 | L19: =J19*K19 -> 83778.378 | M19: =L19+VLOOKUP($I19,$C$15:$E$19,3) -> 88638.378 | N19: =M19*(G19*2%) -> 0 | O19: =M19-N19 -> 88638.378 | P19: =O19/$J$4 -> 38.538425
G20: ='PPC Usine-Zamba'!G21 -> 0 | H20: ='PPC Usine-Zamba'!AC21 -> 378.16784 | I20: =Tableau1[[#This Row],[USD]]*$J$4 -> 869786.03 | J20: =I20-VLOOKUP($I20,$C$6:$D$9,1) -> 707786.03 | K20: =VLOOKUP($I20,$C$11:$D$14,2) -> 0.15 | L20: =J20*K20 -> 106167.91 | M20: =L20+VLOOKUP($I20,$C$15:$E$19,3) -> 111027.91 | N20: =M20*(G20*2%) -> 0 | O20: =M20-N20 -> 111027.91 | P20: =O20/$J$4 -> 48.273002
G21: ='PPC Usine-Zamba'!G22 -> 2 | H21: ='PPC Usine-Zamba'!AC22 -> 470.12557 | I21: =Tableau1[[#This Row],[USD]]*$J$4 -> 1081288.8 | J21: =I21-VLOOKUP($I21,$C$6:$D$9,1) -> 919288.8 | K21: =VLOOKUP($I21,$C$11:$D$14,2) -> 0.15 | L21: =J21*K21 -> 137893.32 | M21: =L21+VLOOKUP($I21,$C$15:$E$19,3) -> 142753.32 | N21: =M21*(G21*2%) -> 5710.1328 | O21: =M21-N21 -> 137043.19 | P21: =O21/$J$4 -> 59.583994
G22: ='PPC Usine-Zamba'!G23 -> 5 | H22: ='PPC Usine-Zamba'!AC23 -> 321.75978 | I22: =Tableau1[[#This Row],[USD]]*$J$4 -> 740047.5 | J22: =I22-VLOOKUP($I22,$C$6:$D$9,1) -> 578047.5 | K22: =VLOOKUP($I22,$C$11:$D$14,2) -> 0.15 | L22: =J22*K22 -> 86707.125 | M22: =L22+VLOOKUP($I22,$C$15:$E$19,3) -> 91567.125 | N22: =M22*(G22*2%) -> 9156.7125 | O22: =M22-N22 -> 82410.412 | P22: =O22/$J$4 -> 35.830614
G23: ='PPC Usine-Zamba'!G25 -> 0 | H23: ='PPC Usine-Zamba'!AC25 -> 402.85129 | I23: =Tableau1[[#This Row],[USD]]*$J$4 -> 926557.97 | J23: =I23-VLOOKUP($I23,$C$6:$D$9,1) -> 764557.97 | K23: =VLOOKUP($I23,$C$11:$D$14,2) -> 0.15 | L23: =J23*K23 -> 114683.69 | M23: =L23+VLOOKUP($I23,$C$15:$E$19,3) -> 119543.69 | N23: =M23*(G23*2%) -> 0 | O23: =M23-N23 -> 119543.69 | P23: =O23/$J$4 -> 51.97552
G24: ='PPC Usine-Zamba'!G26 -> 5 | H24: ='PPC Usine-Zamba'!AC26 -> 0 | I24: =Tableau1[[#This Row],[USD]]*$J$4 -> 0 | J24: =I24-VLOOKUP($I24,$C$6:$D$9,1) -> 0 | K24: =VLOOKUP($I24,$C$11:$D$14,2) -> 0 | L24: =J24*K24 -> 0 | M24: =L24+VLOOKUP($I24,$C$15:$E$19,3) -> 2300 | N24: =M24*(G24*2%) -> 230 | O24: =M24-N24 -> 2070 | P24: =O24/$J$4 -> 0.9
G25: ='PPC Usine-Zamba'!#REF! -> #REF! | H25: ='PPC Usine-Zamba'!#REF! -> #REF! | I25: =Tableau1[[#This Row],[USD]]*$J$4 -> #REF! | J25: =I25-VLOOKUP($I25,$C$6:$D$9,1) -> #REF! | K25: =VLOOKUP($I25,$C$11:$D$14,2) -> #REF! | L25: =J25*K25 -> #REF! | M25: =L25+VLOOKUP($I25,$C$15:$E$19,3) -> #REF! | N25: =M25*(G25*2%) -> #REF! | O25: =M25-N25 -> #REF! | P25: =O25/$J$4 -> #REF!
G26: ='PPC Usine-Zamba'!#REF! -> #REF! | H26: ='PPC Usine-Zamba'!#REF! -> #REF! | I26: =Tableau1[[#This Row],[USD]]*$J$4 -> #REF! | J26: =I26-VLOOKUP($I26,$C$6:$D$9,1) -> #REF! | K26: =VLOOKUP($I26,$C$11:$D$14,2) -> #REF! | L26: =J26*K26 -> #REF! | M26: =L26+VLOOKUP($I26,$C$15:$E$19,3) -> #REF! | N26: =M26*(G26*2%) -> #REF! | O26: =M26-N26 -> #REF! | P26: =O26/$J$4 -> #REF!
G27: ='PPC Usine-Zamba'!G27 -> 0 | H27: ='PPC Usine-Zamba'!AC27 -> 393.91559 | I27: =Tableau1[[#This Row],[USD]]*$J$4 -> 906005.85 | J27: =I27-VLOOKUP($I27,$C$6:$D$9,1) -> 744005.85 | K27: =VLOOKUP($I27,$C$11:$D$14,2) -> 0.15 | L27: =J27*K27 -> 111600.88 | M27: =L27+VLOOKUP($I27,$C$15:$E$19,3) -> 116460.88 | N27: =M27*(G27*2%) -> 0 | O27: =M27-N27 -> 116460.88 | P27: =O27/$J$4 -> 50.635164
G28: ='PPC Usine-Zamba'!G28 -> 0 | H28: ='PPC Usine-Zamba'!AC28 -> 301.65445 | I28: =Tableau1[[#This Row],[USD]]*$J$4 -> 693805.24 | J28: =I28-VLOOKUP($I28,$C$6:$D$9,1) -> 531805.24 | K28: =VLOOKUP($I28,$C$11:$D$14,2) -> 0.15 | L28: =J28*K28 -> 79770.785 | M28: =L28+VLOOKUP($I28,$C$15:$E$19,3) -> 84630.785 | N28: =M28*(G28*2%) -> 0 | O28: =M28-N28 -> 84630.785 | P28: =O28/$J$4 -> 36.795994
G29: ='PPC Usine-Zamba'!G29 -> 0 | H29: ='PPC Usine-Zamba'!AC29 -> 357.57706 | I29: =Tableau1[[#This Row],[USD]]*$J$4 -> 822427.24 | J29: =I29-VLOOKUP($I29,$C$6:$D$9,1) -> 660427.24 | K29: =VLOOKUP($I29,$C$11:$D$14,2) -> 0.15 | L29: =J29*K29 -> 99064.086 | M29: =L29+VLOOKUP($I29,$C$15:$E$19,3) -> 103924.09 | N29: =M29*(G29*2%) -> 0 | O29: =M29-N29 -> 103924.09 | P29: =O29/$J$4 -> 45.184385
G30: ='PPC Usine-Zamba'!G30 -> 0 | H30: ='PPC Usine-Zamba'!AC30 -> 470.89916 | I30: =Tableau1[[#This Row],[USD]]*$J$4 -> 1083068.1 | J30: =I30-VLOOKUP($I30,$C$6:$D$9,1) -> 921068.08 | K30: =VLOOKUP($I30,$C$11:$D$14,2) -> 0.15 | L30: =J30*K30 -> 138160.21 | M30: =L30+VLOOKUP($I30,$C$15:$E$19,3) -> 143020.21 | N30: =M30*(G30*2%) -> 0 | O30: =M30-N30 -> 143020.21 | P30: =O30/$J$4 -> 62.182701
G31: ='PPC Usine-Zamba'!G31 -> 4 | H31: ='PPC Usine-Zamba'!AC31 -> 235.009 | I31: =Tableau1[[#This Row],[USD]]*$J$4 -> 540520.69 | J31: =I31-VLOOKUP($I31,$C$6:$D$9,1) -> 378520.69 | K31: =VLOOKUP($I31,$C$11:$D$14,2) -> 0.15 | L31: =J31*K31 -> 56778.104 | M31: =L31+VLOOKUP($I31,$C$15:$E$19,3) -> 61638.104 | N31: =M31*(G31*2%) -> 4931.0483 | O31: =M31-N31 -> 56707.055 | P31: =O31/$J$4 -> 24.655242
G32: ='PPC Usine-Zamba'!G32 -> 0 | H32: ='PPC Usine-Zamba'!AC32 -> 258.83754 | I32: =Tableau1[[#This Row],[USD]]*$J$4 -> 595326.34 | J32: =I32-VLOOKUP($I32,$C$6:$D$9,1) -> 433326.34 | K32: =VLOOKUP($I32,$C$11:$D$14,2) -> 0.15 | L32: =J32*K32 -> 64998.951 | M32: =L32+VLOOKUP($I32,$C$15:$E$19,3) -> 69858.951 | N32: =M32*(G32*2%) -> 0 | O32: =M32-N32 -> 69858.951 | P32: =O32/$J$4 -> 30.373457
G33: ='PPC Usine-Zamba'!G33 -> 1 | H33: ='PPC Usine-Zamba'!AC33 -> 249.90184 | I33: =Tableau1[[#This Row],[USD]]*$J$4 -> 574774.22 | J33: =I33-VLOOKUP($I33,$C$6:$D$9,1) -> 412774.22 | K33: =VLOOKUP($I33,$C$11:$D$14,2) -> 0.15 | L33: =J33*K33 -> 61916.133 | M33: =L33+VLOOKUP($I33,$C$15:$E$19,3) -> 66776.133 | N33: =M33*(G33*2%) -> 1335.5227 | O33: =M33-N33 -> 65440.61 | P33: =O33/$J$4 -> 28.452439
G34: ='PPC Usine-Zamba'!G34 -> 1 | H34: ='PPC Usine-Zamba'!AC34 -> 223.09473 | I34: =Tableau1[[#This Row],[USD]]*$J$4 -> 513117.87 | J34: =I34-VLOOKUP($I34,$C$6:$D$9,1) -> 351117.87 | K34: =VLOOKUP($I34,$C$11:$D$14,2) -> 0.15 | L34: =J34*K34 -> 52667.68 | M34: =L34+VLOOKUP($I34,$C$15:$E$19,3) -> 57527.68 | N34: =M34*(G34*2%) -> 1150.5536 | O34: =M34-N34 -> 56377.127 | P34: =O34/$J$4 -> 24.511794
G35: ='PPC Usine-Zamba'!G35 -> 1 | H35: ='PPC Usine-Zamba'!AC35 -> 235.009 | I35: =Tableau1[[#This Row],[USD]]*$J$4 -> 540520.69 | J35: =I35-VLOOKUP($I35,$C$6:$D$9,1) -> 378520.69 | K35: =VLOOKUP($I35,$C$11:$D$14,2) -> 0.15 | L35: =J35*K35 -> 56778.104 | M35: =L35+VLOOKUP($I35,$C$15:$E$19,3) -> 61638.104 | N35: =M35*(G35*2%) -> 1232.7621 | O35: =M35-N35 -> 60405.342 | P35: =O35/$J$4 -> 26.263192
G36: ='PPC Usine-Zamba'!G36 -> 1 | H36: ='PPC Usine-Zamba'!AC36 -> 215.57384 | I36: =Tableau1[[#This Row],[USD]]*$J$4 -> 495819.84 | J36: =I36-VLOOKUP($I36,$C$6:$D$9,1) -> 333819.84 | K36: =VLOOKUP($I36,$C$11:$D$14,2) -> 0.15 | L36: =J36*K36 -> 50072.975 | M36: =L36+VLOOKUP($I36,$C$15:$E$19,3) -> 54932.975 | N36: =M36*(G36*2%) -> 1098.6595 | O36: =M36-N36 -> 53834.316 | P36: =O36/$J$4 -> 23.406224
G37: ='PPC Usine-Zamba'!G37 -> 0 | H37: ='PPC Usine-Zamba'!AC37 -> 243.9447 | I37: =Tableau1[[#This Row],[USD]]*$J$4 -> 561072.81 | J37: =I37-VLOOKUP($I37,$C$6:$D$9,1) -> 399072.81 | K37: =VLOOKUP($I37,$C$11:$D$14,2) -> 0.15 | L37: =J37*K37 -> 59860.921 | M37: =L37+VLOOKUP($I37,$C$15:$E$19,3) -> 64720.921 | N37: =M37*(G37*2%) -> 0 | O37: =M37-N37 -> 64720.921 | P37: =O37/$J$4 -> 28.139531
G38: ='PPC Usine-Zamba'!G38 -> 3 | H38: ='PPC Usine-Zamba'!AC38 -> 235.009 | I38: =Tableau1[[#This Row],[USD]]*$J$4 -> 540520.69 | J38: =I38-VLOOKUP($I38,$C$6:$D$9,1) -> 378520.69 | K38: =VLOOKUP($I38,$C$11:$D$14,2) -> 0.15 | L38: =J38*K38 -> 56778.104 | M38: =L38+VLOOKUP($I38,$C$15:$E$19,3) -> 61638.104 | N38: =M38*(G38*2%) -> 3698.2862 | O38: =M38-N38 -> 57939.818 | P38: =O38/$J$4 -> 25.191225
... G59: ='PPC Usine-Zamba'!G59 -> 4 | H59: ='PPC Usine-Zamba'!AC59 -> 244.25113 | I59: =Tableau1[[#This Row],[USD]]*$J$4 -> 561777.6 | J59: =I59-VLOOKUP($I59,$C$6:$D$9,1) -> 399777.6 | K59: =VLOOKUP($I59,$C$11:$D$14,2) -> 0.15 | L59: =J59*K59 -> 59966.639 | M59: =L59+VLOOKUP($I59,$C$15:$E$19,3) -> 64826.639 | N59: =M59*(G59*2%) -> 5186.1311 | O59: =M59-N59 -> 59640.508 | P59: =O59/$J$4 -> 25.930656
G60: ='PPC Usine-Zamba'!#REF! -> #REF! | H60: ='PPC Usine-Zamba'!#REF! -> #REF! | I60: =Tableau1[[#This Row],[USD]]*$J$4 -> #REF! | J60: =I60-VLOOKUP($I60,$C$6:$D$9,1) -> #REF! | K60: =VLOOKUP($I60,$C$11:$D$14,2) -> #REF! | L60: =J60*K60 -> #REF! | M60: =L60+VLOOKUP($I60,$C$15:$E$19,3) -> #REF! | N60: =M60*(G60*2%) -> #REF! | O60: =M60-N60 -> #REF! | P60: =O60/$J$4 -> #REF!
G61: ='PPC Usine-Zamba'!G60 -> 4 | H61: ='PPC Usine-Zamba'!AC60 -> 107.68859 | I61: =Tableau1[[#This Row],[USD]]*$J$4 -> 247683.76 | J61: =I61-VLOOKUP($I61,$C$6:$D$9,1) -> 85683.756 | K61: =VLOOKUP($I61,$C$11:$D$14,2) -> 0.15 | L61: =J61*K61 -> 12852.563 | M61: =L61+VLOOKUP($I61,$C$15:$E$19,3) -> 17712.563 | N61: =M61*(G61*2%) -> 1417.0051 | O61: =M61-N61 -> 16295.558 | P61: =O61/$J$4 -> 7.0850254
G62: ='PPC Usine-Zamba'!G61 -> 4 | H62: ='PPC Usine-Zamba'!AC61 -> 174.10553 | I62: =Tableau1[[#This Row],[USD]]*$J$4 -> 400442.71 | J62: =I62-VLOOKUP($I62,$C$6:$D$9,1) -> 238442.71 | K62: =VLOOKUP($I62,$C$11:$D$14,2) -> 0.15 | L62: =J62*K62 -> 35766.407 | M62: =L62+VLOOKUP($I62,$C$15:$E$19,3) -> 40626.407 | N62: =M62*(G62*2%) -> 3250.1125 | O62: =M62-N62 -> 37376.294 | P62: =O62/$J$4 -> 16.250563
G63: ='PPC Usine-Zamba'!G62 -> 3 | H63: ='PPC Usine-Zamba'!AC62 -> 241.58415 | I63: =Tableau1[[#This Row],[USD]]*$J$4 -> 555643.54 | J63: =I63-VLOOKUP($I63,$C$6:$D$9,1) -> 393643.54 | K63: =VLOOKUP($I63,$C$11:$D$14,2) -> 0.15 | L63: =J63*K63 -> 59046.531 | M63: =L63+VLOOKUP($I63,$C$15:$E$19,3) -> 63906.531 | N63: =M63*(G63*2%) -> 3834.3919 | O63: =M63-N63 -> 60072.139 | P63: =O63/$J$4 -> 26.118321
...
