Workbook

Sheet Sheet1
A4: PAIE PPC AOUT 2026
BA5: 1.3 | BB5: 1.6 | BC5: 2 | BD5: 0.1 | BE5: 0.25
G6: CLASSE | I6: BASE | K6: JOURS PRESTES | N6: JOURS FERIES | Q6: JOURS CONGES | T6: JOURS MALADIES | W6: INDEMNITES | AA6: MONT HEURES SUPP | AB6: Brut Impos | AC6: Sal Impos | AD6: DEDUCTIONS EMPLOYEE | AH6: Net à Payer | AI6: DEDUCTION PATRONALE | AN6: Gross Salary | AO6: M.B | AP6: Provision PPE | AQ6: Prov. S. Méd. | AR6: TVA | AS6: Total Gén
A7: MATR | B7: NOMS | C7: FONCTIONS | D7: NUMERO CNSS | E7: NUMERO DE COMPTE | F7: BANQUE | K7: Jrs | L7: Tx/Jr | M7: Base | N7: Jrs | O7: Tx/Jr | P7: Base | Q7: Jrs | R7: Tx/Jr | S7: Base | T7: Jrs | U7: Tx/Jr | V7: Base | W7: Logm | X7: Trs / Jrs | Y7: Trs Dimanche& Feries | Z7: Tot Trs | AD7: Cnss/O | AE7: Ipr | AF7: Total | AG7: AVANCES | AI7: Cnss/P | AJ7: Inpp | AK7: Onem | AL7: Total | AU7: Sundays | AV7: Overtime 130% (Hrs) | AW7: Overtime 160% (Hrs) | AX7: Overtime 200% (Hrs) | AY7: Overtime 10% (Hrs) | AZ7: Overtime 25% (Hrs) | BA7: Overtime 130% US$ | BB7: Overtime 160% US$ | BC7: Overtime 200% US$ | BD7: Overtime 10% US$ | BE7: Overtime 25% US$ | BF7: Total overtime
G8: Classification | I8: sal base bareme | K8: Pointage | L8: base/pointage | M8: base mensuel | O8: base/pointage | P8: Jrsxtx | R8: base/pointage | S8: Jrsxtx | U8: 0.667*tx | V8: Jrsxtx | W8: 30%base pres, fer, cong,mal | X8: Nbr jr x course | Y8: Awxtras | Z8: x+y | AA8: BH | AB8: Bases+HS | AC8: AB-AD | AD8: BIx5% | AE8: Tranches | AF8: AD+AE | AH8: BI,Log, inden-avance-deduct | AI8: 13%BI | AJ8: 2%BI | AK8: 0.5%BI | AL8: AI+AJ+AK | AN8: AD+AE+AG+AH+AL | AO8: %AN | AP8: forfait | AQ8: Forfait | AR8: 16%AN | AS8: AN+AO+AP+AQ+AR | BA8: (Txj/8)*av*ba

Sheet Sheet1 (2)
A4: PAIE PPC AOUT 2026
BA5: 1.3 | BB5: 1.6 | BC5: 2 | BD5: 0.1 | BE5: 0.25
G6: CLASSE | I6: BASE | K6: JOURS PRESTES | N6: JOURS FERIES | Q6: JOURS CONGES | T6: JOURS MALADIES | W6: INDEMNITES | AA6: MONT HEURES SUPP | AB6: Brut Impos | AC6: Sal Impos | AD6: DEDUCTIONS EMPLOYEE | AH6: Net à Payer | AI6: DEDUCTION PATRONALE | AN6: Gross Salary | AO6: M.B | AP6: Provision PPE | AQ6: Prov. S. Méd. | AR6: TVA | AS6: Total Gén
A7: MATR | B7: NOMS | C7: FONCTIONS | D7: NUMERO CNSS | E7: NUMERO DE COMPTE | F7: BANQUE | K7: Jrs | L7: Tx/Jr | M7: Base | N7: Jrs | O7: Tx/Jr | P7: Base | Q7: Jrs | R7: Tx/Jr | S7: Base | T7: Jrs | U7: Tx/Jr | V7: Base | W7: Logm | X7: Trs / Jrs | Y7: Trs Dimanche& Feries | Z7: Tot Trs | AD7: Cnss/O | AE7: Ipr | AF7: Total | AG7: AVANCES | AI7: Cnss/P | AJ7: Inpp | AK7: Onem | AL7: Total | AU7: Sundays | AV7: Overtime 130% (Hrs) | AW7: Overtime 160% (Hrs) | AX7: Overtime 200% (Hrs) | AY7: Overtime 10% (Hrs) | AZ7: Overtime 25% (Hrs) | BA7: Overtime 130% US$ | BB7: Overtime 160% US$ | BC7: Overtime 200% US$ | BD7: Overtime 10% US$ | BE7: Overtime 25% US$ | BF7: Total overtime
G8: Classification | I8: sal base bareme | K8: 13 | L8: 10 | M8: =L8*K8 -> 130 | N8: 1 | O8: 10 | P8: =N8*O8 -> 10 | Q8: 2 | R8: 10 | S8: =Q8*R8 -> 20 | T8: 3 | U8: =0.667*L8 -> 6.67 | V8: =T8*U8 -> 20.01 | W8: =0.3*(M8+P8+S8+V8) -> 54.003 | X8: =K8*5400 -> 70200 | Y8: 20000 | Z8: =X8+Y8 -> 90200 | AA8: 50000 | AB8: =M8+P8+S8+V8+AA8 -> 50180.01 | AC8: AB-AD | AD8: =AB8*5% -> 2509.0005 | AE8: Tranches | AF8: AD+AE | AH8: BI,Log, inden-avance-deduct | AI8: 13%BI | AJ8: 2%BI | AK8: 0.5%BI | AL8: AI+AJ+AK | AN8: AD+AE+AG+AH+AL | AO8: %AN | AP8: forfait | AQ8: Forfait | AR8: 16%AN | AS8: AN+AO+AP+AQ+AR | BA8: (Txj/8)*av*ba

Sheet Hors-Site
I3: JOURS PRESTES | L3: JOURS FERIES | O3: JOURS CONGES | R3: JOURS MALADIES | U3: INDEMNITES | AD3: DEDUCTIONS EMPLOYEE | AI3: DEDUCTION PATRONALE | AZ3: 1.3 | BA3: 1.6 | BB3: 2 | BC3: 0.1 | BD3: 0.25
A5: MATR | B5: NOMS | C5: FONCTIONS | D5: NUMERO CNSS | E5: NUMERO DE COMPTE | F5: BANQUE | G5: Dépendant | H5: BASE | I5: Jrs | J5: Tx/Jr | K5: Base2 | L5: Jrs3 | M5: Tx/Jr4 | N5: Base5 | O5: Jrs6 | P5: Tx/Jr7 | Q5: Base8 | R5: Jrs9 | S5: Tx/Jr10 | T5: Base11 | U5: Logm | V5: cout/Trs | W5: Trs / Jrs | X5: Jrs/feries&Dimanche | Y5: Trs Dimanche& Feries | Z5: Tot Trs | AA5: MONT HEURES SUPP | AB5: Brut Impos | AC5: Sal Impos | AD5: Cnss/O | AE5: Ipr | AF5: Total | AG5: AVANCES | AH5: Net à Payer | AI5: Cnss/P | AJ5: Inpp | AK5: Onem | AL5: Total12 | AM5: Gross Salary | AN5: M.B | AO5: Provision PPE | AP5: Prov. S. Méd. | AQ5: TVA | AR5: Total Gén | AT5: Sundays | AU5: Overtime 130% (Hrs) | AV5: Overtime 160% (Hrs) | AW5: Overtime 200% (Hrs) | AX5: Overtime 10% (Hrs) | AY5: Overtime 25% (Hrs) | AZ5: Overtime 130% US$ | BA5: Overtime 160% US$ | BB5: Overtime 200% US$ | BC5: Overtime 10% US$ | BD5: Overtime 25% US$ | BE5: Total overtime
B6: SENGA BANZA FOSTINE | C6: AIDE MENAGERE | E6: 0986891544 | F6: Airtel Money | G6: 0 | I6: 16 | J6: 8.7337325 | K6: =(J6*I6) -> 139.73972 | L6: 0 | M6: =Tableau2[[#This Row],[Tx/Jr]] -> 8.7337325 | N6: =L6*M6 -> 0 | O6: 0 | P6: =Tableau2[[#This Row],[Tx/Jr]] -> 8.7337325 | Q6: =O6*P6 -> 0 | R6: 0 | S6: =0.667*J6 -> 5.8253995 | T6: =R6*S6 -> 0 | U6: =0.3*(K6+N6+Q6+T6) -> 41.921916 | V6: 0.81 | W6: =I6*V6 -> 12.96 | X6: 1 | Y6: =X6*V6 -> 0.81 | Z6: =W6+Y6 -> 13.77 | AA6: =BE6 -> 30.175046 | AB6: =K6+N6+Q6+T6+AA6 -> 169.91476 | AC6: =Tableau2[[#This Row],[Brut Impos]]-Tableau2[[#This Row],[Cnss/O]] -> 161.41903 | AD6: =AB6*5% -> 8.4957382 | AE6: =+'Moteur IPR'!P6 -> 15.76068 | AF6: =+AD6+AE6 -> 24.256418 | AG6: 0 | AH6: =+AB6+U6+Z6-AG6-AF6 -> 201.35026 | AI6: =+AB6*0.13 -> 22.088919 | AJ6: =2%*AB6 -> 3.3982953 | AK6: =0.5%*AB6 -> 0.84957382 | AL6: =+AI6+AJ6+AK6 -> 26.336789 | AM6: =+AD6+AE6+AG6+AH6+AL6 -> 251.94347 | AN6: 0 | AO6: 25 | AP6: 45 | AQ6: =0.16*AM6 -> 40.310955 | AR6: =AM6+AN6+AO6+AP6+AQ6 -> 362.25442 | AU6: 6 | AV6: 10.9 | AW6: 1.2 | AX6: 0 | AY6: 0 | AZ6: =($J6/8)*$AU6*(1+0.3) -> 8.5153891 | BA6: =($J6/8)*$AV6*(1+0.6) -> 19.039537 | BB6: =($J6/8)*2*$AW6 -> 2.6201197 | BC6: =($J6/8)*$AX6*(1+0.1) -> 0 | BD6: =($J6/8)*$AY6*(1+0.25) -> 0 | BE6: =AZ6+BA6+BB6+BC6+BD6 -> 30.175046
B7: MUNYEMU WA TUMBWEMBWE GRACE | C7: CHARGEE DES COMPTES CLIENTS. | D7: KINSHASA | E7: 300100001564030 | F7: E-BCDC | G7: 0 | I7: 26 | J7: 29.91102 | K7: 777.68652 | L7: 0 | M7: 29.91102 | N7: 0 | O7: 0 | P7: 29.91102 | Q7: 0 | R7: 0 | S7: 19.95065 | T7: 0 | U7: 233.30596 | V7: 5.01 | W7: 130.26 | Y7: 0 | Z7: 130.26 | AA7: 0 | AB7: 777.68652 | AC7: 738.8022 | AD7: 38.884326 | AE7: 102.36816 | AF7: 141.25248 | AG7: 0 | AH7: 1000 | AI7: 101.09925 | AJ7: 15.55373 | AK7: 3.8884326 | AL7: 120.54141 | AM7: 1261.7939 | AN7: 0 | AO7: 25 | AP7: 45 | AQ7: 201.88702 | AR7: =AM7+AN7+AO7+AP7+AQ7 -> 1533.6809 | AU7: 0 | AV7: 0 | AW7: 0 | AX7: 0 | AY7: 0 | AZ7: 0 | BA7: 0 | BB7: 0 | BC7: 0 | BD7: 0 | BE7: 0
B8: NDAY MUDIBU FREDDY | C8: CHAUFFEUR | D8: LUBUDI | E8: 0976977095 | F8: Airtel Money | G8: 0 | I8: 3 | J8: 11.646044 | K8: 34.938131 | L8: 0 | M8: 11.646044 | N8: 0 | O8: 0 | P8: 11.646044 | Q8: 0 | R8: 0 | S8: 7.7679111 | T8: 0 | U8: 10.481439 | V8: 1.2 | W8: 3.6 | Y8: 0 | Z8: 3.6 | AA8: 7.2933348 | AB8: 42.231466 | AC8: 40.119892 | AD8: 2.1115733 | AE8: 1 | AF8: 3.1115733 | AG8: 0 | AH8: 53.201332 | AI8: 5.4900905 | AJ8: 0.84462931 | AK8: 0.21115733 | AL8: 6.5458772 | AM8: 62.858782 | AN8: 0 | AO8: 25 | AP8: 45 | AQ8: 10.057405 | AR8: =AM8+AN8+AO8+AP8+AQ8 -> 142.91619 | AU8: 2.5 | AV8: 0 | AW8: 0 | AX8: 1.6 | AY8: 0 | AZ8: 4.7312052 | BA8: 0 | BB8: 0 | BC8: 2.5621296 | BD8: 0 | BE8: 7.2933348
B9: BALOY KIMPINDE MARGUERITTE | C9: CUISINIERE | D9: LUBUDI | E9: 0977660115 | F9: Airtel Money | G9: 0 | I9: 16 | J9: 8.7337325 | K9: 139.73972 | L9: 0 | M9: 8.7337325 | N9: 0 | O9: 0 | P9: 8.7337325 | Q9: 0 | R9: 0 | S9: 5.8253995 | T9: 0 | U9: 41.921916 | V9: 0.81 | W9: 12.96 | X9: 1 | Y9: 0.81 | Z9: 13.77 | AA9: 30.175046 | AB9: 169.91476 | AC9: 161.41903 | AD9: 8.4957382 | AE9: 15.76068 | AF9: 24.256418 | AG9: 0 | AH9: 201.35026 | AI9: 22.088919 | AJ9: 3.3982953 | AK9: 0.84957382 | AL9: 26.336789 | AM9: 251.94347 | AN9: 0 | AO9: 25 | AP9: 45 | AQ9: 40.310955 | AR9: =AM9+AN9+AO9+AP9+AQ9 -> 362.25442 | AU9: 6 | AV9: 10.9 | AW9: 1.2 | AX9: 0 | AY9: 0 | AZ9: 8.5153891 | BA9: 19.039537 | BB9: 2.6201197 | BC9: 0 | BD9: 0 | BE9: 30.175046
B10: KIKUNGA WA KIKINGA Claude | C10: DRIVER | D10: KINSHASA | E10: 077200289171154 | F10: E-BCDC | G10: 0 | I10: 15 | J10: 12.541338 | K10: 188.12007 | L10: 0 | M10: 12.541338 | N10: 0 | O10: 0 | P10: 12.541338 | Q10: 0 | R10: 0 | S10: 8.3650724 | T10: 0 | U10: 56.436021 | V10: 1.17 | W10: 17.55 | Y10: 0 | Z10: 17.55 | AA10: 0 | AB10: 188.12007 | AC10: 178.71407 | AD10: 9.4060035 | AE10: 18.354936 | AF10: 27.760939 | AG10: 0 | AH10: 234.34515 | AI10: 24.455609 | AJ10: 3.7624014 | AK10: 0.94060035 | AL10: 29.158611 | AM10: 291.2647 | AN10: 0 | AO10: 25 | AP10: 45 | AQ10: 46.602352 | AR10: =AM10+AN10+AO10+AP10+AQ10 -> 407.86705 | AU10: 0 | AV10: 0 | AW10: 0 | AX10: 0 | AY10: 0 | AZ10: 0 | BA10: 0 | BB10: 0 | BC10: 0 | BD10: 0 | BE10: 0
B11: TSHIBANGU KABONGO TEDDY | C11: IT SUPPORT | D11: LUBUDI | E11: 899100253931922 | F11: E-BCDC | G11: 0 | I11: 15 | J11: 23.000098 | K11: 345.00147 | L11: 0 | M11: 23.000098 | N11: 0 | O11: 0 | P11: 23.000098 | Q11: 0 | R11: 0 | S11: 15.341065 | T11: 0 | U11: 103.50044 | V11: 4.01 | W11: 60.15 | Y11: 0 | Z11: 60.15 | AA11: 0 | AB11: 345.00147 | AC11: 327.7514 | AD11: 17.250074 | AE11: 40.710536 | AF11: 57.960609 | AG11: 0 | AH11: 450.6913 | AI11: 44.850191 | AJ11: 6.9000294 | AK11: 1.7250074 | AL11: 53.475228 | AM11: 562.12714 | AN11: 0 | AO11: 25 | AP11: 45 | AQ11: 89.940343 | AR11: =AM11+AN11+AO11+AP11+AQ11 -> 722.06748 | AU11: 0 | AV11: 0 | AW11: 0 | AX11: 0 | AY11: 0 | AZ11: 0 | BA11: 0 | BB11: 0 | BC11: 0 | BD11: 0 | BE11: 0
B12: FLEUR KADIMA | C12: RECEPTIONNISTE | D12: KINSHASA | E12: 060121495120024 | F12: E-BCDC | G12: 0 | I12: 26 | J12: 19.486988 | K12: 337.77446 | L12: 0 | M12: 19.486988 | N12: 0 | O12: 0 | P12: 19.486988 | Q12: 0 | R12: 0 | S12: 12.997821 | T12: 0 | U12: 101.33234 | V12: 1.17 | W12: 30.42 | Y12: 0 | Z12: 30.42 | AA12: 0 | AB12: 337.77446 | AC12: 320.88574 | AD12: 16.888723 | AE12: 39.680687 | AF12: 56.56941 | AG12: 0 | AH12: 412.95739 | AI12: 43.91068 | AJ12: 6.7554893 | AK12: 1.6888723 | AL12: 52.355042 | AM12: 521.88184 | AN12: 0 | AO12: 25 | AP12: 45 | AQ12: 83.501095 | AR12: =AM12+AN12+AO12+AP12+AQ12 -> 675.38294 | AU12: 0 | AV12: 0 | AW12: 0 | AX12: 0 | AY12: 0 | AZ12: 0 | BA12: 0 | BB12: 0 | BC12: 0 | BD12: 0 | BE12: 0
B13: NKOSO BAONDJO Stanis | C13: Sales consultant | D13: BENA DIBELE | E13: 05162-01097622001-17 | F13: RAWBANK | G13: 0 | I13: 13 | J13: 24.522585 | K13: 318.7936 | L13: 0 | M13: 24.522585 | N13: 0 | O13: 0 | P13: 24.522585 | Q13: 0 | R13: 0 | S13: 16.356564 | T13: 0 | U13: 95.63808 | V13: 1.17 | W13: 15.21 | Y13: 0 | Z13: 15.21 | AA13: 0 | AB13: 318.7936 | AC13: 302.85392 | AD13: 15.93968 | AE13: 36.975914 | AF13: 52.915594 | AG13: 0 | AH13: 376.72609 | AI13: 41.443168 | AJ13: 6.375872 | AK13: 1.593968 | AL13: 49.413008 | AM13: 479.05469 | AN13: 0 | AO13: 25 | AP13: 45 | AQ13: 76.64875 | AR13: =AM13+AN13+AO13+AP13+AQ13 -> 625.70344 | AU13: 0 | AV13: 0 | AW13: 0 | AX13: 0 | AY13: 0 | AZ13: 0 | BA13: 0 | BB13: 0 | BC13: 0 | BD13: 0 | BE13: 0
B14: GAMIZELO MATALATALA CAMILLE | C14: WAREHOUSE CLERCK | D14: IDIOFA | G14: 0 | I14: 15 | J14: 24.522585 | K14: 367.83877 | L14: 0 | M14: 24.522585 | N14: 0 | O14: 0 | P14: 24.522585 | Q14: 0 | R14: 0 | S14: 16.356564 | T14: 0 | U14: 110.35163 | V14: 1.17 | W14: 17.55 | Y14: 0 | Z14: 17.55 | AA14: 0 | AB14: 367.83877 | AC14: 349.44683 | AD14: 18.391939 | AE14: 43.964851 | AF14: 62.356789 | AG14: 0 | AH14: 433.38361 | AI14: 47.81904 | AJ14: 7.3567754 | AK14: 1.8391939 | AL14: 57.015009 | AM14: 552.75541 | AN14: 0 | AO14: 25 | AP14: 45 | AQ14: 88.440866 | AR14: =AM14+AN14+AO14+AP14+AQ14 -> 711.19628 | AU14: 0 | AV14: 0 | AW14: 0 | AX14: 0 | AY14: 0 | AZ14: 0 | BA14: 0 | BB14: 0 | BC14: 0 | BD14: 0 | BE14: 0
B15: MBAKI MVUANDULU FRANCOIS | C15: WAREHOUSE CLERCK | D15: BUMBA | E15: 05181-01084984001-21 | F15: RAWBANK | G15: 0 | I15: 14 | J15: 24.522585 | K15: 343.31619 | L15: 0 | M15: 24.522585 | N15: 0 | O15: 0 | P15: 24.522585 | Q15: 0 | R15: 0 | S15: 16.356564 | T15: 0 | U15: 102.99486 | V15: 1.17 | W15: 16.38 | Y15: 0 | Z15: 16.38 | AA15: 0 | AB15: 343.31619 | AC15: 326.15038 | AD15: 17.165809 | AE15: 40.470383 | AF15: 57.636192 | AG15: 0 | AH15: 405.05485 | AI15: 44.631104 | AJ15: 6.8663237 | AK15: 1.7165809 | AL15: 53.214009 | AM15: 515.90505 | AN15: 0 | AO15: 25 | AP15: 45 | AQ15: 82.544808 | AR15: =AM15+AN15+AO15+AP15+AQ15 -> 668.44986 | AU15: 0 | AV15: 0 | AW15: 0 | AX15: 0 | AY15: 0 | AZ15: 0 | BA15: 0 | BB15: 0 | BC15: 0 | BD15: 0 | BE15: 0
B16: CONSOLATE PONGO | C16: Warehouse clerk | D16: KINSHASA | E16: 700100047832101 | F16: E-BCDC | G16: 0 | I16: 15 | J16: 35.239399 | K16: 528.59099 | L16: 0 | M16: 35.239399 | N16: 0 | O16: 0 | P16: 35.239399 | Q16: 0 | R16: 0 | S16: 23.504679 | T16: 0 | U16: 158.5773 | V16: 6.5 | W16: 97.5 | Y16: 0 | Z16: 97.5 | AA16: 0 | AB16: 528.59099 | AC16: 502.16144 | AD16: 26.429549 | AE16: 66.872042 | AF16: 93.301591 | AG16: 0 | AH16: 691.36669 | AI16: 68.716828 | AJ16: 10.57182 | AK16: 2.6429549 | AL16: 81.931603 | AM16: 866.59988 | AN16: 0 | AO16: 25 | AP16: 45 | AQ16: 138.65598 | AR16: =AM16+AN16+AO16+AP16+AQ16 -> 1075.2559 | AU16: 0 | AV16: 0 | AW16: 0 | AX16: 0 | AY16: 0 | AZ16: 0 | BA16: 0 | BB16: 0 | BC16: 0 | BD16: 0 | BE16: 0
B17: NGINDU KABUYA FRANCK | C17: WAREHOUSE OFFICER | D17: KANANGA | E17: 700100247958330 | F17: E-BCDC | G17: 0 | I17: 15 | J17: 24.522585 | K17: 367.83877 | L17: 0 | M17: 24.522585 | N17: 0 | O17: 0 | P17: 24.522585 | Q17: 0 | R17: 0 | S17: 16.356564 | T17: 0 | U17: 110.35163 | V17: 1.17 | W17: 17.55 | Y17: 0 | Z17: 17.55 | AA17: 0 | AB17: 367.83877 | AC17: 349.44683 | AD17: 18.391939 | AE17: 43.964851 | AF17: 62.356789 | AG17: 0 | AH17: 433.38361 | AI17: 47.81904 | AJ17: 7.3567754 | AK17: 1.8391939 | AL17: 57.015009 | AM17: 552.75541 | AN17: 0 | AO17: 25 | AP17: 45 | AQ17: 88.440866 | AR17: =AM17+AN17+AO17+AP17+AQ17 -> 711.19628 | AU17: 0 | AV17: 0 | AW17: 0 | AX17: 0 | AY17: 0 | AZ17: 0 | BA17: 0 | BB17: 0 | BC17: 0 | BD17: 0 | BE17: 0
B18: NKUMA MVIOKI NOE | C18: WAREHOUSE OFFICER | D18: MOANDA | E18: 733200096969385 | F18: E-BCDC | G18: 0 | I18: 15 | J18: 24.522585 | K18: 367.83877 | L18: 0 | M18: 24.522585 | N18: 0 | O18: 0 | P18: 24.522585 | Q18: 0 | R18: 0 | S18: 16.356564 | T18: 0 | U18: 110.35163 | V18: 1.17 | W18: 17.55 | Y18: 0 | Z18: 17.55 | AA18: 0 | AB18: 367.83877 | AC18: 349.44683 | AD18: 18.391939 | AE18: 43.964851 | AF18: 62.356789 | AG18: 0 | AH18: 433.38361 | AI18: 47.81904 | AJ18: 7.3567754 | AK18: 1.8391939 | AL18: 57.015009 | AM18: 552.75541 | AN18: 0 | AO18: 25 | AP18: 45 | AQ18: 88.440866 | AR18: =AM18+AN18+AO18+AP18+AQ18 -> 711.19628 | AU18: 0 | AV18: 0 | AW18: 0 | AX18: 0 | AY18: 0 | AZ18: 0 | BA18: 0 | BB18: 0 | BC18: 0 | BD18: 0 | BE18: 0
B19: BOB KITENGE | C19: Warehouse operator | D19: KINSHASA | E19: 05141-00977656001-08 | F19: RAWBANK | G19: 0 | I19: 15 | J19: 24.522585 | K19: 367.83877 | L19: 0 | M19: 24.522585 | N19: 0 | O19: 0 | P19: 24.522585 | Q19: 0 | R19: 0 | S19: 16.356564 | T19: 0 | U19: 110.35163 | V19: 1.17 | W19: 17.55 | Y19: 0 | Z19: 17.55 | AA19: 0 | AB19: 367.83877 | AC19: 349.44683 | AD19: 18.391939 | AE19: 43.964851 | AF19: 62.356789 | AG19: 0 | AH19: 433.38361 | AI19: 47.81904 | AJ19: 7.3567754 | AK19: 1.8391939 | AL19: 57.015009 | AM19: 552.75541 | AN19: 0 | AO19: 25 | AP19: 45 | AQ19: 88.440866 | AR19: =AM19+AN19+AO19+AP19+AQ19 -> 711.19628 | AU19: 0 | AV19: 0 | AW19: 0 | AX19: 0 | AY19: 0 | AZ19: 0 | BA19: 0 | BB19: 0 | BC19: 0 | BD19: 0 | BE19: 0
B20: Josué BAKAFUKA | C20: Warehouse operator | D20: KINSHASA | E20: 500100081327606 | F20: E-BCDC | G20: 0 | I20: 15 | J20: 35.239399 | K20: 528.59099 | L20: 0 | M20: 35.239399 | N20: 0 | O20: 0 | P20: 35.239399 | Q20: 0 | R20: 0 | S20: 23.504679 | T20: 0 | U20: 158.5773 | V20: 6.5 | W20: 97.5 | Y20: 0 | Z20: 97.5 | AA20: 0 | AB20: 528.59099 | AC20: 502.16144 | AD20: 26.429549 | AE20: 66.872042 | AF20: 93.301591 | AG20: 0 | AH20: 691.36669 | AI20: 68.716828 | AJ20: 10.57182 | AK20: 2.6429549 | AL20: 81.931603 | AM20: 866.59988 | AN20: 0 | AO20: 25 | AP20: 45 | AQ20: 138.65598 | AR20: =AM20+AN20+AO20+AP20+AQ20 -> 1075.2559 | AU20: 0 | AV20: 0 | AW20: 0 | AX20: 0 | AY20: 0 | AZ20: 0 | BA20: 0 | BB20: 0 | BC20: 0 | BD20: 0 | BE20: 0
B21: BAMPEMBE BAFUMBA HUGUE | C21: WAREHOUSE OPERATOR | D21: BENA DIBELE | E21: 05162-01091888001-37 | F21: RAWBANK | G21: 0 | I21: 15 | J21: 24.522585 | K21: 367.83877 | L21: 0 | M21: 24.522585 | N21: 0 | O21: 0 | P21: 24.522585 | Q21: 0 | R21: 0 | S21: 16.356564 | T21: 0 | U21: 110.35163 | V21: 1.17 | W21: 17.55 | Y21: 0 | Z21: 17.55 | AA21: 0 | AB21: 367.83877 | AC21: 349.44683 | AD21: 18.391939 | AE21: 43.964851 | AF21: 62.356789 | AG21: 0 | AH21: 433.38361 | AI21: 47.81904 | AJ21: 7.3567754 | AK21: 1.8391939 | AL21: 57.015009 | AM21: 552.75541 | AN21: 0 | AO21: 25 | AP21: 45 | AQ21: 88.440866 | AR21: =AM21+AN21+AO21+AP21+AQ21 -> 711.19628 | AU21: 0 | AV21: 0 | AW21: 0 | AX21: 0 | AY21: 0 | AZ21: 0 | BA21: 0 | BB21: 0 | BC21: 0 | BD21: 0 | BE21: 0
B22: KIDALA DIANDUKILA WILLIAMS | C22: WAREHOUSE OPERATOR | D22: KIMPESE | E22: 544200178512476 | F22: E-BCDC | G22: 0 | I22: 26 | J22: 24.522585 | K22: 637.5872 | L22: 0 | M22: 24.522585 | N22: 0 | O22: 0 | P22: 24.522585 | Q22: 0 | R22: 0 | S22: 16.356564 | T22: 0 | U22: 191.27616 | V22: 1.17 | W22: 30.42 | Y22: 0 | Z22: 30.42 | AA22: 0 | AB22: 637.5872 | AC22: 605.70784 | AD22: 31.87936 | AE22: 82.404002 | AF22: 114.28336 | AG22: 0 | AH22: 745 | AI22: 82.886336 | AJ22: 12.751744 | AK22: 3.187936 | AL22: 98.826016 | AM22: 958.10938 | AN22: 0 | AO22: 25 | AP22: 45 | AQ22: 153.2975 | AR22: =AM22+AN22+AO22+AP22+AQ22 -> 1181.4069 | AU22: 0 | AV22: 0 | AW22: 0 | AX22: 0 | AY22: 0 | AZ22: 0 | BA22: 0 | BB22: 0 | BC22: 0 | BD22: 0 | BE22: 0
B23: MALOMAMO YEMA Jean Marie | C23: Chauffeur Chariot elevateur | D23: KISANGANI | I23: 26 | J23: 15.28 | K23: 397.28 | L23: 0 | N23: 0 | O23: 0 | Q23: 0 | R23: 0 | T23: 0 | U23: 119.184 | V23: 3.2041905 | W23: 83.308952 | Y23: 0 | Z23: 83.308952 | AA23: 0 | AB23: 397.28 | AC23: 377.416 | AD23: 19.864 | AE23: 48.16 | AF23: 68.024 | AG23: 0 | AH23: 531.74895 | AI23: 51.6464 | AJ23: 7.9456 | AK23: 1.9864 | AL23: 61.5784 | AM23: 661.35135 | AN23: 0 | AO23: 25 | AP23: 45 | AQ23: 105.81622 | AR23: =AM23+AN23+AO23+AP23+AQ23 -> 837.16757 | AU23: 0 | AV23: 0 | AW23: 0 | AX23: 0 | AY23: 0 | AZ23: 0 | BA23: 0 | BB23: 0 | BC23: 0 | BD23: 0 | BE23: 0
B24: SONGBELE Jacques | C24: Warehouse | D24: MBANDAKA | I24: 26 | J24: 22.8 | K24: 592.8 | L24: 0 | N24: 0 | O24: 0 | Q24: 0 | R24: 0 | T24: 0 | U24: 177.84 | V24: 4.7604058 | W24: 123.77055 | Y24: 0 | Z24: 123.77055 | AA24: 0 | AB24: 592.8 | AC24: 563.16 | AD24: 29.64 | AE24: 76.02 | AF24: 105.66 | AG24: 0 | AH24: 788.75055 | AI24: 77.064 | AJ24: 11.856 | AK24: 2.964 | AL24: 91.884 | AM24: 986.29455 | AN24: 0 | AO24: 25 | AP24: 45 | AQ24: 157.80713 | AR24: =AM24+AN24+AO24+AP24+AQ24 -> 1214.1017 | AU24: 0 | AV24: 0 | AW24: 0 | AX24: 0 | AY24: 0 | AZ24: 0 | BA24: 0 | BB24: 0 | BC24: 0 | BD24: 0 | BE24: 0
B25: MAKOBO FUANINUA Christian | C25: Spooter | D25: LUBUDI | I25: 26 | J25: 3.91 | K25: 78.2 | L25: 0 | N25: 0 | O25: 0 | Q25: 0 | R25: 0 | T25: 0 | U25: 177.84 | V25: 4.7604058 | W25: 123.77055 | Y25: 0 | Z25: 123.77055 | AA25: 0 | AB25: 78.2 | AC25: 74.29 | AD25: 3.91 | AE25: 2.69 | AF25: 6.6 | AG25: 0 | AH25: 373.21055 | AI25: 10.166 | AJ25: 1.564 | AK25: 0.391 | AL25: 12.121 | AM25: 391.93155 | AN25: 0 | AO25: 25 | AP25: 45 | AQ25: 62.709048 | AR25: =AM25+AN25+AO25+AP25+AQ25 -> 524.6406 | AU25: 0 | AV25: 0 | AW25: 0 | AX25: 0 | AY25: 0 | AZ25: 0 | BA25: 0 | BB25: 0 | BC25: 0 | BD25: 0 | BE25: 0
B26: LUMUNA KILWINA SERGE | C26: Spooter | D26: LUBUDI | I26: 26 | J26: 3.91 | K26: 101.66 | L26: 0 | N26: 0 | O26: 0 | Q26: 0 | R26: 0 | T26: 0 | U26: 30.498 | V26: 0.41185007 | W26: 10.708102 | Y26: 0 | Z26: 10.708102 | AA26: 0 | AB26: 101.66 | AC26: 96.577 | AD26: 5.083 | AE26: 6.03 | AF26: 11.113 | AG26: 0 | AH26: 131.7531 | AI26: 13.2158 | AJ26: 2.0332 | AK26: 0.5083 | AL26: 15.7573 | AM26: 158.6234 | AN26: 0 | AO26: 25 | AP26: 45 | AQ26: 25.379744 | AR26: =AM26+AN26+AO26+AP26+AQ26 -> 254.00315 | AU26: 0 | AV26: 0 | AW26: 0 | AX26: 0 | AY26: 0 | AZ26: 0 | BA26: 0 | BB26: 0 | BC26: 0 | BD26: 0 | BE26: 0
B27: MUTELA MBAU Christian | C27: Spooter | D27: LUBUDI | I27: 26 | J27: 3.91 | K27: 101.66 | L27: 0 | N27: 0 | O27: 0 | Q27: 0 | R27: 0 | T27: 0 | U27: 30.498 | V27: 0.41185007 | W27: 10.708102 | Y27: 0 | Z27: 10.708102 | AA27: 0 | AB27: 101.66 | AC27: 96.577 | AD27: 5.083 | AE27: 6.03 | AF27: 11.113 | AG27: 0 | AH27: 131.7531 | AI27: 13.2158 | AJ27: 2.0332 | AK27: 0.5083 | AL27: 15.7573 | AM27: 158.6234 | AN27: 0 | AO27: 25 | AP27: 45 | AQ27: 25.379744 | AR27: =AM27+AN27+AO27+AP27+AQ27 -> 254.00315 | AU27: 0 | AV27: 0 | AW27: 0 | AX27: 0 | AY27: 0 | AZ27: 0 | BA27: 0 | BB27: 0 | BC27: 0 | BD27: 0 | BE27: 0
B28: NUMBI IMANGO Théophil | C28: Spooter | D28: LUBUDI | I28: 26 | J28: 3.91 | K28: 101.66 | L28: 0 | N28: 0 | O28: 0 | Q28: 0 | R28: 0 | T28: 0 | U28: 30.498 | V28: 0.41185007 | W28: 10.708102 | Y28: 0 | Z28: 10.708102 | AA28: 0 | AB28: 101.66 | AC28: 96.577 | AD28: 5.083 | AE28: 6.03 | AF28: 11.113 | AG28: 0 | AH28: 131.7531 | AI28: 13.2158 | AJ28: 2.0332 | AK28: 0.5083 | AL28: 15.7573 | AM28: 158.6234 | AN28: 0 | AO28: 25 | AP28: 45 | AQ28: 25.379744 | AR28: =AM28+AN28+AO28+AP28+AQ28 -> 254.00315 | AU28: 0 | AV28: 0 | AW28: 0 | AX28: 0 | AY28: 0 | AZ28: 0 | BA28: 0 | BB28: 0 | BC28: 0 | BD28: 0 | BE28: 0
B29: USENI KITOKO Cesar | C29: Warehouse | D29: KINSHASA | I29: 26 | J29: 22.8 | K29: 592.8 | L29: 0 | N29: 0 | O29: 0 | Q29: 0 | R29: 0 | T29: 0 | U29: 177.84 | V29: 4.7603846 | W29: 123.77 | Y29: 0 | Z29: 123.77 | AA29: 0 | AB29: 592.8 | AC29: 563.16 | AD29: 29.64 | AE29: 76.02 | AF29: 105.66 | AG29: 0 | AH29: 788.75 | AI29: 77.064 | AJ29: 11.856 | AK29: 2.964 | AL29: 91.884 | AM29: 986.294 | AN29: 0 | AO29: 25 | AP29: 45 | AQ29: 157.80704 | AR29: =AM29+AN29+AO29+AP29+AQ29 -> 1214.101 | AU29: 0 | AV29: 0 | AW29: 0 | AX29: 0 | AY29: 0 | AZ29: 0 | BA29: 0 | BB29: 0 | BC29: 0 | BD29: 0 | BE29: 0
B30: KALENGA MBAYO Chancelle | C30: Agent d'entretien | D30: LUBUDI | I30: 26 | J30: 8.8 | K30: 228.8 | L30: 0 | N30: 0 | O30: 0 | Q30: 0 | R30: 0 | T30: 0 | U30: 68.64 | V30: 0.80386737 | W30: 20.900552 | Y30: 0 | Z30: 20.900552 | AA30: 0 | AB30: 228.8 | AC30: 217.36 | AD30: 11.44 | AE30: 24.15 | AF30: 35.59 | AG30: 0 | AH30: 282.75055 | AI30: 29.744 | AJ30: 4.576 | AK30: 1.144 | AL30: 35.464 | AM30: 353.80455 | AN30: 0 | AO30: 25 | AP30: 45 | AQ30: 56.608728 | AR30: =AM30+AN30+AO30+AP30+AQ30 -> 480.41328 | AU30: 0 | AV30: 0 | AW30: 0 | AX30: 0 | AY30: 0 | AZ30: 0 | BA30: 0 | BB30: 0 | BC30: 0 | BD30: 0 | BE30: 0
B31: NGUVU MUNYANGI ROBERT | C31: chauffeur | D31: LUBUDI | I31: 26 | J31: 11.71 | K31: 304.46 | L31: 0 | N31: 0 | O31: 0 | Q31: 0 | R31: 0 | T31: 0 | U31: 91.34 | V31: 1.22 | W31: 31.64 | X31: 2 | Y31: 0 | Z31: 34.08 | AA31: 42.68295 | AB31: 347.14295 | AC31: 329.7858 | AD31: 17.357148 | AE31: 36.68 | AF31: 67.347437 | AG31: 0 | AH31: 405.21551 | AI31: 45.128584 | AJ31: 6.942859 | AK31: 1.7357148 | AL31: 53.807157 | AM31: 513.05982 | AN31: 0 | AO31: 25 | AP31: 45 | AQ31: 82.089571 | AR31: =AM31+AN31+AO31+AP31+AQ31 -> 665.14939 | AU31: 6 | AV31: 1.6 | AW31: 7.75 | AX31: 3 | AY31: 0 | AZ31: 11.41725 | BA31: 3.7472 | BB31: 22.688125 | BC31: 4.830375 | BD31: 0 | BE31: 42.68295
B32: KYUNGU ILUNGA | C32: chauffeur | D32: LUBUDI | I32: 6 | J32: 11.71 | K32: 70.26 | L32: 0 | N32: 0 | O32: 0 | Q32: 0 | R32: 0 | T32: 0 | U32: 91.34 | V32: 5.2733333 | W32: 31.64 | Y32: 0 | Z32: 31.64 | AA32: 0 | AB32: 70.26 | AC32: 66.75 | AD32: 3.513 | AE32: 2 | AF32: 5.513 | AG32: 0 | AH32: 187.727 | AI32: 9.1338 | AJ32: 1.4052 | AK32: 0.3513 | AL32: 10.8903 | AM32: 204.1303 | AN32: 0 | AO32: 25 | AP32: 45 | AQ32: 32.660848 | AR32: =AM32+AN32+AO32+AP32+AQ32 -> 306.79115 | AU32: 0 | AV32: 0 | AW32: 0 | AX32: 0 | AY32: 0 | AZ32: 0 | BA32: 0 | BB32: 0 | BC32: 0 | BD32: 0 | BE32: 0
B33: BASHONGA MOHINDO ALINE | C33: Receptionniste | D33: KINSHASA | I33: 26 | J33: 14.39 | K33: 374.14 | L33: 0 | N33: 0 | O33: 0 | Q33: 0 | R33: 0 | T33: 0 | U33: 8.58 | V33: 2.66 | W33: 69.16 | Y33: 0 | Z33: 69.16 | AA33: 0 | AB33: 374.14 | AC33: 355.433 | AD33: 18.707 | AE33: 44.86 | AF33: 63.567 | AG33: 0 | AH33: 388.313 | AI33: 48.6382 | AJ33: 7.4828 | AK33: 1.8707 | AL33: 57.9917 | AM33: 509.8717 | AN33: 0 | AO33: 25 | AP33: 45 | AQ33: 81.579472 | AR33: =AM33+AN33+AO33+AP33+AQ33 -> 661.45117 | AU33: 0 | AV33: 0 | AW33: 0 | AX33: 0 | AY33: 0 | AZ33: 0 | BA33: 0 | BB33: 0 | BC33: 0 | BD33: 0 | BE33: 0
B34: SOMBO NGUTU ALBERT | C34: chauffeur | D34: KISANGANI | I34: 3 | J34: 14.39 | K34: 43.17 | L34: 0 | N34: 0 | O34: 0 | Q34: 0 | R34: 0 | T34: 0 | U34: 8.58 | V34: 23.053333 | W34: 69.16 | Y34: 0 | Z34: 69.16 | AA34: 0 | AB34: 43.17 | AC34: 41.0115 | AD34: 2.1585 | AE34: 1.23 | AF34: 3.3885 | AG34: 0 | AH34: 117.5215 | AI34: 5.6121 | AJ34: 0.8634 | AK34: 0.21585 | AL34: 6.69135 | AM34: 127.60135 | AN34: 0 | AO34: 25 | AP34: 45 | AQ34: 20.416216 | AR34: =AM34+AN34+AO34+AP34+AQ34 -> 218.01757 | AU34: 0 | AV34: 0 | AW34: 0 | AX34: 0 | AY34: 0 | AZ34: 0 | BA34: 0 | BB34: 0 | BC34: 0 | BD34: 0 | BE34: 0
B35: MALO MALO YEMA JEAN H | C35: CONDUCTEUR ELEVATEUR | D35: KISANGANI | I35: 26 | J35: 15.28 | K35: 397.28 | L35: 0 | N35: 0 | O35: 0 | Q35: 0 | R35: 0 | T35: 0 | U35: 119.184 | V35: 3.2042308 | W35: 83.31 | Y35: 0 | Z35: 83.31 | AA35: 8.404 | AB35: 405.684 | AC35: 385.3998 | AD35: 20.2842 | AE35: 49.35 | AF35: 69.6342 | AG35: 0 | AH35: 538.5438 | AI35: 52.73892 | AJ35: 8.11368 | AK35: 2.02842 | AL35: 62.88102 | AM35: 671.05902 | AN35: 0 | AO35: 25 | AP35: 45 | AQ35: 107.36944 | AR35: =AM35+AN35+AO35+AP35+AQ35 -> 848.42846 | AU35: 0 | AV35: 0 | AW35: 0 | AX35: 4 | AY35: 0 | AZ35: 0 | BA35: 0 | BB35: 0 | BC35: 8.404 | BD35: 0 | BE35: 8.404

Sheet Moteur IPR
I4: taux | J4: 2300
B5: taux | C5: valeur inf | D5: valeur sup | E5: cumul | G5: nbre pers | H5: USD | I5: CDF | J5: BI | K5: Taux | L5: Tranche | M5: Cumul IPR | N5: Rabais | O5: IPR NET | P5: IPR USD
B6: 0 | C6: 0 | D6: 162000 | E6: 4860 | G6: ='Hors-Site'!G6 -> 0 | H6: ='Hors-Site'!AC6 -> 161.41903 | I6: =Tableau1[[#This Row],[USD]]*$J$4 -> 371263.76 | J6: =I6-VLOOKUP($I6,$C$6:$D$9,1) -> 209263.76 | K6: =VLOOKUP($I6,$C$11:$D$14,2) -> 0.15 | L6: =J6*K6 -> 31389.564 | M6: =L6+VLOOKUP($I6,$C$15:$E$19,3) -> 36249.564 | N6: =M6*(G6*2%) -> 0 | O6: =M6-N6 -> 36249.564 | P6: =O6/$J$4 -> 15.76068
B7: 0.15 | C7: 162000 | D7: 1800000 | E7: 245700 | G7: ='Hors-Site'!#REF! -> #REF! | H7: ='Hors-Site'!#REF! -> #REF! | I7: =Tableau1[[#This Row],[USD]]*$J$4 -> #REF! | J7: =I7-VLOOKUP($I7,$C$6:$D$9,1) -> #REF! | K7: =VLOOKUP($I7,$C$11:$D$14,2) -> #REF! | L7: =J7*K7 -> #REF! | M7: =L7+VLOOKUP($I7,$C$15:$E$19,3) -> #REF! | N7: =M7*(G7*2%) -> #REF! | O7: =M7-N7 -> #REF! | P7: =O7/$J$4 -> #REF!
B8: 0.3 | C8: 1800000 | D8: 3600000 | E8: 540000 | G8: ='Hors-Site'!#REF! -> #REF! | H8: ='Hors-Site'!#REF! -> #REF! | I8: =Tableau1[[#This Row],[USD]]*$J$4 -> #REF! | J8: =I8-VLOOKUP($I8,$C$6:$D$9,1) -> #REF! | K8: =VLOOKUP($I8,$C$11:$D$14,2) -> #REF! | L8: =J8*K8 -> #REF! | M8: =L8+VLOOKUP($I8,$C$15:$E$19,3) -> #REF! | N8: =M8*(G8*2%) -> #REF! | O8: =M8-N8 -> #REF! | P8: =O8/$J$4 -> #REF!
B9: 0.4 | C9: 3600000 | D9: 0 | E9: 0 | G9: ='Hors-Site'!#REF! -> #REF! | H9: ='Hors-Site'!#REF! -> #REF! | I9: =Tableau1[[#This Row],[USD]]*$J$4 -> #REF! | J9: =I9-VLOOKUP($I9,$C$6:$D$9,1) -> #REF! | K9: =VLOOKUP($I9,$C$11:$D$14,2) -> #REF! | L9: =J9*K9 -> #REF! | M9: =L9+VLOOKUP($I9,$C$15:$E$19,3) -> #REF! | N9: =M9*(G9*2%) -> #REF! | O9: =M9-N9 -> #REF! | P9: =O9/$J$4 -> #REF!
G10: ='Hors-Site'!#REF! -> #REF! | H10: ='Hors-Site'!#REF! -> #REF! | I10: =Tableau1[[#This Row],[USD]]*$J$4 -> #REF! | J10: =I10-VLOOKUP($I10,$C$6:$D$9,1) -> #REF! | K10: =VLOOKUP($I10,$C$11:$D$14,2) -> #REF! | L10: =J10*K10 -> #REF! | M10: =L10+VLOOKUP($I10,$C$15:$E$19,3) -> #REF! | N10: =M10*(G10*2%) -> #REF! | O10: =M10-N10 -> #REF! | P10: =O10/$J$4 -> #REF!
C11: 0 | D11: 0 | G11: ='Hors-Site'!#REF! -> #REF! | H11: ='Hors-Site'!#REF! -> #REF! | I11: =Tableau1[[#This Row],[USD]]*$J$4 -> #REF! | J11: =I11-VLOOKUP($I11,$C$6:$D$9,1) -> #REF! | K11: =VLOOKUP($I11,$C$11:$D$14,2) -> #REF! | L11: =J11*K11 -> #REF! | M11: =L11+VLOOKUP($I11,$C$15:$E$19,3) -> #REF! | N11: =M11*(G11*2%) -> #REF! | O11: =M11-N11 -> #REF! | P11: =O11/$J$4 -> #REF!
C12: 162001 | D12: 0.15 | G12: ='Hors-Site'!#REF! -> #REF! | H12: ='Hors-Site'!#REF! -> #REF! | I12: =Tableau1[[#This Row],[USD]]*$J$4 -> #REF! | J12: =I12-VLOOKUP($I12,$C$6:$D$9,1) -> #REF! | K12: =VLOOKUP($I12,$C$11:$D$14,2) -> #REF! | L12: =J12*K12 -> #REF! | M12: =L12+VLOOKUP($I12,$C$15:$E$19,3) -> #REF! | N12: =M12*(G12*2%) -> #REF! | O12: =M12-N12 -> #REF! | P12: =O12/$J$4 -> #REF!
C13: 1800001 | D13: 0.3 | G13: ='Hors-Site'!#REF! -> #REF! | H13: ='Hors-Site'!#REF! -> #REF! | I13: =Tableau1[[#This Row],[USD]]*$J$4 -> #REF! | J13: =I13-VLOOKUP($I13,$C$6:$D$9,1) -> #REF! | K13: =VLOOKUP($I13,$C$11:$D$14,2) -> #REF! | L13: =J13*K13 -> #REF! | M13: =L13+VLOOKUP($I13,$C$15:$E$19,3) -> #REF! | N13: =M13*(G13*2%) -> #REF! | O13: =M13-N13 -> #REF! | P13: =O13/$J$4 -> #REF!
C14: 3600001 | D14: 0.4 | G14: ='Hors-Site'!#REF! -> #REF! | H14: ='Hors-Site'!#REF! -> #REF! | I14: =Tableau1[[#This Row],[USD]]*$J$4 -> #REF! | J14: =I14-VLOOKUP($I14,$C$6:$D$9,1) -> #REF! | K14: =VLOOKUP($I14,$C$11:$D$14,2) -> #REF! | L14: =J14*K14 -> #REF! | M14: =L14+VLOOKUP($I14,$C$15:$E$19,3) -> #REF! | N14: =M14*(G14*2%) -> #REF! | O14: =M14-N14 -> #REF! | P14: =O14/$J$4 -> #REF!
G15: ='Hors-Site'!#REF! -> #REF! | H15: ='Hors-Site'!#REF! -> #REF! | I15: =Tableau1[[#This Row],[USD]]*$J$4 -> #REF! | J15: =I15-VLOOKUP($I15,$C$6:$D$9,1) -> #REF! | K15: =VLOOKUP($I15,$C$11:$D$14,2) -> #REF! | L15: =J15*K15 -> #REF! | M15: =L15+VLOOKUP($I15,$C$15:$E$19,3) -> #REF! | N15: =M15*(G15*2%) -> #REF! | O15: =M15-N15 -> #REF! | P15: =O15/$J$4 -> #REF!
C16: 0 | D16: 4860 | E16: 2300 | G16: ='Hors-Site'!#REF! -> #REF! | H16: ='Hors-Site'!#REF! -> #REF! | I16: =Tableau1[[#This Row],[USD]]*$J$4 -> #REF! | J16: =I16-VLOOKUP($I16,$C$6:$D$9,1) -> #REF! | K16: =VLOOKUP($I16,$C$11:$D$14,2) -> #REF! | L16: =J16*K16 -> #REF! | M16: =L16+VLOOKUP($I16,$C$15:$E$19,3) -> #REF! | N16: =M16*(G16*2%) -> #REF! | O16: =M16-N16 -> #REF! | P16: =O16/$J$4 -> #REF!
C17: 162001 | D17: 245700 | E17: 4860 | G17: ='Hors-Site'!#REF! -> #REF! | H17: ='Hors-Site'!#REF! -> #REF! | I17: =Tableau1[[#This Row],[USD]]*$J$4 -> #REF! | J17: =I17-VLOOKUP($I17,$C$6:$D$9,1) -> #REF! | K17: =VLOOKUP($I17,$C$11:$D$14,2) -> #REF! | L17: =J17*K17 -> #REF! | M17: =L17+VLOOKUP($I17,$C$15:$E$19,3) -> #REF! | N17: =M17*(G17*2%) -> #REF! | O17: =M17-N17 -> #REF! | P17: =O17/$J$4 -> #REF!
C18: 1800001 | D18: 540000 | E18: 250560 | G18: ='Hors-Site'!#REF! -> #REF! | H18: ='Hors-Site'!#REF! -> #REF! | I18: =Tableau1[[#This Row],[USD]]*$J$4 -> #REF! | J18: =I18-VLOOKUP($I18,$C$6:$D$9,1) -> #REF! | K18: =VLOOKUP($I18,$C$11:$D$14,2) -> #REF! | L18: =J18*K18 -> #REF! | M18: =L18+VLOOKUP($I18,$C$15:$E$19,3) -> #REF! | N18: =M18*(G18*2%) -> #REF! | O18: =M18-N18 -> #REF! | P18: =O18/$J$4 -> #REF!
C19: 3600001 | D19: 0 | E19: 790560 | G19: ='Hors-Site'!#REF! -> #REF! | H19: ='Hors-Site'!#REF! -> #REF! | I19: =Tableau1[[#This Row],[USD]]*$J$4 -> #REF! | J19: =I19-VLOOKUP($I19,$C$6:$D$9,1) -> #REF! | K19: =VLOOKUP($I19,$C$11:$D$14,2) -> #REF! | L19: =J19*K19 -> #REF! | M19: =L19+VLOOKUP($I19,$C$15:$E$19,3) -> #REF! | N19: =M19*(G19*2%) -> #REF! | O19: =M19-N19 -> #REF! | P19: =O19/$J$4 -> #REF!
G20: ='Hors-Site'!#REF! -> #REF! | H20: ='Hors-Site'!#REF! -> #REF! | I20: =Tableau1[[#This Row],[USD]]*$J$4 -> #REF! | J20: =I20-VLOOKUP($I20,$C$6:$D$9,1) -> #REF! | K20: =VLOOKUP($I20,$C$11:$D$14,2) -> #REF! | L20: =J20*K20 -> #REF! | M20: =L20+VLOOKUP($I20,$C$15:$E$19,3) -> #REF! | N20: =M20*(G20*2%) -> #REF! | O20: =M20-N20 -> #REF! | P20: =O20/$J$4 -> #REF!
G21: ='Hors-Site'!#REF! -> #REF! | H21: ='Hors-Site'!#REF! -> #REF! | I21: =Tableau1[[#This Row],[USD]]*$J$4 -> #REF! | J21: =I21-VLOOKUP($I21,$C$6:$D$9,1) -> #REF! | K21: =VLOOKUP($I21,$C$11:$D$14,2) -> #REF! | L21: =J21*K21 -> #REF! | M21: =L21+VLOOKUP($I21,$C$15:$E$19,3) -> #REF! | N21: =M21*(G21*2%) -> #REF! | O21: =M21-N21 -> #REF! | P21: =O21/$J$4 -> #REF!
G22: ='Hors-Site'!#REF! -> #REF! | H22: ='Hors-Site'!#REF! -> #REF! | I22: =Tableau1[[#This Row],[USD]]*$J$4 -> #REF! | J22: =I22-VLOOKUP($I22,$C$6:$D$9,1) -> #REF! | K22: =VLOOKUP($I22,$C$11:$D$14,2) -> #REF! | L22: =J22*K22 -> #REF! | M22: =L22+VLOOKUP($I22,$C$15:$E$19,3) -> #REF! | N22: =M22*(G22*2%) -> #REF! | O22: =M22-N22 -> #REF! | P22: =O22/$J$4 -> #REF!
G23: ='Hors-Site'!#REF! -> #REF! | H23: ='Hors-Site'!#REF! -> #REF! | I23: =Tableau1[[#This Row],[USD]]*$J$4 -> #REF! | J23: =I23-VLOOKUP($I23,$C$6:$D$9,1) -> #REF! | K23: =VLOOKUP($I23,$C$11:$D$14,2) -> #REF! | L23: =J23*K23 -> #REF! | M23: =L23+VLOOKUP($I23,$C$15:$E$19,3) -> #REF! | N23: =M23*(G23*2%) -> #REF! | O23: =M23-N23 -> #REF! | P23: =O23/$J$4 -> #REF!
G24: ='Hors-Site'!#REF! -> #REF! | H24: ='Hors-Site'!#REF! -> #REF! | I24: =Tableau1[[#This Row],[USD]]*$J$4 -> #REF! | J24: =I24-VLOOKUP($I24,$C$6:$D$9,1) -> #REF! | K24: =VLOOKUP($I24,$C$11:$D$14,2) -> #REF! | L24: =J24*K24 -> #REF! | M24: =L24+VLOOKUP($I24,$C$15:$E$19,3) -> #REF! | N24: =M24*(G24*2%) -> #REF! | O24: =M24-N24 -> #REF! | P24: =O24/$J$4 -> #REF!
G25: ='Hors-Site'!#REF! -> #REF! | H25: ='Hors-Site'!#REF! -> #REF! | I25: =Tableau1[[#This Row],[USD]]*$J$4 -> #REF! | J25: =I25-VLOOKUP($I25,$C$6:$D$9,1) -> #REF! | K25: =VLOOKUP($I25,$C$11:$D$14,2) -> #REF! | L25: =J25*K25 -> #REF! | M25: =L25+VLOOKUP($I25,$C$15:$E$19,3) -> #REF! | N25: =M25*(G25*2%) -> #REF! | O25: =M25-N25 -> #REF! | P25: =O25/$J$4 -> #REF!
G26: ='Hors-Site'!#REF! -> #REF! | H26: ='Hors-Site'!#REF! -> #REF! | I26: =Tableau1[[#This Row],[USD]]*$J$4 -> #REF! | J26: =I26-VLOOKUP($I26,$C$6:$D$9,1) -> #REF! | K26: =VLOOKUP($I26,$C$11:$D$14,2) -> #REF! | L26: =J26*K26 -> #REF! | M26: =L26+VLOOKUP($I26,$C$15:$E$19,3) -> #REF! | N26: =M26*(G26*2%) -> #REF! | O26: =M26-N26 -> #REF! | P26: =O26/$J$4 -> #REF!
G27: ='Hors-Site'!#REF! -> #REF! | H27: ='Hors-Site'!#REF! -> #REF! | I27: =Tableau1[[#This Row],[USD]]*$J$4 -> #REF! | J27: =I27-VLOOKUP($I27,$C$6:$D$9,1) -> #REF! | K27: =VLOOKUP($I27,$C$11:$D$14,2) -> #REF! | L27: =J27*K27 -> #REF! | M27: =L27+VLOOKUP($I27,$C$15:$E$19,3) -> #REF! | N27: =M27*(G27*2%) -> #REF! | O27: =M27-N27 -> #REF! | P27: =O27/$J$4 -> #REF!
G28: ='Hors-Site'!#REF! -> #REF! | H28: ='Hors-Site'!#REF! -> #REF! | I28: =Tableau1[[#This Row],[USD]]*$J$4 -> #REF! | J28: =I28-VLOOKUP($I28,$C$6:$D$9,1) -> #REF! | K28: =VLOOKUP($I28,$C$11:$D$14,2) -> #REF! | L28: =J28*K28 -> #REF! | M28: =L28+VLOOKUP($I28,$C$15:$E$19,3) -> #REF! | N28: =M28*(G28*2%) -> #REF! | O28: =M28-N28 -> #REF! | P28: =O28/$J$4 -> #REF!
G29: ='Hors-Site'!#REF! -> #REF! | H29: ='Hors-Site'!#REF! -> #REF! | I29: =Tableau1[[#This Row],[USD]]*$J$4 -> #REF! | J29: =I29-VLOOKUP($I29,$C$6:$D$9,1) -> #REF! | K29: =VLOOKUP($I29,$C$11:$D$14,2) -> #REF! | L29: =J29*K29 -> #REF! | M29: =L29+VLOOKUP($I29,$C$15:$E$19,3) -> #REF! | N29: =M29*(G29*2%) -> #REF! | O29: =M29-N29 -> #REF! | P29: =O29/$J$4 -> #REF!
G30: ='Hors-Site'!#REF! -> #REF! | H30: ='Hors-Site'!#REF! -> #REF! | I30: =Tableau1[[#This Row],[USD]]*$J$4 -> #REF! | J30: =I30-VLOOKUP($I30,$C$6:$D$9,1) -> #REF! | K30: =VLOOKUP($I30,$C$11:$D$14,2) -> #REF! | L30: =J30*K30 -> #REF! | M30: =L30+VLOOKUP($I30,$C$15:$E$19,3) -> #REF! | N30: =M30*(G30*2%) -> #REF! | O30: =M30-N30 -> #REF! | P30: =O30/$J$4 -> #REF!
G31: ='Hors-Site'!#REF! -> #REF! | H31: ='Hors-Site'!#REF! -> #REF! | I31: =Tableau1[[#This Row],[USD]]*$J$4 -> #REF! | J31: =I31-VLOOKUP($I31,$C$6:$D$9,1) -> #REF! | K31: =VLOOKUP($I31,$C$11:$D$14,2) -> #REF! | L31: =J31*K31 -> #REF! | M31: =L31+VLOOKUP($I31,$C$15:$E$19,3) -> #REF! | N31: =M31*(G31*2%) -> #REF! | O31: =M31-N31 -> #REF! | P31: =O31/$J$4 -> #REF!
... G140: ='Hors-Site'!#REF! -> #REF! | H140: ='Hors-Site'!#REF! -> #REF! | I140: =Tableau1[[#This Row],[USD]]*$J$4 -> #REF! | J140: =I140-VLOOKUP($I140,$C$6:$D$9,1) -> #REF! | K140: =VLOOKUP($I140,$C$11:$D$14,2) -> #REF! | L140: =J140*K140 -> #REF! | M140: =L140+VLOOKUP($I140,$C$15:$E$19,3) -> #REF! | N140: =M140*(G140*2%) -> #REF! | O140: =M140-N140 -> #REF! | P140: =O140/$J$4 -> #REF!
G141: ='Hors-Site'!G7 -> 0 | H141: ='Hors-Site'!AC7 -> 738.8022 | I141: =Tableau1[[#This Row],[USD]]*$J$4 -> 1699245.1 | J141: =I141-VLOOKUP($I141,$C$6:$D$9,1) -> 1537245.1 | K141: =VLOOKUP($I141,$C$11:$D$14,2) -> 0.15 | L141: =J141*K141 -> 230586.76 | M141: =L141+VLOOKUP($I141,$C$15:$E$19,3) -> 235446.76 | N141: =M141*(G141*2%) -> 0 | O141: =M141-N141 -> 235446.76 | P141: =O141/$J$4 -> 102.36816
G142: ='Hors-Site'!G8 -> 0 | H142: ='Hors-Site'!AC8 -> 40.119892 | I142: =Tableau1[[#This Row],[USD]]*$J$4 -> 92275.753 | J142: =I142-VLOOKUP($I142,$C$6:$D$9,1) -> 92275.753 | K142: =VLOOKUP($I142,$C$11:$D$14,2) -> 0 | L142: =J142*K142 -> 0 | M142: =L142+VLOOKUP($I142,$C$15:$E$19,3) -> 2300 | N142: =M142*(G142*2%) -> 0 | O142: =M142-N142 -> 2300 | P142: =O142/$J$4 -> 1
G143: ='Hors-Site'!G9 -> 0 | H143: ='Hors-Site'!AC9 -> 161.41903 | I143: =Tableau1[[#This Row],[USD]]*$J$4 -> 371263.76 | J143: =I143-VLOOKUP($I143,$C$6:$D$9,1) -> 209263.76 | K143: =VLOOKUP($I143,$C$11:$D$14,2) -> 0.15 | L143: =J143*K143 -> 31389.564 | M143: =L143+VLOOKUP($I143,$C$15:$E$19,3) -> 36249.564 | N143: =M143*(G143*2%) -> 0 | O143: =M143-N143 -> 36249.564 | P143: =O143/$J$4 -> 15.76068
G144: ='Hors-Site'!G10 -> 0 | H144: ='Hors-Site'!AC10 -> 178.71407 | I144: =Tableau1[[#This Row],[USD]]*$J$4 -> 411042.35 | J144: =I144-VLOOKUP($I144,$C$6:$D$9,1) -> 249042.35 | K144: =VLOOKUP($I144,$C$11:$D$14,2) -> 0.15 | L144: =J144*K144 -> 37356.353 | M144: =L144+VLOOKUP($I144,$C$15:$E$19,3) -> 42216.353 | N144: =M144*(G144*2%) -> 0 | O144: =M144-N144 -> 42216.353 | P144: =O144/$J$4 -> 18.354936
G145: ='Hors-Site'!G11 -> 0 | H145: ='Hors-Site'!AC11 -> 327.7514 | I145: =Tableau1[[#This Row],[USD]]*$J$4 -> 753828.22 | J145: =I145-VLOOKUP($I145,$C$6:$D$9,1) -> 591828.22 | K145: =VLOOKUP($I145,$C$11:$D$14,2) -> 0.15 | L145: =J145*K145 -> 88774.233 | M145: =L145+VLOOKUP($I145,$C$15:$E$19,3) -> 93634.233 | N145: =M145*(G145*2%) -> 0 | O145: =M145-N145 -> 93634.233 | P145: =O145/$J$4 -> 40.710536
G146: ='Hors-Site'!G12 -> 0 | H146: ='Hors-Site'!AC12 -> 320.88574 | I146: =Tableau1[[#This Row],[USD]]*$J$4 -> 738037.2 | J146: =I146-VLOOKUP($I146,$C$6:$D$9,1) -> 576037.2 | K146: =VLOOKUP($I146,$C$11:$D$14,2) -> 0.15 | L146: =J146*K146 -> 86405.58 | M146: =L146+VLOOKUP($I146,$C$15:$E$19,3) -> 91265.58 | N146: =M146*(G146*2%) -> 0 | O146: =M146-N146 -> 91265.58 | P146: =O146/$J$4 -> 39.680687
G147: ='Hors-Site'!G13 -> 0 | H147: ='Hors-Site'!AC13 -> 302.85392 | I147: =Tableau1[[#This Row],[USD]]*$J$4 -> 696564.02 | J147: =I147-VLOOKUP($I147,$C$6:$D$9,1) -> 534564.02 | K147: =VLOOKUP($I147,$C$11:$D$14,2) -> 0.15 | L147: =J147*K147 -> 80184.603 | M147: =L147+VLOOKUP($I147,$C$15:$E$19,3) -> 85044.603 | N147: =M147*(G147*2%) -> 0 | O147: =M147-N147 -> 85044.603 | P147: =O147/$J$4 -> 36.975914
G148: ='Hors-Site'!G14 -> 0 | H148: ='Hors-Site'!AC14 -> 349.44683 | I148: =Tableau1[[#This Row],[USD]]*$J$4 -> 803727.71 | J148: =I148-VLOOKUP($I148,$C$6:$D$9,1) -> 641727.71 | K148: =VLOOKUP($I148,$C$11:$D$14,2) -> 0.15 | L148: =J148*K148 -> 96259.157 | M148: =L148+VLOOKUP($I148,$C$15:$E$19,3) -> 101119.16 | N148: =M148*(G148*2%) -> 0 | O148: =M148-N148 -> 101119.16 | P148: =O148/$J$4 -> 43.964851
G149: ='Hors-Site'!G15 -> 0 | H149: ='Hors-Site'!AC15 -> 326.15038 | I149: =Tableau1[[#This Row],[USD]]*$J$4 -> 750145.87 | J149: =I149-VLOOKUP($I149,$C$6:$D$9,1) -> 588145.87 | K149: =VLOOKUP($I149,$C$11:$D$14,2) -> 0.15 | L149: =J149*K149 -> 88221.88 | M149: =L149+VLOOKUP($I149,$C$15:$E$19,3) -> 93081.88 | N149: =M149*(G149*2%) -> 0 | O149: =M149-N149 -> 93081.88 | P149: =O149/$J$4 -> 40.470383
G150: ='Hors-Site'!G16 -> 0 | H150: ='Hors-Site'!AC16 -> 502.16144 | I150: =Tableau1[[#This Row],[USD]]*$J$4 -> 1154971.3 | J150: =I150-VLOOKUP($I150,$C$6:$D$9,1) -> 992971.3 | K150: =VLOOKUP($I150,$C$11:$D$14,2) -> 0.15 | L150: =J150*K150 -> 148945.7 | M150: =L150+VLOOKUP($I150,$C$15:$E$19,3) -> 153805.7 | N150: =M150*(G150*2%) -> 0 | O150: =M150-N150 -> 153805.7 | P150: =O150/$J$4 -> 66.872042
G151: ='Hors-Site'!G17 -> 0 | H151: ='Hors-Site'!AC17 -> 349.44683 | I151: =Tableau1[[#This Row],[USD]]*$J$4 -> 803727.71 | J151: =I151-VLOOKUP($I151,$C$6:$D$9,1) -> 641727.71 | K151: =VLOOKUP($I151,$C$11:$D$14,2) -> 0.15 | L151: =J151*K151 -> 96259.157 | M151: =L151+VLOOKUP($I151,$C$15:$E$19,3) -> 101119.16 | N151: =M151*(G151*2%) -> 0 | O151: =M151-N151 -> 101119.16 | P151: =O151/$J$4 -> 43.964851
...
