Workbook

Sheet Dashboard
B2: HR KPIs DASHBOARD — EMPLOYÉS
B3: ="Export du "&TEXT(TODAY(),"dd/mm/yyyy")&" — "&COUNTA(Base!$A$3:$A$177)&" employés" -> Export du 24/07/2026 — 175 employés
B4: TOTAL EMPLOYÉS | E4: HOMMES | H4: FEMMES
B5: =COUNTA(Base!$A$3:$A$177) -> 175 | E5: =COUNTIF(Base!$J$3:$J$177,"Male")+COUNTIF(Base!$J$3:$J$177,"M") -> 148 | H5: =COUNTIF(Base!$J$3:$J$177,"Female")+COUNTIF(Base!$J$3:$J$177,"F") -> 27
B6: ÂGE MOYEN | E6: MOY. ENFANTS | H6: MARIÉS
B7: =IFERROR(ROUND(AVERAGE(Base!$L$3:$L$177),1),0) -> 40.1 | E7: =IFERROR(ROUND(AVERAGE(Base!$O$3:$O$177),2),0) -> 2.25 | H7: =COUNTIF(Base!$N$3:$N$177,"*Married*") -> 128
B9: PAR LOCALISATION | E9: PAR GENRE | H9: PAR GRADE
B10: Catégorie | C10: Effectif | E10: Catégorie | F10: Effectif | H10: Catégorie | I10: Effectif
B11: Zamba | C11: =COUNTIF(Base!$G$3:$G$177,"Zamba") -> 101 | E11: Male | F11: =COUNTIF(Base!$J$3:$J$177,"Male") -> 148 | H11: C2 | I11: =COUNTIF(Base!$E$3:$E$177,"C2") -> 38
B12: Kinshasa | C12: =COUNTIF(Base!$G$3:$G$177,"Kinshasa") -> 66 | E12: Female | F12: =COUNTIF(Base!$J$3:$J$177,"Female") -> 27 | H12: C3 | I12: =COUNTIF(Base!$E$3:$E$177,"C3") -> 24
B13: Lubudi | C13: =COUNTIF(Base!$G$3:$G$177,"Lubudi") -> 8 | E13: female | F13: =COUNTIF(Base!$J$3:$J$177,"female") -> 27 | H13: C4 | I13: =COUNTIF(Base!$E$3:$E$177,"C4") -> 19
B14: TOTAL | C14: =SUM(C11:C13) -> 175 | E14: TOTAL | F14: =SUM(F11:F13) -> 202 | H14: D2 | I14: =COUNTIF(Base!$E$3:$E$177,"D2") -> 17
H15: B2 | I15: =COUNTIF(Base!$E$3:$E$177,"B2") -> 14
B16: PAR DÉPARTEMENT | E16: PAR TRANCHE D'ÂGE | H16: C1 | I16: =COUNTIF(Base!$E$3:$E$177,"C1") -> 12
B17: Catégorie | C17: Effectif | E17: Catégorie | F17: Effectif | H17: C5 | I17: =COUNTIF(Base!$E$3:$E$177,"C5") -> 11
B18: Sales & Logistics | C18: =COUNTIF(Base!$D$3:$D$177,"Sales & Logistics") -> 35 | E18: 35-44 | F18: =COUNTIFS(Base!$L$3:$L$177,">=35",Base!$L$3:$L$177,"<45") -> 91 | H18: D1 | I18: =COUNTIF(Base!$E$3:$E$177,"D1") -> 8
B19: Corporate Admin | C19: =COUNTIF(Base!$D$3:$D$177,"Corporate Admin") -> 34 | E19: 25-34 | F19: =COUNTIFS(Base!$L$3:$L$177,">=25",Base!$L$3:$L$177,"<35") -> 39 | H19: B3 | I19: =COUNTIF(Base!$E$3:$E$177,"B3") -> 7
B20: Engineering | C20: =COUNTIF(Base!$D$3:$D$177,"Engineering") -> 28 | E20: 45-54 | F20: =COUNTIFS(Base!$L$3:$L$177,">=45",Base!$L$3:$L$177,"<55") -> 33 | H20: B4 | I20: =COUNTIF(Base!$E$3:$E$177,"B4") -> 6
B21: Production | C21: =COUNTIF(Base!$D$3:$D$177,"Production") -> 21 | E21: 55+ | F21: =COUNTIF(Base!$L$3:$L$177,">=55") -> 11 | H21: D4 | I21: =COUNTIF(Base!$E$3:$E$177,"D4") -> 6
B22: Administration | C22: =COUNTIF(Base!$D$3:$D$177,"Administration") -> 18 | E22: < 25 | F22: =COUNTIFS(Base!$L$3:$L$177,">=0",Base!$L$3:$L$177,"<25") -> 1 | H22: D5 | I22: =COUNTIF(Base!$E$3:$E$177,"D5") -> 4
B23: Quality Assurance | C23: =COUNTIF(Base!$D$3:$D$177,"Quality Assurance") -> 11 | E23: TOTAL | F23: =SUM(F18:F22) -> 175 | H23: B1 | I23: =COUNTIF(Base!$E$3:$E$177,"B1") -> 3
B24: Mining | C24: =COUNTIF(Base!$D$3:$D$177,"Mining") -> 0 | H24: B5 | I24: =COUNTIF(Base!$E$3:$E$177,"B5") -> 3
B25: Human Resources | C25: =COUNTIF(Base!$D$3:$D$177,"Human Resources") -> 7 | E25: PAR NATIONALITÉ | H25: E1 | I25: =COUNTIF(Base!$E$3:$E$177,"E1") -> 1
B26: Packaging & Logistics | C26: =COUNTIF(Base!$D$3:$D$177,"Packaging & Logistics") -> 5 | E26: Catégorie | F26: Effectif | H26: E2 | I26: =COUNTIF(Base!$E$3:$E$177,"E2") -> 1
B27: Risk & Environment | C27: =COUNTIF(Base!$D$3:$D$177,"Risk & Environment") -> 5 | E27: Congolese | F27: =COUNTIF(Base!$M$3:$M$177,"Congolese") -> 169 | H27: E4 | I27: =COUNTIF(Base!$E$3:$E$177,"E4") -> 1
B28: Finance | C28: =COUNTIF(Base!$D$3:$D$177,"Finance") -> 2 | E28: congolese | F28: =COUNTIF(Base!$M$3:$M$177,"congolese") -> 169 | H28: TOTAL | I28: =SUM(I11:I27) -> 175
B29: TOTAL | C29: =SUM(C18:C28) -> 166 | E29: Kenyan | F29: =COUNTIF(Base!$M$3:$M$177,"Kenyan") -> 3
E30: Cameroonian | F30: =COUNTIF(Base!$M$3:$M$177,"Cameroonian") -> 2
E31: Ivorian | F31: =COUNTIF(Base!$M$3:$M$177,"Ivorian") -> 1
E32: TOTAL | F32: =SUM(F27:F31) -> 344
B34: SORTIES (EXIT)
B35: Total sorties | C35: =COUNTA(EXIT!$A$3:$A$3) -> 1
B36: Motif | C36: Effectif
B37: Demission | C37: =COUNTIF(EXIT!$AD$3:$AD$3,"Demission") -> 1
B38: Licenciement | C38: =COUNTIF(EXIT!$AD$3:$AD$3,"Licenciement") -> 0
B39: Retraite | C39: =COUNTIF(EXIT!$AD$3:$AD$3,"Retraite") -> 0
B40: Fin de contrat | C40: =COUNTIF(EXIT!$AD$3:$AD$3,"Fin de contrat") -> 0
B41: TOTAL | C41: =SUM(C37:C40) -> 1

Sheet Base
A1: EMPLOYEE BASE
A2: MATRICULE | B2: COMPANY | C2: COMPLET NAME | D2: DEPARTMENT | E2: GRADE | F2: JOB TITLE | G2: LOCALISATION | H2: CENTER DES COUTS | I2: Appointment Date | J2: Gender | K2: Date of Birth | L2: Age | M2: Nationality | N2: Marital Status | O2: number of children | P2: Personnal Area | Q2: Employee SubGroup | R2: Payroll Area | S2: Payroll periode | T2: Line Manager Name | U2: Line manager position
A3: 70000002 | B3: PPC Barnet DRC Manufacturing | C3: MBODI BAUSHILE GAEL | D3: Administration | E3: D2 | F3: Site Manager | G3: Lubudi | H3: DL5110 | I3: 41852 | J3: Male | K3: 31575 | L3: =DATEDIF(K3,TODAY(),"Y") -> 40 | M3: Congolese | N3: Married | O3: 3 | P3: DRC | Q3: Zamba | R3: Permanent | S3: Monthly | T3: KABEYA KABENGELE Tresor Michel | U3: =IFERROR(VLOOKUP(T3,Base!$C$3:$F$177,4,FALSE),"Production Manager") -> Production Manager
A4: 70000008 | B4: PPC Barnet DRC Manufacturing | C4: MUAKASA NSONI SERGE | D4: Human Resources | E4: C4 | F4: Estate Officer | G4: Zamba | H4: KM5631 | I4: 42099 | J4: Male | K4: 28524 | L4: =DATEDIF(K4,TODAY(),"Y") -> 48 | M4: Congolese | N4: Married | O4: 4 | P4: DRC | Q4: Zamba | R4: Permanent | S4: Monthly | T4: ZAKUANI BAHATI BENNY | U4: =IFERROR(VLOOKUP(T4,Base!$C$3:$F$177,4,FALSE),"Plant HR Manager") -> Talent & Development Manager
A5: 70000009 | B5: PPC Barnet DRC Manufacturing | C5: ZODULUA GADUA Jean Jacques | D5: Corporate Admin | E5: B2 | F5: Driver | G5: Kinshasa | H5: KC8710 | I5: 42135 | J5: Male | K5: 25429 | L5: =DATEDIF(K5,TODAY(),"Y") -> 56 | M5: Congolese | N5: Married | O5: 2 | P5: DRC | Q5: Kinshasa | R5: Permanent | S5: Monthly | T5: Lisangola Marie Jose | U5: =IFERROR(VLOOKUP(T5,Base!$C$3:$F$177,4,FALSE),"Facilities coordinator and adm (HQ)") -> Facilities coordinator and adm (HQ)
A6: 70000011 | B6: PPC Barnet DRC Manufacturing | C6: KIMBANZI FEINTA BOVICK | D6: Sales & Logistics | E6: C4 | F6: Senior Sales Consultant | G6: Zamba | H6: KC6111 | I6: 42240 | J6: Male | K6: 25330 | L6: =DATEDIF(K6,TODAY(),"Y") -> 57 | M6: Congolese | N6: Married | O6: 4 | P6: DRC | Q6: Kwango | R6: Permanent | S6: Monthly | T6: Bashige Rurabura Jean-Pierre | U6: =IFERROR(VLOOKUP(T6,Base!$C$3:$F$177,4,FALSE),"Regional Sales Manager") -> Regional Sales Manager
A7: 70000013 | B7: PPC Barnet DRC Quarrying | C7: KUASA KINSIONA CHRISPIN | D7: Mining | E7: B2 | F7: Drilling Operator | G7: Zamba | H7: KQ1010 | I7: 42240 | J7: Male | K7: 30277 | L7: =DATEDIF(K7,TODAY(),"Y") -> 43 | M7: Congolese | N7: Married | O7: 5 | P7: DRC | Q7: Zamba | R7: Permanent | S7: Monthly | T7: LONGO ZOLA CHRISPIN | U7: =IFERROR(VLOOKUP(T7,Base!$C$3:$F$177,4,FALSE),"Shift Supervisor/ blaster") -> Shift Supervisor
A8: 70000015 | B8: PPC Barnet DRC Manufacturing | C8: LUZOLO NSEMBOLO THOMAS | D8: Engineering | E8: C2 | F8: Mechanic | G8: Zamba | H8: KM5317 | I8: 42286 | J8: Male | K8: 32509 | L8: =DATEDIF(K8,TODAY(),"Y") -> 37 | M8: Congolese | N8: Married | O8: 7 | P8: DRC | Q8: Zamba | R8: Permanent | S8: Monthly | T8: Mechanical Engineer | U8: =IFERROR(VLOOKUP(T8,Base!$C$3:$F$177,4,FALSE),"Mechanical Engineer") -> Mechanical Engineer
A9: 70000019 | B9: PPC Barnet DRC Manufacturing | C9: BANGULI KIESSE SANDRINE | D9: Corporate Admin | E9: D1 | F9: Payroll and Admin Manager | G9: Kinshasa | H9: KC8710 | I9: 41771 | J9: Female | K9: 28799 | L9: =DATEDIF(K9,TODAY(),"Y") -> 47 | M9: Congolese | N9: Married | O9: 0 | P9: DRC | Q9: Kinshasa | R9: Permanent | S9: Monthly | T9: Carine Ewuli | U9: =IFERROR(VLOOKUP(T9,Base!$C$3:$F$177,4,FALSE),"Head of HR") -> Head of HR
A10: 70000021 | B10: PPC Barnet DRC Manufacturing | C10: LISANGOLA YOWALI Marie-Josee | D10: Corporate Admin | E10: C4 | F10: Facilities Officer | G10: Kinshasa | H10: KC8710 | I10: 41771 | J10: Female | K10: 29642 | L10: =DATEDIF(K10,TODAY(),"Y") -> 45 | M10: Congolese | N10: Married | O10: 2 | P10: DRC | Q10: Kinshasa | R10: Permanent | S10: Monthly | T10: Kiesse Banguli | U10: =IFERROR(VLOOKUP(T10,Base!$C$3:$F$177,4,FALSE),"Payroll and Admin Manager") -> Payroll and Admin Manager
A11: 70000022 | B11: PPC Barnet DRC Manufacturing | C11: MUNANGA DINA CARINE | D11: Sales & Logistics | E11: C5 | F11: Customer Demand Supply Planner | G11: Kinshasa | H11: KC6312 | I11: 41771 | J11: Female | K11: 29186 | L11: =DATEDIF(K11,TODAY(),"Y") -> 46 | M11: Congolese | N11: Married | O11: 2 | P11: DRC | Q11: Kinshasa | R11: Permanent | S11: Monthly | T11: 0 | U11: =IFERROR(VLOOKUP(T11,Base!$C$3:$F$177,4,FALSE),"Lead Customer Excellence") -> Lead Customer Excellence
A12: 70000023 | B12: PPC Barnet DRC Manufacturing | C12: BANGA BANGA APEA ONESIME | D12: Corporate Admin | E12: B2 | F12: Driver | G12: Kinshasa | H12: KC8710 | I12: 41913 | J12: Male | K12: 25208 | L12: =DATEDIF(K12,TODAY(),"Y") -> 57 | M12: Congolese | N12: Married | O12: 2 | P12: DRC | Q12: Kinshasa | R12: Permanent | S12: Monthly | T12: Lisangola Marie Jose | U12: =IFERROR(VLOOKUP(T12,Base!$C$3:$F$177,4,FALSE),"Facilities coordinator and adm (HQ)") -> Facilities coordinator and adm (HQ)
A13: 70000024 | B13: PPC Barnet DRC Manufacturing | C13: KITAMBO SENEMONA MEDARD | D13: Human Resources | E13: B2 | F13: Driver | G13: Zamba | H13: KM5413 | I13: 41897 | J13: Male | K13: 23836 | L13: =DATEDIF(K13,TODAY(),"Y") -> 61 | M13: Congolese | N13: Married | O13: 0 | P13: DRC | Q13: Zamba | R13: Permanent | S13: Monthly | T13: MUAKASA NSONI SERGE | U13: =IFERROR(VLOOKUP(T13,Base!$C$3:$F$177,4,FALSE),"State Officer") -> Estate Officer
A14: 70000026 | B14: PPC Barnet DRC Manufacturing | C14: KABANGU MUTAMBAYI CHARLIE | D14: Production | E14: C3 | F14: Shift Supervisor | G14: Zamba | H14: KM4421 | I14: 42317 | J14: Male | K14: 32392 | L14: =DATEDIF(K14,TODAY(),"Y") -> 37 | M14: Congolese | N14: Married | O14: 2 | P14: DRC | Q14: Zamba | R14: Permanent | S14: Monthly | T14: KABEYA KABENGELE Tresor Michel | U14: =IFERROR(VLOOKUP(T14,Base!$C$3:$F$177,4,FALSE),"Production Manager") -> Production Manager
A15: 70000027 | B15: PPC Barnet DRC Manufacturing | C15: KABEYA KABENGELE Tresor Michel | D15: Production | E15: D4 | F15: Production Manager | G15: Zamba | H15: KM5110 | I15: 42317 | J15: Male | K15: 31255 | L15: =DATEDIF(K15,TODAY(),"Y") -> 40 | M15: Congolese | N15: Married | O15: 0 | P15: DRC | Q15: Zamba | R15: Permanent | S15: Monthly | T15: Andrew Molonga | U15: =IFERROR(VLOOKUP(T15,Base!$C$3:$F$177,4,FALSE),"Plant Manager") -> Plant Manager
A16: 70000028 | B16: PPC Barnet DRC Manufacturing | C16: KADIMOYO ILUNGA YVAN | D16: Production | E16: D1 | F16: Production Superintendent | G16: Zamba | H16: KM4421 | I16: 42317 | J16: Male | K16: 33504 | L16: =DATEDIF(K16,TODAY(),"Y") -> 34 | M16: Congolese | N16: Married | O16: 1 | P16: DRC | Q16: Zamba | R16: Permanent | S16: Monthly | T16: Michel Kabeya | U16: =IFERROR(VLOOKUP(T16,Base!$C$3:$F$177,4,FALSE),"Production Manager") -> Production Manager
A17: 70000029 | B17: PPC Barnet DRC Manufacturing | C17: MAPHASI VANGU PHILIPPE | D17: Production | E17: C3 | F17: Production Shift Supervisor | G17: Zamba | H17: KM4510 | I17: 42317 | J17: Male | K17: 30405 | L17: =DATEDIF(K17,TODAY(),"Y") -> 43 | M17: Congolese | N17: Married | O17: 4 | P17: DRC | Q17: Zamba | R17: Permanent | S17: Monthly | T17: Yvan Kadimoyo | U17: =IFERROR(VLOOKUP(T17,Base!$C$3:$F$177,4,FALSE),"Production Superintendent") -> Production Superintendent
A18: 70000030 | B18: PPC Barnet DRC Manufacturing | C18: MUBA KAYEMBE JEREMIE | D18: Packaging & Logistics | E18: C4 | F18: Packing Plant Foreman | G18: Zamba | H18: KM4610 | I18: 42317 | J18: Male | K18: 32730 | L18: =DATEDIF(K18,TODAY(),"Y") -> 36 | M18: Congolese | N18: Married | O18: 2 | P18: DRC | Q18: Zamba | R18: Permanent | S18: Monthly | T18: Yvan Kadimoyo | U18: =IFERROR(VLOOKUP(T18,Base!$C$3:$F$177,4,FALSE),"Production Superintendent") -> Production Superintendent
A19: 70000032 | B19: PPC Barnet DRC Manufacturing | C19: NEMWANDJARE PERO PHILEMON | D19: Administration | E19: C5 | F19: Junior Process Engineer | G19: Zamba | H19: KM5910 | I19: 42317 | J19: Male | K19: 32748 | L19: =DATEDIF(K19,TODAY(),"Y") -> 36 | M19: Congolese | N19: Married | O19: 2 | P19: DRC | Q19: Zamba | R19: Permanent | S19: Monthly | T19: Parician Ucchi | U19: =IFERROR(VLOOKUP(T19,Base!$C$3:$F$177,4,FALSE),"Process Engineer") -> Process Engineer
A20: 70000033 | B20: PPC Barnet DRC Manufacturing | C20: UUCHI UMIRAMBE PARICIAN | D20: Administration | E20: D1 | F20: Optimisation Process Engineer | G20: Zamba | H20: KM5910 | I20: 42317 | J20: Male | K20: 32408 | L20: =DATEDIF(K20,TODAY(),"Y") -> 37 | M20: Congolese | N20: Married | O20: 3 | P20: DRC | Q20: Zamba | R20: Permanent | S20: Monthly | T20: Andrew Molonga | U20: =IFERROR(VLOOKUP(T20,Base!$C$3:$F$177,4,FALSE),"Plant Manager") -> Plant Manager
A21: 70000034 | B21: PPC Barnet DRC Manufacturing | C21: MULOLO KANKOLONGO MANIX | D21: Corporate Admin | E21: D2 | F21: IT Manager | G21: Kinshasa | H21: KC8414 | I21: 42338 | J21: Male | K21: 31762 | L21: =DATEDIF(K21,TODAY(),"Y") -> 39 | M21: Congolese | N21: Married | O21: 3 | P21: DRC | Q21: Kinshasa | R21: Permanent | S21: Monthly | T21: Cedric Muzadi | U21: =IFERROR(VLOOKUP(T21,Base!$C$3:$F$177,4,FALSE),"Head of Finance") -> Head of Finance
A22: 70000038 | B22: PPC Barnet DRC Manufacturing | C22: MACHARIA KINYANJUI SIMON | D22: Engineering | E22: D1 | F22: Electrical & Instrumentation Engineer | G22: Zamba | H22: KM5310 | I22: 42430 | J22: Male | K22: 29048 | L22: =DATEDIF(K22,TODAY(),"Y") -> 47 | M22: Kenyan | N22: Single | O22: 0 | P22: DRC | Q22: Zamba | R22: Permanent | S22: Monthly | T22: Jack Ilondo | U22: =IFERROR(VLOOKUP(T22,Base!$C$3:$F$177,4,FALSE),"Engineering Manager") -> Engineering Manager
A23: 70000040 | B23: PPC Barnet DRC Manufacturing | C23: ILONDO LIKOMBA Jack Lethycien | D23: Engineering | E23: D4 | F23: Engineering Manager | G23: Zamba | H23: KM5310 | I23: 42471 | J23: Male | K23: 31855 | L23: =DATEDIF(K23,TODAY(),"Y") -> 39 | M23: Congolese | N23: Married | O23: 3 | P23: DRC | Q23: Zamba | R23: Permanent | S23: Monthly | T23: Andrew Molonga | U23: =IFERROR(VLOOKUP(T23,Base!$C$3:$F$177,4,FALSE),"Plant Manager") -> Plant Manager
A24: 70000042 | B24: PPC Barnet DRC Quarrying | C24: NZAZI KALUZAKI TOUBI | D24: Mining | E24: B2 | F24: Drilling Operator | G24: Zamba | H24: KQ1010 | I24: 42499 | J24: Male | K24: 25820 | L24: =DATEDIF(K24,TODAY(),"Y") -> 55 | M24: Congolese | N24: Single | O24: 5 | P24: DRC | Q24: Zamba | R24: Permanent | S24: Monthly | T24: LONGO ZOLA CHRISPIN | U24: =IFERROR(VLOOKUP(T24,Base!$C$3:$F$177,4,FALSE),"Mining Supervisor/blaster") -> Shift Supervisor
A25: 70000043 | B25: PPC Barnet DRC Manufacturing | C25: MAKIVOVI KEVENA EDDO | D25: Risk & Environment | E25: C2 | F25: Safety Officer | G25: Zamba | H25: KM5811 | I25: 42499 | J25: Male | K25: 26131 | L25: =DATEDIF(K25,TODAY(),"Y") -> 55 | M25: Congolese | N25: Married | O25: 6 | P25: DRC | Q25: Zamba | R25: Permanent | S25: Monthly | T25: Mobile Equipment Operator | U25: =IFERROR(VLOOKUP(T25,Base!$C$3:$F$177,4,FALSE),"Mining Supervisor/blaster") -> Mining Supervisor/blaster
A26: 70000045 | B26: PPC Barnet DRC Manufacturing | C26: BILONDA KAZADI DIANE | D26: Sales & Logistics | E26: C5 | F26: Senior Regional Sales Consultant Construction, Ready Mix & Indus | G26: Kinshasa | H26: KC6111 | I26: 42506 | J26: Female | K26: 32197 | L26: =DATEDIF(K26,TODAY(),"Y") -> 38 | M26: Congolese | N26: Married | O26: 0 | P26: DRC | Q26: Kinshasa | R26: Permanent | S26: Monthly | T26: KILOSO SANDA HELENA | U26: =IFERROR(VLOOKUP(T26,Base!$C$3:$F$177,4,FALSE),"Regional Sales Manager") -> Senior Regional Sales Consultant Retail & Funa
A27: 70000046 | B27: PPC Barnet DRC Manufacturing | C27: MUKENDI KABONGO PATRICK | D27: Engineering | E27: D1 | F27: Mechanical Engineer | G27: Zamba | H27: KM5311 | I27: 42522 | J27: Male | K27: 29323 | L27: =DATEDIF(K27,TODAY(),"Y") -> 46 | M27: Congolese | N27: Married | O27: 5 | P27: DRC | Q27: Zamba | R27: Permanent | S27: Monthly | T27: Jack Ilondo | U27: =IFERROR(VLOOKUP(T27,Base!$C$3:$F$177,4,FALSE),"Engineering manager") -> Engineering manager
A28: 70000048 | B28: PPC Barnet DRC Manufacturing | C28: KILOSO SANDA HELENA | D28: Sales & Logistics | E28: C5 | F28: Senior Regional Sales Consultant Retail & Funa | G28: Kinshasa | H28: KC6111 | I28: 42522 | J28: Female | K28: 32543 | L28: =DATEDIF(K28,TODAY(),"Y") -> 37 | M28: Congolese | N28: Single | O28: 0 | P28: DRC | Q28: Kinshasa | R28: Permanent | S28: Monthly | T28: Serge Bazola | U28: =IFERROR(VLOOKUP(T28,Base!$C$3:$F$177,4,FALSE),"Head of Business Development") -> Head of Business Development
A29: 70000049 | B29: PPC Barnet DRC Manufacturing | C29: PONGO PONGO LIWANDA LUTE CHARLES | D29: Quality Assurance | E29: D2 | F29: Quality Assurance Manager | G29: Zamba | H29: KM5510 | I29: 42515 | J29: Male | K29: 23282 | L29: =DATEDIF(K29,TODAY(),"Y") -> 62 | M29: Congolese | N29: Married | O29: 6 | P29: DRC | Q29: Zamba | R29: Permanent | S29: Monthly | T29: Andrew Molonga | U29: =IFERROR(VLOOKUP(T29,Base!$C$3:$F$177,4,FALSE),"Plant Manager") -> Plant Manager
A30: 70000050 | B30: PPC Barnet DRC Manufacturing | C30: TANUI KIPRUTO ELIAS | D30: Administration | E30: D4 | F30: Project Manager | G30: Zamba | H30: KM8910 | I30: 42562 | J30: Male | K30: 27214 | L30: =DATEDIF(K30,TODAY(),"Y") -> 52 | M30: Kenyan | N30: Married | O30: 1 | P30: DRC | Q30: Zamba | R30: Permanent | S30: Monthly | T30: Patrick Kahasha | U30: =IFERROR(VLOOKUP(T30,Base!$C$3:$F$177,4,FALSE),"Managing Director") -> Managing Director
A31: 70000051 | B31: PPC Barnet DRC Manufacturing | C31: DIAKIESE LUTUTALA GRACE | D31: Sales & Logistics | E31: C2 | F31: Sales Consultant Tshangu | G31: Kinshasa | H31: KC6111 | I31: 42569 | J31: Female | K31: 34355 | L31: =DATEDIF(K31,TODAY(),"Y") -> 32 | M31: Congolese | N31: Married | O31: 4 | P31: DRC | Q31: Kinshasa | R31: Permanent | S31: Monthly | T31: KILOSO SANDA HELENA | U31: =IFERROR(VLOOKUP(T31,Base!$C$3:$F$177,4,FALSE),"Regional Sales Manager") -> Senior Regional Sales Consultant Retail & Funa
A32: 70000052 | B32: PPC Barnet DRC Manufacturing | C32: BAYISA SIMON DIDIER | D32: Engineering | E32: C2 | F32: Fitter & Turner | G32: Zamba | H32: KM5310 | I32: 42569 | J32: Male | K32: 29768 | L32: =DATEDIF(K32,TODAY(),"Y") -> 45 | M32: Congolese | N32: Married | O32: 5 | P32: DRC | Q32: Zamba | R32: Permanent | S32: Monthly | T32: Patrick Mukendi | U32: =IFERROR(VLOOKUP(T32,Base!$C$3:$F$177,4,FALSE),"Mechanical Foreman") -> Mechanical Foreman
A33: 70000056 | B33: PPC Barnet DRC Manufacturing | C33: NSAKALA KUNIEKI GAYLOR | D33: Production | E33: B4 | F33: Operator Support | G33: Zamba | H33: KM4510 | I33: 42632 | J33: Male | K33: 30206 | L33: =DATEDIF(K33,TODAY(),"Y") -> 43 | M33: Congolese | N33: Married | O33: 4 | P33: DRC | Q33: Zamba | R33: Permanent | S33: Monthly | T33: MPONGO KOLONGO LEON | U33: =IFERROR(VLOOKUP(T33,Base!$C$3:$F$177,4,FALSE),"Packing/ Loading shift supervisor") -> Buyer
A34: 70000057 | B34: PPC Barnet DRC Manufacturing | C34: LUTONADIO NGUAWANI OLIVIER | D34: Packaging & Logistics | E34: C2 | F34: Packing/Loading Shift Supervisor | G34: Zamba | H34: KM4610 | I34: 42632 | J34: Male | K34: 32768 | L34: =DATEDIF(K34,TODAY(),"Y") -> 36 | M34: Congolese | N34: Single | O34: 2 | P34: DRC | Q34: Zamba | R34: Permanent | S34: Monthly | T34: ADHULE NYADRIA JOEL | U34: =IFERROR(VLOOKUP(T34,Base!$C$3:$F$177,4,FALSE),"Packing Plant Manager") -> Safety Manager
A35: 70000058 | B35: PPC Barnet DRC Manufacturing | C35: TULENGI KASIAMA REAGAN | D35: Engineering | E35: C2 | F35: Fitter & Crane Specialist | G35: Zamba | H35: KM5310 | I35: 42632 | J35: Male | K35: 31705 | L35: =DATEDIF(K35,TODAY(),"Y") -> 39 | M35: Congolese | N35: Married | O35: 5 | P35: DRC | Q35: Zamba | R35: Permanent | S35: Monthly | T35: Patrick Mukendi | U35: =IFERROR(VLOOKUP(T35,Base!$C$3:$F$177,4,FALSE),"Mechanical Foreman") -> Mechanical Foreman
A36: 70000059 | B36: PPC Barnet DRC Manufacturing | C36: LUZOLAWO MANKELA RODRIGUE | D36: Packaging & Logistics | E36: C2 | F36: Packing/Loading Shift Supervisor | G36: Zamba | H36: KM4610 | I36: 42632 | J36: Male | K36: 31885 | L36: =DATEDIF(K36,TODAY(),"Y") -> 39 | M36: Congolese | N36: Married | O36: 2 | P36: DRC | Q36: Zamba | R36: Permanent | S36: Monthly | T36: Gael Mbodi | U36: =IFERROR(VLOOKUP(T36,Base!$C$3:$F$177,4,FALSE),"Packing Plant Superintendant") -> Packing Plant Superintendant
A37: 70000061 | B37: PPC Barnet DRC Manufacturing | C37: NZUZI TABILA JOEL | D37: Packaging & Logistics | E37: C2 | F37: Packing/Loading Shift Supervisor | G37: Zamba | H37: KM4610 | I37: 42632 | J37: Male | K37: 25800 | L37: =DATEDIF(K37,TODAY(),"Y") -> 55 | M37: Congolese | N37: Married | O37: 5 | P37: DRC | Q37: Zamba | R37: Permanent | S37: Monthly | T37: Gael Mbodi | U37: =IFERROR(VLOOKUP(T37,Base!$C$3:$F$177,4,FALSE),"Packing Plant Superintendant") -> Packing Plant Superintendant
A38: 70000063 | B38: PPC Barnet DRC Manufacturing | C38: MUANDA BALOKI JISCA | D38: Production | E38: C3 | F38: Shift Supervisor | G38: Zamba | H38: KM4421 | I38: 42632 | J38: Male | K38: 30284 | L38: =DATEDIF(K38,TODAY(),"Y") -> 43 | M38: Congolese | N38: Married | O38: 3 | P38: DRC | Q38: Zamba | R38: Permanent | S38: Monthly | T38: Yvan Kadimoyo | U38: =IFERROR(VLOOKUP(T38,Base!$C$3:$F$177,4,FALSE),"Production Superintendent") -> Production Superintendent
A39: 70000064 | B39: PPC Barnet DRC Manufacturing | C39: KALUNGA MASELE RAMSES | D39: Production | E39: C1 | F39: Process Operator | G39: Zamba | H39: KM4421 | I39: 42632 | J39: Male | K39: 31917 | L39: =DATEDIF(K39,TODAY(),"Y") -> 39 | M39: Congolese | N39: Married | O39: 2 | P39: DRC | Q39: Zamba | R39: Permanent | S39: Monthly | T39: Jeremie Muba | U39: =IFERROR(VLOOKUP(T39,Base!$C$3:$F$177,4,FALSE),"Shift Supervisor") -> Shift Supervisor
A40: 70000067 | B40: PPC Barnet DRC Manufacturing | C40: MPONGO KOLONGO LEON | D40: Sales & Logistics | E40: C3 | F40: Buyer | G40: Zamba | H40: KC8813 | I40: 42632 | J40: Male | K40: 33425 | L40: =DATEDIF(K40,TODAY(),"Y") -> 35 | M40: Congolese | N40: Single | O40: 1 | P40: DRC | Q40: Zamba | R40: Permanent | S40: Monthly | T40: Nelly Biganiro | U40: =IFERROR(VLOOKUP(T40,Base!$C$3:$F$177,4,FALSE),"Purchasing Manager") -> Purchasing Manager
...

Sheet EXIT
A1: EXIT — AGENTS SORTIS
A2: MATRICULE | B2: COMPANY | C2: COMPLET NAME | D2: DEPARTMENT | E2: GRADE | F2: JOB TITLE | G2: LOCALISATION | H2: CENTER DES COUTS | I2: Appointment Date | J2: Gender | K2: Date of Birth | L2: Age | M2: Nationality | N2: Marital Status | O2: number of children | P2: Personnal Area | Q2: Employee SubGroup | R2: Payroll Area | S2: Departement | V2: Line Manager Name | W2: Line manager position
A3: 70000273 | B3: PPC Barnet DRC Manufacturing | C3: NDUSHA CLEMENT | D3: Administration | E3: C2 | F3: Process Technician | G3: Zamba | H3: KM5910 | I3: 45446 | J3: Male | K3: 36512 | L3: =DATEDIF(K3,TODAY(),"Y") -> 26 | M3: congolese | N3: Single | O3: 0 | P3: DRC | R3: Contract | S3: Monthly | V3: Parician Ucchi | W3: =IFERROR(VLOOKUP(V3,Base!$C$3:$F$177,4,FALSE),"Optimization Process Engineer") -> Optimization Process Engineer | Y3: Inactive | Z3: CDD | AA3: 26 | AB3: 46237 | AC3: 46217 | AD3: Demission
